<?xml version="1.0" ?>
<!-- =================================================================================== -->
<!-- |    This document was autogenerated by xacro from moonbot2.xacro                 | -->
<!-- |    EDITING THIS FILE BY HAND IS NOT RECOMMENDED                                 | -->
<!-- =================================================================================== -->
<robot name="moonbot2">
  <material name="silver">
    <color rgba="0.700 0.700 0.700 1.000"/>
  </material>
  <transmission name="Limb0Pitch2_tran">
    <type>transmission_interface/SimpleTransmission</type>
    <joint name="Limb0Pitch2">
      <hardwareInterface>hardware_interface/EffortJointInterface</hardwareInterface>
    </joint>
    <actuator name="Limb0Pitch2_actr">
      <hardwareInterface>hardware_interface/EffortJointInterface</hardwareInterface>
      <mechanicalReduction>1</mechanicalReduction>
    </actuator>
  </transmission>
  <transmission name="Limb0Pitch1_tran">
    <type>transmission_interface/SimpleTransmission</type>
    <joint name="Limb0Pitch1">
      <hardwareInterface>hardware_interface/EffortJointInterface</hardwareInterface>
    </joint>
    <actuator name="Limb0Pitch1_actr">
      <hardwareInterface>hardware_interface/EffortJointInterface</hardwareInterface>
      <mechanicalReduction>1</mechanicalReduction>
    </actuator>
  </transmission>
  <transmission name="Limb0Roll1_tran">
    <type>transmission_interface/SimpleTransmission</type>
    <joint name="Limb0Roll1">
      <hardwareInterface>hardware_interface/EffortJointInterface</hardwareInterface>
    </joint>
    <actuator name="Limb0Roll1_actr">
      <hardwareInterface>hardware_interface/EffortJointInterface</hardwareInterface>
      <mechanicalReduction>1</mechanicalReduction>
    </actuator>
  </transmission>
  <transmission name="Limb0Roll2_tran">
    <type>transmission_interface/SimpleTransmission</type>
    <joint name="Limb0Roll2">
      <hardwareInterface>hardware_interface/EffortJointInterface</hardwareInterface>
    </joint>
    <actuator name="Limb0Roll2_actr">
      <hardwareInterface>hardware_interface/EffortJointInterface</hardwareInterface>
      <mechanicalReduction>1</mechanicalReduction>
    </actuator>
  </transmission>
  <transmission name="Limb0Pitch3_tran">
    <type>transmission_interface/SimpleTransmission</type>
    <joint name="Limb0Pitch3">
      <hardwareInterface>hardware_interface/EffortJointInterface</hardwareInterface>
    </joint>
    <actuator name="Limb0Pitch3_actr">
      <hardwareInterface>hardware_interface/EffortJointInterface</hardwareInterface>
      <mechanicalReduction>1</mechanicalReduction>
    </actuator>
  </transmission>
  <transmission name="Limb0Roll3_tran">
    <type>transmission_interface/SimpleTransmission</type>
    <joint name="Limb0Roll3">
      <hardwareInterface>hardware_interface/EffortJointInterface</hardwareInterface>
    </joint>
    <actuator name="Limb0Roll3_actr">
      <hardwareInterface>hardware_interface/EffortJointInterface</hardwareInterface>
      <mechanicalReduction>1</mechanicalReduction>
    </actuator>
  </transmission>
  <transmission name="Revolute 53_tran">
    <type>transmission_interface/SimpleTransmission</type>
    <joint name="Revolute 53">
      <hardwareInterface>hardware_interface/EffortJointInterface</hardwareInterface>
    </joint>
    <actuator name="Revolute 53_actr">
      <hardwareInterface>hardware_interface/EffortJointInterface</hardwareInterface>
      <mechanicalReduction>1</mechanicalReduction>
    </actuator>
  </transmission>
  <transmission name="Limb1Pitch1_tran">
    <type>transmission_interface/SimpleTransmission</type>
    <joint name="Limb1Pitch1">
      <hardwareInterface>hardware_interface/EffortJointInterface</hardwareInterface>
    </joint>
    <actuator name="Limb1Pitch1_actr">
      <hardwareInterface>hardware_interface/EffortJointInterface</hardwareInterface>
      <mechanicalReduction>1</mechanicalReduction>
    </actuator>
  </transmission>
  <transmission name="Limb1Pitch2_tran">
    <type>transmission_interface/SimpleTransmission</type>
    <joint name="Limb1Pitch2">
      <hardwareInterface>hardware_interface/EffortJointInterface</hardwareInterface>
    </joint>
    <actuator name="Limb1Pitch2_actr">
      <hardwareInterface>hardware_interface/EffortJointInterface</hardwareInterface>
      <mechanicalReduction>1</mechanicalReduction>
    </actuator>
  </transmission>
  <transmission name="Limb1Roll2_tran">
    <type>transmission_interface/SimpleTransmission</type>
    <joint name="Limb1Roll2">
      <hardwareInterface>hardware_interface/EffortJointInterface</hardwareInterface>
    </joint>
    <actuator name="Limb1Roll2_actr">
      <hardwareInterface>hardware_interface/EffortJointInterface</hardwareInterface>
      <mechanicalReduction>1</mechanicalReduction>
    </actuator>
  </transmission>
  <transmission name="Revolute 63_tran">
    <type>transmission_interface/SimpleTransmission</type>
    <joint name="Revolute 63">
      <hardwareInterface>hardware_interface/EffortJointInterface</hardwareInterface>
    </joint>
    <actuator name="Revolute 63_actr">
      <hardwareInterface>hardware_interface/EffortJointInterface</hardwareInterface>
      <mechanicalReduction>1</mechanicalReduction>
    </actuator>
  </transmission>
  <transmission name="Revolute 65_tran">
    <type>transmission_interface/SimpleTransmission</type>
    <joint name="Revolute 65">
      <hardwareInterface>hardware_interface/EffortJointInterface</hardwareInterface>
    </joint>
    <actuator name="Revolute 65_actr">
      <hardwareInterface>hardware_interface/EffortJointInterface</hardwareInterface>
      <mechanicalReduction>1</mechanicalReduction>
    </actuator>
  </transmission>
  <transmission name="Limb3Roll1_tran">
    <type>transmission_interface/SimpleTransmission</type>
    <joint name="Limb3Roll1">
      <hardwareInterface>hardware_interface/EffortJointInterface</hardwareInterface>
    </joint>
    <actuator name="Limb3Roll1_actr">
      <hardwareInterface>hardware_interface/EffortJointInterface</hardwareInterface>
      <mechanicalReduction>1</mechanicalReduction>
    </actuator>
  </transmission>
  <transmission name="Limb3Pitch1_tran">
    <type>transmission_interface/SimpleTransmission</type>
    <joint name="Limb3Pitch1">
      <hardwareInterface>hardware_interface/EffortJointInterface</hardwareInterface>
    </joint>
    <actuator name="Limb3Pitch1_actr">
      <hardwareInterface>hardware_interface/EffortJointInterface</hardwareInterface>
      <mechanicalReduction>1</mechanicalReduction>
    </actuator>
  </transmission>
  <transmission name="Limb3Pitch2_tran">
    <type>transmission_interface/SimpleTransmission</type>
    <joint name="Limb3Pitch2">
      <hardwareInterface>hardware_interface/EffortJointInterface</hardwareInterface>
    </joint>
    <actuator name="Limb3Pitch2_actr">
      <hardwareInterface>hardware_interface/EffortJointInterface</hardwareInterface>
      <mechanicalReduction>1</mechanicalReduction>
    </actuator>
  </transmission>
  <transmission name="Limb3Roll2_tran">
    <type>transmission_interface/SimpleTransmission</type>
    <joint name="Limb3Roll2">
      <hardwareInterface>hardware_interface/EffortJointInterface</hardwareInterface>
    </joint>
    <actuator name="Limb3Roll2_actr">
      <hardwareInterface>hardware_interface/EffortJointInterface</hardwareInterface>
      <mechanicalReduction>1</mechanicalReduction>
    </actuator>
  </transmission>
  <transmission name="Limb3Pitch3_tran">
    <type>transmission_interface/SimpleTransmission</type>
    <joint name="Limb3Pitch3">
      <hardwareInterface>hardware_interface/EffortJointInterface</hardwareInterface>
    </joint>
    <actuator name="Limb3Pitch3_actr">
      <hardwareInterface>hardware_interface/EffortJointInterface</hardwareInterface>
      <mechanicalReduction>1</mechanicalReduction>
    </actuator>
  </transmission>
  <transmission name="Limb3Roll3_tran">
    <type>transmission_interface/SimpleTransmission</type>
    <joint name="Limb3Roll3">
      <hardwareInterface>hardware_interface/EffortJointInterface</hardwareInterface>
    </joint>
    <actuator name="Limb3Roll3_actr">
      <hardwareInterface>hardware_interface/EffortJointInterface</hardwareInterface>
      <mechanicalReduction>1</mechanicalReduction>
    </actuator>
  </transmission>
  <transmission name="Limb2Roll1_tran">
    <type>transmission_interface/SimpleTransmission</type>
    <joint name="Limb2Roll1">
      <hardwareInterface>hardware_interface/EffortJointInterface</hardwareInterface>
    </joint>
    <actuator name="Limb2Roll1_actr">
      <hardwareInterface>hardware_interface/EffortJointInterface</hardwareInterface>
      <mechanicalReduction>1</mechanicalReduction>
    </actuator>
  </transmission>
  <transmission name="Limb2Pitch1_tran">
    <type>transmission_interface/SimpleTransmission</type>
    <joint name="Limb2Pitch1">
      <hardwareInterface>hardware_interface/EffortJointInterface</hardwareInterface>
    </joint>
    <actuator name="Limb2Pitch1_actr">
      <hardwareInterface>hardware_interface/EffortJointInterface</hardwareInterface>
      <mechanicalReduction>1</mechanicalReduction>
    </actuator>
  </transmission>
  <transmission name="Limb2Pitch2_tran">
    <type>transmission_interface/SimpleTransmission</type>
    <joint name="Limb2Pitch2">
      <hardwareInterface>hardware_interface/EffortJointInterface</hardwareInterface>
    </joint>
    <actuator name="Limb2Pitch2_actr">
      <hardwareInterface>hardware_interface/EffortJointInterface</hardwareInterface>
      <mechanicalReduction>1</mechanicalReduction>
    </actuator>
  </transmission>
  <transmission name="Limb2Roll2_tran">
    <type>transmission_interface/SimpleTransmission</type>
    <joint name="Limb2Roll2">
      <hardwareInterface>hardware_interface/EffortJointInterface</hardwareInterface>
    </joint>
    <actuator name="Limb2Roll2_actr">
      <hardwareInterface>hardware_interface/EffortJointInterface</hardwareInterface>
      <mechanicalReduction>1</mechanicalReduction>
    </actuator>
  </transmission>
  <transmission name="Limb2Pitch3_tran">
    <type>transmission_interface/SimpleTransmission</type>
    <joint name="Limb2Pitch3">
      <hardwareInterface>hardware_interface/EffortJointInterface</hardwareInterface>
    </joint>
    <actuator name="Limb2Pitch3_actr">
      <hardwareInterface>hardware_interface/EffortJointInterface</hardwareInterface>
      <mechanicalReduction>1</mechanicalReduction>
    </actuator>
  </transmission>
  <transmission name="Limb2Roll3_tran">
    <type>transmission_interface/SimpleTransmission</type>
    <joint name="Limb2Roll3">
      <hardwareInterface>hardware_interface/EffortJointInterface</hardwareInterface>
    </joint>
    <actuator name="Limb2Roll3_actr">
      <hardwareInterface>hardware_interface/EffortJointInterface</hardwareInterface>
      <mechanicalReduction>1</mechanicalReduction>
    </actuator>
  </transmission>
  <gazebo>
    <plugin filename="libgazebo_ros_control.so" name="control"/>
  </gazebo>
  <gazebo reference="base_link">
    <material>Gazebo/Silver</material>
    <mu1>0.2</mu1>
    <mu2>0.2</mu2>
    <selfCollide>true</selfCollide>
    <gravity>true</gravity>
  </gazebo>
  <gazebo reference="Body_connector_5">
    <material>Gazebo/Silver</material>
    <mu1>0.2</mu1>
    <mu2>0.2</mu2>
    <selfCollide>true</selfCollide>
  </gazebo>
  <gazebo reference="Limb0Connector2_2">
    <material>Gazebo/Silver</material>
    <mu1>0.2</mu1>
    <mu2>0.2</mu2>
    <selfCollide>true</selfCollide>
  </gazebo>
  <gazebo reference="Limb0Pitch2A_2">
    <material>Gazebo/Silver</material>
    <mu1>0.2</mu1>
    <mu2>0.2</mu2>
    <selfCollide>true</selfCollide>
  </gazebo>
  <gazebo reference="Limb0Pitch1B_2">
    <material>Gazebo/Silver</material>
    <mu1>0.2</mu1>
    <mu2>0.2</mu2>
    <selfCollide>true</selfCollide>
  </gazebo>
  <gazebo reference="Limb0Pitch1A_2">
    <material>Gazebo/Silver</material>
    <mu1>0.2</mu1>
    <mu2>0.2</mu2>
    <selfCollide>true</selfCollide>
  </gazebo>
  <gazebo reference="Limb0Roll1B_2">
    <material>Gazebo/Silver</material>
    <mu1>0.2</mu1>
    <mu2>0.2</mu2>
    <selfCollide>true</selfCollide>
  </gazebo>
  <gazebo reference="Limb0Connector3_3">
    <material>Gazebo/Silver</material>
    <mu1>0.2</mu1>
    <mu2>0.2</mu2>
    <selfCollide>true</selfCollide>
  </gazebo>
  <gazebo reference="Limb0Roll2A_3">
    <material>Gazebo/Silver</material>
    <mu1>0.2</mu1>
    <mu2>0.2</mu2>
    <selfCollide>true</selfCollide>
  </gazebo>
  <gazebo reference="Limb0Roll2B_2">
    <material>Gazebo/Silver</material>
    <mu1>0.2</mu1>
    <mu2>0.2</mu2>
    <selfCollide>true</selfCollide>
  </gazebo>
  <gazebo reference="Limb0Roll2C_2">
    <material>Gazebo/Silver</material>
    <mu1>0.2</mu1>
    <mu2>0.2</mu2>
    <selfCollide>true</selfCollide>
  </gazebo>
  <gazebo reference="Limb0Pitch3A_2">
    <material>Gazebo/Silver</material>
    <mu1>0.2</mu1>
    <mu2>0.2</mu2>
    <selfCollide>true</selfCollide>
  </gazebo>
  <gazebo reference="Limb0Pitch3B_2">
    <material>Gazebo/Silver</material>
    <mu1>0.2</mu1>
    <mu2>0.2</mu2>
    <selfCollide>true</selfCollide>
  </gazebo>
  <gazebo reference="Limb0Roll3A_2">
    <material>Gazebo/Silver</material>
    <mu1>0.2</mu1>
    <mu2>0.2</mu2>
    <selfCollide>true</selfCollide>
  </gazebo>
  <gazebo reference="Limb0Roll3B_2">
    <material>Gazebo/Silver</material>
    <mu1>0.2</mu1>
    <mu2>0.2</mu2>
    <selfCollide>true</selfCollide>
  </gazebo>
  <gazebo reference="Limb1Roll1B_1">
    <material>Gazebo/Silver</material>
    <mu1>0.2</mu1>
    <mu2>0.2</mu2>
    <selfCollide>true</selfCollide>
  </gazebo>
  <gazebo reference="Limb1Pitch1A_1">
    <material>Gazebo/Silver</material>
    <mu1>0.2</mu1>
    <mu2>0.2</mu2>
    <selfCollide>true</selfCollide>
  </gazebo>
  <gazebo reference="Limb1Pitch1B_1">
    <material>Gazebo/Silver</material>
    <mu1>0.2</mu1>
    <mu2>0.2</mu2>
    <selfCollide>true</selfCollide>
  </gazebo>
  <gazebo reference="Limb1Pitch2A_1">
    <material>Gazebo/Silver</material>
    <mu1>0.2</mu1>
    <mu2>0.2</mu2>
    <selfCollide>true</selfCollide>
  </gazebo>
  <gazebo reference="Limb1Connector2_1">
    <material>Gazebo/Silver</material>
    <mu1>0.2</mu1>
    <mu2>0.2</mu2>
    <selfCollide>true</selfCollide>
  </gazebo>
  <gazebo reference="Limb1Connector3_1">
    <material>Gazebo/Silver</material>
    <mu1>0.2</mu1>
    <mu2>0.2</mu2>
    <selfCollide>true</selfCollide>
  </gazebo>
  <gazebo reference="Limb1Roll2A_1">
    <material>Gazebo/Silver</material>
    <mu1>0.2</mu1>
    <mu2>0.2</mu2>
    <selfCollide>true</selfCollide>
  </gazebo>
  <gazebo reference="Limb1Roll2B_1">
    <material>Gazebo/Silver</material>
    <mu1>0.2</mu1>
    <mu2>0.2</mu2>
    <selfCollide>true</selfCollide>
  </gazebo>
  <gazebo reference="LimbRoll2C__1__1">
    <material>Gazebo/Silver</material>
    <mu1>0.2</mu1>
    <mu2>0.2</mu2>
    <selfCollide>true</selfCollide>
  </gazebo>
  <gazebo reference="Limb1Pitch3A_1">
    <material>Gazebo/Silver</material>
    <mu1>0.2</mu1>
    <mu2>0.2</mu2>
    <selfCollide>true</selfCollide>
  </gazebo>
  <gazebo reference="Limb1Pitch3B_1">
    <material>Gazebo/Silver</material>
    <mu1>0.2</mu1>
    <mu2>0.2</mu2>
    <selfCollide>true</selfCollide>
  </gazebo>
  <gazebo reference="Limb1Roll3A_1">
    <material>Gazebo/Silver</material>
    <mu1>0.2</mu1>
    <mu2>0.2</mu2>
    <selfCollide>true</selfCollide>
  </gazebo>
  <gazebo reference="Limb1Roll3B_1">
    <material>Gazebo/Silver</material>
    <mu1>0.2</mu1>
    <mu2>0.2</mu2>
    <selfCollide>true</selfCollide>
  </gazebo>
  <gazebo reference="Limb0Connector1_1">
    <material>Gazebo/Silver</material>
    <mu1>0.2</mu1>
    <mu2>0.2</mu2>
    <selfCollide>true</selfCollide>
  </gazebo>
  <gazebo reference="Body_connector__2__1">
    <material>Gazebo/Silver</material>
    <mu1>0.2</mu1>
    <mu2>0.2</mu2>
    <selfCollide>true</selfCollide>
  </gazebo>
  <gazebo reference="Limb0Roll1A_2">
    <material>Gazebo/Silver</material>
    <mu1>0.2</mu1>
    <mu2>0.2</mu2>
    <selfCollide>true</selfCollide>
  </gazebo>
  <gazebo reference="Limb1Roll1A_1">
    <material>Gazebo/Silver</material>
    <mu1>0.2</mu1>
    <mu2>0.2</mu2>
    <selfCollide>true</selfCollide>
  </gazebo>
  <gazebo reference="Limb1Connector1_1">
    <material>Gazebo/Silver</material>
    <mu1>0.2</mu1>
    <mu2>0.2</mu2>
    <selfCollide>true</selfCollide>
  </gazebo>
  <gazebo reference="Limb3BodyConnector_1">
    <material>Gazebo/Silver</material>
    <mu1>0.2</mu1>
    <mu2>0.2</mu2>
    <selfCollide>true</selfCollide>
  </gazebo>
  <gazebo reference="Body_connector__3__1">
    <material>Gazebo/Silver</material>
    <mu1>0.2</mu1>
    <mu2>0.2</mu2>
    <selfCollide>true</selfCollide>
  </gazebo>
  <gazebo reference="Limb3Roll1A_1">
    <material>Gazebo/Silver</material>
    <mu1>0.2</mu1>
    <mu2>0.2</mu2>
    <selfCollide>true</selfCollide>
  </gazebo>
  <gazebo reference="Limb3Roll1B_1">
    <material>Gazebo/Silver</material>
    <mu1>0.2</mu1>
    <mu2>0.2</mu2>
    <selfCollide>true</selfCollide>
  </gazebo>
  <gazebo reference="Limb3Pitch1A_1">
    <material>Gazebo/Silver</material>
    <mu1>0.2</mu1>
    <mu2>0.2</mu2>
    <selfCollide>true</selfCollide>
  </gazebo>
  <gazebo reference="Limb3Pitch1B_1">
    <material>Gazebo/Silver</material>
    <mu1>0.2</mu1>
    <mu2>0.2</mu2>
    <selfCollide>true</selfCollide>
  </gazebo>
  <gazebo reference="Limb3Pitch2A_1">
    <material>Gazebo/Silver</material>
    <mu1>0.2</mu1>
    <mu2>0.2</mu2>
    <selfCollide>true</selfCollide>
  </gazebo>
  <gazebo reference="Limb3Connector2_1">
    <material>Gazebo/Silver</material>
    <mu1>0.2</mu1>
    <mu2>0.2</mu2>
    <selfCollide>true</selfCollide>
  </gazebo>
  <gazebo reference="Limb3Connector3_1">
    <material>Gazebo/Silver</material>
    <mu1>0.2</mu1>
    <mu2>0.2</mu2>
    <selfCollide>true</selfCollide>
  </gazebo>
  <gazebo reference="Limb3Roll2A_1">
    <material>Gazebo/Silver</material>
    <mu1>0.2</mu1>
    <mu2>0.2</mu2>
    <selfCollide>true</selfCollide>
  </gazebo>
  <gazebo reference="Limb3Roll2B_1">
    <material>Gazebo/Silver</material>
    <mu1>0.2</mu1>
    <mu2>0.2</mu2>
    <selfCollide>true</selfCollide>
  </gazebo>
  <gazebo reference="Limb3Roll2C_1">
    <material>Gazebo/Silver</material>
    <mu1>0.2</mu1>
    <mu2>0.2</mu2>
    <selfCollide>true</selfCollide>
  </gazebo>
  <gazebo reference="Limb3Pitch3A_1">
    <material>Gazebo/Silver</material>
    <mu1>0.2</mu1>
    <mu2>0.2</mu2>
    <selfCollide>true</selfCollide>
  </gazebo>
  <gazebo reference="Limb3Pitch3B_1">
    <material>Gazebo/Silver</material>
    <mu1>0.2</mu1>
    <mu2>0.2</mu2>
    <selfCollide>true</selfCollide>
  </gazebo>
  <gazebo reference="Limb3Roll3A_1">
    <material>Gazebo/Silver</material>
    <mu1>0.2</mu1>
    <mu2>0.2</mu2>
    <selfCollide>true</selfCollide>
  </gazebo>
  <gazebo reference="Limb3Roll3B_1">
    <material>Gazebo/Silver</material>
    <mu1>0.2</mu1>
    <mu2>0.2</mu2>
    <selfCollide>true</selfCollide>
  </gazebo>
  <gazebo reference="Limb0Connector1__1__1">
    <material>Gazebo/Silver</material>
    <mu1>0.2</mu1>
    <mu2>0.2</mu2>
    <selfCollide>true</selfCollide>
  </gazebo>
  <gazebo reference="Limb0Roll1A__1__1">
    <material>Gazebo/Silver</material>
    <mu1>0.2</mu1>
    <mu2>0.2</mu2>
    <selfCollide>true</selfCollide>
  </gazebo>
  <gazebo reference="Limb0Roll1B__1__1">
    <material>Gazebo/Silver</material>
    <mu1>0.2</mu1>
    <mu2>0.2</mu2>
    <selfCollide>true</selfCollide>
  </gazebo>
  <gazebo reference="Limb0Pitch1A__1__1">
    <material>Gazebo/Silver</material>
    <mu1>0.2</mu1>
    <mu2>0.2</mu2>
    <selfCollide>true</selfCollide>
  </gazebo>
  <gazebo reference="Limb0Pitch1B__1__1">
    <material>Gazebo/Silver</material>
    <mu1>0.2</mu1>
    <mu2>0.2</mu2>
    <selfCollide>true</selfCollide>
  </gazebo>
  <gazebo reference="Limb0Pitch2A__1__1">
    <material>Gazebo/Silver</material>
    <mu1>0.2</mu1>
    <mu2>0.2</mu2>
    <selfCollide>true</selfCollide>
  </gazebo>
  <gazebo reference="Limb0Connector2__1__1">
    <material>Gazebo/Silver</material>
    <mu1>0.2</mu1>
    <mu2>0.2</mu2>
    <selfCollide>true</selfCollide>
  </gazebo>
  <gazebo reference="Limb0Connector3__1__1">
    <material>Gazebo/Silver</material>
    <mu1>0.2</mu1>
    <mu2>0.2</mu2>
    <selfCollide>true</selfCollide>
  </gazebo>
  <gazebo reference="Limb0Roll2A__1__1">
    <material>Gazebo/Silver</material>
    <mu1>0.2</mu1>
    <mu2>0.2</mu2>
    <selfCollide>true</selfCollide>
  </gazebo>
  <gazebo reference="Limb0Roll2B__1__1">
    <material>Gazebo/Silver</material>
    <mu1>0.2</mu1>
    <mu2>0.2</mu2>
    <selfCollide>true</selfCollide>
  </gazebo>
  <gazebo reference="Limb0Roll2C__1__1">
    <material>Gazebo/Silver</material>
    <mu1>0.2</mu1>
    <mu2>0.2</mu2>
    <selfCollide>true</selfCollide>
  </gazebo>
  <gazebo reference="Limb0Pitch3A__1__1">
    <material>Gazebo/Silver</material>
    <mu1>0.2</mu1>
    <mu2>0.2</mu2>
    <selfCollide>true</selfCollide>
  </gazebo>
  <gazebo reference="Limb0Pitch3B__1__1">
    <material>Gazebo/Silver</material>
    <mu1>0.2</mu1>
    <mu2>0.2</mu2>
    <selfCollide>true</selfCollide>
  </gazebo>
  <gazebo reference="Limb0Roll3A__1__1">
    <material>Gazebo/Silver</material>
    <mu1>0.2</mu1>
    <mu2>0.2</mu2>
    <selfCollide>true</selfCollide>
  </gazebo>
  <gazebo reference="Limb0Roll3B__1__1">
    <material>Gazebo/Silver</material>
    <mu1>0.2</mu1>
    <mu2>0.2</mu2>
    <selfCollide>true</selfCollide>
  </gazebo>
  <gazebo reference="Limb3Wheel_1">
    <material>Gazebo/Silver</material>
    <mu1>0.2</mu1>
    <mu2>0.2</mu2>
    <selfCollide>true</selfCollide>
  </gazebo>
  <gazebo reference="Limb2Wheel_1">
    <material>Gazebo/Silver</material>
    <mu1>0.2</mu1>
    <mu2>0.2</mu2>
    <selfCollide>true</selfCollide>
  </gazebo>
  <gazebo reference="Limb0Wheel_1">
    <material>Gazebo/Silver</material>
    <mu1>0.2</mu1>
    <mu2>0.2</mu2>
    <selfCollide>true</selfCollide>
  </gazebo>
  <gazebo reference="Limb1Wheel_1">
    <material>Gazebo/Silver</material>
    <mu1>0.2</mu1>
    <mu2>0.2</mu2>
    <selfCollide>true</selfCollide>
  </gazebo>
  <gazebo reference="Connector4_1">
    <material>Gazebo/Silver</material>
    <mu1>0.2</mu1>
    <mu2>0.2</mu2>
    <selfCollide>true</selfCollide>
  </gazebo>
  <link name="base_link">
    <inertial>
      <origin rpy="0 0 0" xyz="-0.002718753748846342 -0.002205739141353069 0.7033681348241015"/>
      <mass value="83.58553795695674"/>
      <inertia ixx="0.627961" ixy="6e-06" ixz="0.001498" iyy="0.622623" iyz="-1.7e-05" izz="0.957797"/>
    </inertial>
    <visual>
      <origin rpy="0 0 0" xyz="0 0 0"/>
      <geometry>
        <mesh filename="package://rviz_basic/meshes/base_link.stl" scale="0.001 0.001 0.001"/>
      </geometry>
      <material name="silver"/>
    </visual>
    <collision>
      <origin rpy="0 0 0" xyz="0 0 0"/>
      <geometry>
        <mesh filename="package://rviz_basic/meshes/base_link.stl" scale="0.001 0.001 0.001"/>
      </geometry>
    </collision>
  </link>
  <link name="Body_connector_5">
    <inertial>
      <origin rpy="0 0 0" xyz="-0.00677930927205897 0.006691164760938034 -0.00852535545613553"/>
      <mass value="1.00227146305622"/>
      <inertia ixx="0.000536" ixy="-8.8e-05" ixz="0.000112" iyy="0.000536" iyz="-0.000112" izz="0.00059"/>
    </inertial>
    <visual>
      <origin rpy="0 0 0" xyz="0.104123 -0.099642 -0.676307"/>
      <geometry>
        <mesh filename="package://rviz_basic/meshes/Body_connector_5.stl" scale="0.001 0.001 0.001"/>
      </geometry>
      <material name="silver"/>
    </visual>
    <collision>
      <origin rpy="0 0 0" xyz="0.104123 -0.099642 -0.676307"/>
      <geometry>
        <mesh filename="package://rviz_basic/meshes/Body_connector_5.stl" scale="0.001 0.001 0.001"/>
      </geometry>
    </collision>
  </link>
  <link name="Limb0Connector2_2">
    <inertial>
      <origin rpy="0 0 0" xyz="0.002103021656725712 -0.00210349984971947 -0.0026738550137934136"/>
      <mass value="0.028818583393616055"/>
      <inertia ixx="1e-05" ixy="-2e-06" ixz="-3e-06" iyy="1e-05" iyz="3e-06" izz="1.1e-05"/>
    </inertial>
    <visual>
      <origin rpy="0 0 0" xyz="-0.311981 0.316466 -0.406184"/>
      <geometry>
        <mesh filename="package://rviz_basic/meshes/Limb0Connector2_2.stl" scale="0.001 0.001 0.001"/>
      </geometry>
      <material name="silver"/>
    </visual>
    <collision>
      <origin rpy="0 0 0" xyz="-0.311981 0.316466 -0.406184"/>
      <geometry>
        <mesh filename="package://rviz_basic/meshes/Limb0Connector2_2.stl" scale="0.001 0.001 0.001"/>
      </geometry>
    </collision>
  </link>
  <link name="Limb0Pitch2A_2">
    <inertial>
      <origin rpy="0 0 0" xyz="0.029959620301540757 -0.029959103553448052 -0.03808776464443614"/>
      <mass value="0.18660217560053788"/>
      <inertia ixx="9.9e-05" ixy="-0.0" ixz="-4e-06" iyy="0.000101" iyz="2e-06" izz="0.0001"/>
    </inertial>
    <visual>
      <origin rpy="0 0 0" xyz="-0.267282 0.271768 -0.46301"/>
      <geometry>
        <mesh filename="package://rviz_basic/meshes/Limb0Pitch2A_2.stl" scale="0.001 0.001 0.001"/>
      </geometry>
      <material name="silver"/>
    </visual>
    <collision>
      <origin rpy="0 0 0" xyz="-0.267282 0.271768 -0.46301"/>
      <geometry>
        <mesh filename="package://rviz_basic/meshes/Limb0Pitch2A_2.stl" scale="0.001 0.001 0.001"/>
      </geometry>
    </collision>
  </link>
  <link name="Limb0Pitch1B_2">
    <inertial>
      <origin rpy="0 0 0" xyz="0.06822924852709525 -0.0682287306107931 -0.0867406044238917"/>
      <mass value="0.7729993259283914"/>
      <inertia ixx="0.001978" ixy="0.000552" ixz="0.000714" iyy="0.001971" iyz="-0.000709" izz="0.001637"/>
    </inertial>
    <visual>
      <origin rpy="0 0 0" xyz="-0.169998 0.174484 -0.586689"/>
      <geometry>
        <mesh filename="package://rviz_basic/meshes/Limb0Pitch1B_2.stl" scale="0.001 0.001 0.001"/>
      </geometry>
      <material name="silver"/>
    </visual>
    <collision>
      <origin rpy="0 0 0" xyz="-0.169998 0.174484 -0.586689"/>
      <geometry>
        <mesh filename="package://rviz_basic/meshes/Limb0Pitch1B_2.stl" scale="0.001 0.001 0.001"/>
      </geometry>
    </collision>
  </link>
  <link name="Limb0Pitch1A_2">
    <inertial>
      <origin rpy="0 0 0" xyz="0.02622252256340238 -0.026226373841744727 -0.03333985784790783"/>
      <mass value="3.3477117479193077"/>
      <inertia ixx="0.003424" ixy="0.000327" ixz="0.000518" iyy="0.003364" iyz="-0.000471" izz="0.003217"/>
    </inertial>
    <visual>
      <origin rpy="0 0 0" xyz="-0.135835 0.140315 -0.630126"/>
      <geometry>
        <mesh filename="package://rviz_basic/meshes/Limb0Pitch1A_2.stl" scale="0.001 0.001 0.001"/>
      </geometry>
      <material name="silver"/>
    </visual>
    <collision>
      <origin rpy="0 0 0" xyz="-0.135835 0.140315 -0.630126"/>
      <geometry>
        <mesh filename="package://rviz_basic/meshes/Limb0Pitch1A_2.stl" scale="0.001 0.001 0.001"/>
      </geometry>
    </collision>
  </link>
  <link name="Limb0Roll1B_2">
    <inertial>
      <origin rpy="0 0 0" xyz="0.0013142684746978994 -0.0013146802594786178 -0.0016713372811122396"/>
      <mass value="0.1621742617893587"/>
      <inertia ixx="6.8e-05" ixy="-1.5e-05" ixz="-1.9e-05" iyy="6.8e-05" iyz="1.9e-05" izz="7.7e-05"/>
    </inertial>
    <visual>
      <origin rpy="0 0 0" xyz="-0.133206 0.137686 -0.633469"/>
      <geometry>
        <mesh filename="package://rviz_basic/meshes/Limb0Roll1B_2.stl" scale="0.001 0.001 0.001"/>
      </geometry>
      <material name="silver"/>
    </visual>
    <collision>
      <origin rpy="0 0 0" xyz="-0.133206 0.137686 -0.633469"/>
      <geometry>
        <mesh filename="package://rviz_basic/meshes/Limb0Roll1B_2.stl" scale="0.001 0.001 0.001"/>
      </geometry>
    </collision>
  </link>
  <link name="Limb0Connector3_3">
    <inertial>
      <origin rpy="0 0 0" xyz="0.0020728386970867985 -0.0020723168893330146 -0.0026346561677129676"/>
      <mass value="0.028067093486926365"/>
      <inertia ixx="1e-05" ixy="-2e-06" ixz="-3e-06" iyy="1e-05" iyz="3e-06" izz="1.1e-05"/>
    </inertial>
    <visual>
      <origin rpy="0 0 0" xyz="-0.316187 0.320673 -0.400836"/>
      <geometry>
        <mesh filename="package://rviz_basic/meshes/Limb0Connector3_3.stl" scale="0.001 0.001 0.001"/>
      </geometry>
      <material name="silver"/>
    </visual>
    <collision>
      <origin rpy="0 0 0" xyz="-0.316187 0.320673 -0.400836"/>
      <geometry>
        <mesh filename="package://rviz_basic/meshes/Limb0Connector3_3.stl" scale="0.001 0.001 0.001"/>
      </geometry>
    </collision>
  </link>
  <link name="Limb0Roll2A_3">
    <inertial>
      <origin rpy="0 0 0" xyz="0.006681624363454208 -0.006681102554122131 -0.008494343828823636"/>
      <mass value="0.09449902324417689"/>
      <inertia ixx="3.8e-05" ixy="-6e-06" ixz="-8e-06" iyy="3.8e-05" iyz="8e-06" izz="4.2e-05"/>
    </inertial>
    <visual>
      <origin rpy="0 0 0" xyz="-0.320394 0.32488 -0.395488"/>
      <geometry>
        <mesh filename="package://rviz_basic/meshes/Limb0Roll2A_3.stl" scale="0.001 0.001 0.001"/>
      </geometry>
      <material name="silver"/>
    </visual>
    <collision>
      <origin rpy="0 0 0" xyz="-0.320394 0.32488 -0.395488"/>
      <geometry>
        <mesh filename="package://rviz_basic/meshes/Limb0Roll2A_3.stl" scale="0.001 0.001 0.001"/>
      </geometry>
    </collision>
  </link>
  <link name="Limb0Roll2B_2">
    <inertial>
      <origin rpy="0 0 0" xyz="0.0013145066946149697 -0.001314984883888537 -0.0016710665060420404"/>
      <mass value="0.14254348347132964"/>
      <inertia ixx="5.3e-05" ixy="-1.1e-05" ixz="-1.4e-05" iyy="5.3e-05" iyz="1.4e-05" izz="6e-05"/>
    </inertial>
    <visual>
      <origin rpy="0 0 0" xyz="-0.333541 0.338026 -0.378774"/>
      <geometry>
        <mesh filename="package://rviz_basic/meshes/Limb0Roll2B_2.stl" scale="0.001 0.001 0.001"/>
      </geometry>
      <material name="silver"/>
    </visual>
    <collision>
      <origin rpy="0 0 0" xyz="-0.333541 0.338026 -0.378774"/>
      <geometry>
        <mesh filename="package://rviz_basic/meshes/Limb0Roll2B_2.stl" scale="0.001 0.001 0.001"/>
      </geometry>
    </collision>
  </link>
  <link name="Limb0Roll2C_2">
    <inertial>
      <origin rpy="0 0 0" xyz="-0.0003246307642108537 -0.07136701847741012 -0.03596102418659597"/>
      <mass value="5.5447698039525"/>
      <inertia ixx="0.015358" ixy="-0.000788" ixz="0.000257" iyy="0.006867" iyz="-0.004143" izz="0.01392"/>
    </inertial>
    <visual>
      <origin rpy="0 0 0" xyz="-0.33617 0.340656 -0.375432"/>
      <geometry>
        <mesh filename="package://rviz_basic/meshes/Limb0Roll2C_2.stl" scale="0.001 0.001 0.001"/>
      </geometry>
      <material name="silver"/>
    </visual>
    <collision>
      <origin rpy="0 0 0" xyz="-0.33617 0.340656 -0.375432"/>
      <geometry>
        <mesh filename="package://rviz_basic/meshes/Limb0Roll2C_2.stl" scale="0.001 0.001 0.001"/>
      </geometry>
    </collision>
  </link>
  <link name="Limb0Pitch3A_2">
    <inertial>
      <origin rpy="0 0 0" xyz="0.0007974074761619154 0.00095487844214176 -0.0001240472342625143"/>
      <mass value="0.07127174173566476"/>
      <inertia ixx="2.9e-05" ixy="1e-05" ixz="-1e-06" iyy="3.3e-05" iyz="-2e-06" izz="2.1e-05"/>
    </inertial>
    <visual>
      <origin rpy="0 0 0" xyz="-0.36158 0.443149 -0.304018"/>
      <geometry>
        <mesh filename="package://rviz_basic/meshes/Limb0Pitch3A_2.stl" scale="0.001 0.001 0.001"/>
      </geometry>
      <material name="silver"/>
    </visual>
    <collision>
      <origin rpy="0 0 0" xyz="-0.36158 0.443149 -0.304018"/>
      <geometry>
        <mesh filename="package://rviz_basic/meshes/Limb0Pitch3A_2.stl" scale="0.001 0.001 0.001"/>
      </geometry>
    </collision>
  </link>
  <link name="Limb0Pitch3B_2">
    <inertial>
      <origin rpy="0 0 0" xyz="0.0007972556022602384 0.000954808730158685 -0.0001246723453181553"/>
      <mass value="0.07127174173566476"/>
      <inertia ixx="2.9e-05" ixy="1e-05" ixz="-1e-06" iyy="3.3e-05" iyz="-2e-06" izz="2.1e-05"/>
    </inertial>
    <visual>
      <origin rpy="0 0 0" xyz="-0.363174 0.441239 -0.30377"/>
      <geometry>
        <mesh filename="package://rviz_basic/meshes/Limb0Pitch3B_2.stl" scale="0.001 0.001 0.001"/>
      </geometry>
      <material name="silver"/>
    </visual>
    <collision>
      <origin rpy="0 0 0" xyz="-0.363174 0.441239 -0.30377"/>
      <geometry>
        <mesh filename="package://rviz_basic/meshes/Limb0Pitch3B_2.stl" scale="0.001 0.001 0.001"/>
      </geometry>
    </collision>
  </link>
  <link name="Limb0Roll3A_2">
    <inertial>
      <origin rpy="0 0 0" xyz="0.02690119223229953 0.03172481863983617 -0.004455451652114806"/>
      <mass value="2.8490901932138626"/>
      <inertia ixx="0.002365" ixy="-0.000127" ixz="0.000201" iyy="0.002287" iyz="-0.000118" izz="0.002499"/>
    </inertial>
    <visual>
      <origin rpy="0 0 0" xyz="-0.364768 0.439329 -0.303521"/>
      <geometry>
        <mesh filename="package://rviz_basic/meshes/Limb0Roll3A_2.stl" scale="0.001 0.001 0.001"/>
      </geometry>
      <material name="silver"/>
    </visual>
    <collision>
      <origin rpy="0 0 0" xyz="-0.364768 0.439329 -0.303521"/>
      <geometry>
        <mesh filename="package://rviz_basic/meshes/Limb0Roll3A_2.stl" scale="0.001 0.001 0.001"/>
      </geometry>
    </collision>
  </link>
  <link name="Limb0Roll3B_2">
    <inertial>
      <origin rpy="0 0 0" xyz="0.002628818559336943 -0.0026292967333145234 -0.003342328974139386"/>
      <mass value="0.28508696694265934"/>
      <inertia ixx="0.000107" ixy="-2.2e-05" ixz="-2.8e-05" iyy="0.000107" iyz="2.8e-05" izz="0.000121"/>
    </inertial>
    <visual>
      <origin rpy="0 0 0" xyz="-0.417679 0.422164 -0.271808"/>
      <geometry>
        <mesh filename="package://rviz_basic/meshes/Limb0Roll3B_2.stl" scale="0.001 0.001 0.001"/>
      </geometry>
      <material name="silver"/>
    </visual>
    <collision>
      <origin rpy="0 0 0" xyz="-0.417679 0.422164 -0.271808"/>
      <geometry>
        <mesh filename="package://rviz_basic/meshes/Limb0Roll3B_2.stl" scale="0.001 0.001 0.001"/>
      </geometry>
    </collision>
  </link>
  <link name="Limb1Roll1B_1">
    <inertial>
      <origin rpy="0 0 0" xyz="0.001314715250233106 0.0013146995287366126 -0.0016716503046055875"/>
      <mass value="0.1621742617893587"/>
      <inertia ixx="6.8e-05" ixy="1.5e-05" ixz="-1.9e-05" iyy="6.8e-05" iyz="-1.9e-05" izz="7.7e-05"/>
    </inertial>
    <visual>
      <origin rpy="0 0 0" xyz="-0.133236 -0.133352 -0.633562"/>
      <geometry>
        <mesh filename="package://rviz_basic/meshes/Limb1Roll1B_1.stl" scale="0.001 0.001 0.001"/>
      </geometry>
      <material name="silver"/>
    </visual>
    <collision>
      <origin rpy="0 0 0" xyz="-0.133236 -0.133352 -0.633562"/>
      <geometry>
        <mesh filename="package://rviz_basic/meshes/Limb1Roll1B_1.stl" scale="0.001 0.001 0.001"/>
      </geometry>
    </collision>
  </link>
  <link name="Limb1Pitch1A_1">
    <inertial>
      <origin rpy="0 0 0" xyz="0.026225903022392 0.02622280443795691 -0.03334068607561047"/>
      <mass value="3.3477117479193077"/>
      <inertia ixx="0.003389" ixy="-0.000316" ixz="0.000499" iyy="0.003392" iyz="0.000501" izz="0.003225"/>
    </inertial>
    <visual>
      <origin rpy="0 0 0" xyz="-0.135865 -0.135981 -0.630219"/>
      <geometry>
        <mesh filename="package://rviz_basic/meshes/Limb1Pitch1A_1.stl" scale="0.001 0.001 0.001"/>
      </geometry>
      <material name="silver"/>
    </visual>
    <collision>
      <origin rpy="0 0 0" xyz="-0.135865 -0.135981 -0.630219"/>
      <geometry>
        <mesh filename="package://rviz_basic/meshes/Limb1Pitch1A_1.stl" scale="0.001 0.001 0.001"/>
      </geometry>
    </collision>
  </link>
  <link name="Limb1Pitch1B_1">
    <inertial>
      <origin rpy="0 0 0" xyz="0.06822898471093783 0.0682285127569274 -0.08674066290451965"/>
      <mass value="0.7729993259283914"/>
      <inertia ixx="0.001974" ixy="-0.000551" ixz="0.000712" iyy="0.001974" iyz="0.000712" izz="0.001638"/>
    </inertial>
    <visual>
      <origin rpy="0 0 0" xyz="-0.170033 -0.170145 -0.586781"/>
      <geometry>
        <mesh filename="package://rviz_basic/meshes/Limb1Pitch1B_1.stl" scale="0.001 0.001 0.001"/>
      </geometry>
      <material name="silver"/>
    </visual>
    <collision>
      <origin rpy="0 0 0" xyz="-0.170033 -0.170145 -0.586781"/>
      <geometry>
        <mesh filename="package://rviz_basic/meshes/Limb1Pitch1B_1.stl" scale="0.001 0.001 0.001"/>
      </geometry>
    </collision>
  </link>
  <link name="Limb1Pitch2A_1">
    <inertial>
      <origin rpy="0 0 0" xyz="0.029959346570444356 0.029958879463168275 -0.03808783582946196"/>
      <mass value="0.18660217560053788"/>
      <inertia ixx="0.0001" ixy="-0.0" ixz="-3e-06" iyy="0.0001" iyz="-3e-06" izz="9.9e-05"/>
    </inertial>
    <visual>
      <origin rpy="0 0 0" xyz="-0.267317 -0.267429 -0.463102"/>
      <geometry>
        <mesh filename="package://rviz_basic/meshes/Limb1Pitch2A_1.stl" scale="0.001 0.001 0.001"/>
      </geometry>
      <material name="silver"/>
    </visual>
    <collision>
      <origin rpy="0 0 0" xyz="-0.267317 -0.267429 -0.463102"/>
      <geometry>
        <mesh filename="package://rviz_basic/meshes/Limb1Pitch2A_1.stl" scale="0.001 0.001 0.001"/>
      </geometry>
    </collision>
  </link>
  <link name="Limb1Connector2_1">
    <inertial>
      <origin rpy="0 0 0" xyz="0.0021037524558481513 0.002103278638910855 -0.002673920370475591"/>
      <mass value="0.028818583393616055"/>
      <inertia ixx="1e-05" ixy="2e-06" ixz="-3e-06" iyy="1e-05" iyz="-3e-06" izz="1.1e-05"/>
    </inertial>
    <visual>
      <origin rpy="0 0 0" xyz="-0.312015 -0.312127 -0.406276"/>
      <geometry>
        <mesh filename="package://rviz_basic/meshes/Limb1Connector2_1.stl" scale="0.001 0.001 0.001"/>
      </geometry>
      <material name="silver"/>
    </visual>
    <collision>
      <origin rpy="0 0 0" xyz="-0.312015 -0.312127 -0.406276"/>
      <geometry>
        <mesh filename="package://rviz_basic/meshes/Limb1Connector2_1.stl" scale="0.001 0.001 0.001"/>
      </geometry>
    </collision>
  </link>
  <link name="Limb1Connector3_1">
    <inertial>
      <origin rpy="0 0 0" xyz="0.002072569494944443 0.002072095680584418 -0.002634721523767869"/>
      <mass value="0.028067093486926365"/>
      <inertia ixx="1e-05" ixy="2e-06" ixz="-3e-06" iyy="1e-05" iyz="-3e-06" izz="1.1e-05"/>
    </inertial>
    <visual>
      <origin rpy="0 0 0" xyz="-0.316222 -0.316334 -0.400928"/>
      <geometry>
        <mesh filename="package://rviz_basic/meshes/Limb1Connector3_1.stl" scale="0.001 0.001 0.001"/>
      </geometry>
      <material name="silver"/>
    </visual>
    <collision>
      <origin rpy="0 0 0" xyz="-0.316222 -0.316334 -0.400928"/>
      <geometry>
        <mesh filename="package://rviz_basic/meshes/Limb1Connector3_1.stl" scale="0.001 0.001 0.001"/>
      </geometry>
    </collision>
  </link>
  <link name="Limb1Roll2A_1">
    <inertial>
      <origin rpy="0 0 0" xyz="0.006681355158644264 0.006680881349721002 -0.008494409183558094"/>
      <mass value="0.09449902324417689"/>
      <inertia ixx="3.8e-05" ixy="6e-06" ixz="-8e-06" iyy="3.8e-05" iyz="-8e-06" izz="4.2e-05"/>
    </inertial>
    <visual>
      <origin rpy="0 0 0" xyz="-0.320429 -0.320541 -0.39558"/>
      <geometry>
        <mesh filename="package://rviz_basic/meshes/Limb1Roll2A_1.stl" scale="0.001 0.001 0.001"/>
      </geometry>
      <material name="silver"/>
    </visual>
    <collision>
      <origin rpy="0 0 0" xyz="-0.320429 -0.320541 -0.39558"/>
      <geometry>
        <mesh filename="package://rviz_basic/meshes/Limb1Roll2A_1.stl" scale="0.001 0.001 0.001"/>
      </geometry>
    </collision>
  </link>
  <link name="Limb1Roll2B_1">
    <inertial>
      <origin rpy="0 0 0" xyz="0.001314237487446246 0.0013147636833246157 -0.0016711318596070446"/>
      <mass value="0.14254348347132964"/>
      <inertia ixx="5.3e-05" ixy="1.1e-05" ixz="-1.4e-05" iyy="5.3e-05" iyz="-1.4e-05" izz="6e-05"/>
    </inertial>
    <visual>
      <origin rpy="0 0 0" xyz="-0.333576 -0.333687 -0.378866"/>
      <geometry>
        <mesh filename="package://rviz_basic/meshes/Limb1Roll2B_1.stl" scale="0.001 0.001 0.001"/>
      </geometry>
      <material name="silver"/>
    </visual>
    <collision>
      <origin rpy="0 0 0" xyz="-0.333576 -0.333687 -0.378866"/>
      <geometry>
        <mesh filename="package://rviz_basic/meshes/Limb1Roll2B_1.stl" scale="0.001 0.001 0.001"/>
      </geometry>
    </collision>
  </link>
  <link name="LimbRoll2C__1__1">
    <inertial>
      <origin rpy="0 0 0" xyz="0.06879531516956255 -0.0035389192688810023 -0.04051265787606534"/>
      <mass value="5.5447698039525"/>
      <inertia ixx="0.007579" ixy="0.001164" ixz="0.00462" iyy="0.015187" iyz="-5.5e-05" izz="0.013379"/>
    </inertial>
    <visual>
      <origin rpy="0 0 0" xyz="-0.336205 -0.336316 -0.375524"/>
      <geometry>
        <mesh filename="package://rviz_basic/meshes/LimbRoll2C__1__1.stl" scale="0.001 0.001 0.001"/>
      </geometry>
      <material name="silver"/>
    </visual>
    <collision>
      <origin rpy="0 0 0" xyz="-0.336205 -0.336316 -0.375524"/>
      <geometry>
        <mesh filename="package://rviz_basic/meshes/LimbRoll2C__1__1.stl" scale="0.001 0.001 0.001"/>
      </geometry>
    </collision>
  </link>
  <link name="Limb1Pitch3A_1">
    <inertial>
      <origin rpy="0 0 0" xyz="-0.000892133048895849 0.0008759498560332313 -1.2716647066313147e-05"/>
      <mass value="0.07127174173566476"/>
      <inertia ixx="3.1e-05" ixy="-1e-05" ixz="0.0" iyy="3.1e-05" iyz="-0.0" izz="2.1e-05"/>
    </inertial>
    <visual>
      <origin rpy="0 0 0" xyz="-0.435933 -0.35827 -0.299216"/>
      <geometry>
        <mesh filename="package://rviz_basic/meshes/Limb1Pitch3A_1.stl" scale="0.001 0.001 0.001"/>
      </geometry>
      <material name="silver"/>
    </visual>
    <collision>
      <origin rpy="0 0 0" xyz="-0.435933 -0.35827 -0.299216"/>
      <geometry>
        <mesh filename="package://rviz_basic/meshes/Limb1Pitch3A_1.stl" scale="0.001 0.001 0.001"/>
      </geometry>
    </collision>
  </link>
  <link name="Limb1Pitch3B_1">
    <inertial>
      <origin rpy="0 0 0" xyz="-0.0008923653274860999 0.0008759009880966451 -1.289505726209672e-05"/>
      <mass value="0.07127174173566476"/>
      <inertia ixx="3.1e-05" ixy="-1e-05" ixz="0.0" iyy="3.1e-05" iyz="-0.0" izz="2.1e-05"/>
    </inertial>
    <visual>
      <origin rpy="0 0 0" xyz="-0.434149 -0.360021 -0.29919"/>
      <geometry>
        <mesh filename="package://rviz_basic/meshes/Limb1Pitch3B_1.stl" scale="0.001 0.001 0.001"/>
      </geometry>
      <material name="silver"/>
    </visual>
    <collision>
      <origin rpy="0 0 0" xyz="-0.434149 -0.360021 -0.29919"/>
      <geometry>
        <mesh filename="package://rviz_basic/meshes/Limb1Pitch3B_1.stl" scale="0.001 0.001 0.001"/>
      </geometry>
    </collision>
  </link>
  <link name="Limb1Roll3A_1">
    <inertial>
      <origin rpy="0 0 0" xyz="-0.029622317213466032 0.029530074249443317 -0.0007334196749793631"/>
      <mass value="2.8490901932138626"/>
      <inertia ixx="0.002326" ixy="0.000133" ixz="0.000154" iyy="0.00232" iyz="0.000172" izz="0.002505"/>
    </inertial>
    <visual>
      <origin rpy="0 0 0" xyz="-0.432365 -0.361772 -0.299164"/>
      <geometry>
        <mesh filename="package://rviz_basic/meshes/Limb1Roll3A_1.stl" scale="0.001 0.001 0.001"/>
      </geometry>
      <material name="silver"/>
    </visual>
    <collision>
      <origin rpy="0 0 0" xyz="-0.432365 -0.361772 -0.299164"/>
      <geometry>
        <mesh filename="package://rviz_basic/meshes/Limb1Roll3A_1.stl" scale="0.001 0.001 0.001"/>
      </geometry>
    </collision>
  </link>
  <link name="Limb1Roll3B_1">
    <inertial>
      <origin rpy="0 0 0" xyz="0.002629549326306546 0.0026290755748996086 -0.0033423943148920277"/>
      <mass value="0.28508696694265934"/>
      <inertia ixx="0.000107" ixy="2.2e-05" ixz="-2.8e-05" iyy="0.000107" iyz="-2.8e-05" izz="0.000121"/>
    </inertial>
    <visual>
      <origin rpy="0 0 0" xyz="-0.417713 -0.417825 -0.2719"/>
      <geometry>
        <mesh filename="package://rviz_basic/meshes/Limb1Roll3B_1.stl" scale="0.001 0.001 0.001"/>
      </geometry>
      <material name="silver"/>
    </visual>
    <collision>
      <origin rpy="0 0 0" xyz="-0.417713 -0.417825 -0.2719"/>
      <geometry>
        <mesh filename="package://rviz_basic/meshes/Limb1Roll3B_1.stl" scale="0.001 0.001 0.001"/>
      </geometry>
    </collision>
  </link>
  <link name="Limb0Connector1_1">
    <inertial>
      <origin rpy="0 0 0" xyz="0.002882044955110477 -0.0028824567425736886 -0.0036644034918792423"/>
      <mass value="0.41151751450909346"/>
      <inertia ixx="0.000202" ixy="-4.2e-05" ixz="-5.4e-05" iyy="0.000202" iyz="5.4e-05" izz="0.000228"/>
    </inertial>
    <visual>
      <origin rpy="0 0 0" xyz="-0.113749 0.118229 -0.658205"/>
      <geometry>
        <mesh filename="package://rviz_basic/meshes/Limb0Connector1_1.stl" scale="0.001 0.001 0.001"/>
      </geometry>
      <material name="silver"/>
    </visual>
    <collision>
      <origin rpy="0 0 0" xyz="-0.113749 0.118229 -0.658205"/>
      <geometry>
        <mesh filename="package://rviz_basic/meshes/Limb0Connector1_1.stl" scale="0.001 0.001 0.001"/>
      </geometry>
    </collision>
  </link>
  <link name="Body_connector__2__1">
    <inertial>
      <origin rpy="0 0 0" xyz="0.006689645187671248 -0.006690019077090437 -0.008597503863414846"/>
      <mass value="1.00227146305622"/>
      <inertia ixx="0.000536" ixy="-8.8e-05" ixz="-0.000112" iyy="0.000536" iyz="0.000112" izz="0.00059"/>
    </inertial>
    <visual>
      <origin rpy="0 0 0" xyz="-0.099583 0.104063 -0.676307"/>
      <geometry>
        <mesh filename="package://rviz_basic/meshes/Body_connector__2__1.stl" scale="0.001 0.001 0.001"/>
      </geometry>
      <material name="silver"/>
    </visual>
    <collision>
      <origin rpy="0 0 0" xyz="-0.099583 0.104063 -0.676307"/>
      <geometry>
        <mesh filename="package://rviz_basic/meshes/Body_connector__2__1.stl" scale="0.001 0.001 0.001"/>
      </geometry>
    </collision>
  </link>
  <link name="Limb0Roll1A_2">
    <inertial>
      <origin rpy="0 0 0" xyz="0.0068180092992543295 -0.006817421085496864 -0.008667591900487825"/>
      <mass value="0.8458457350592995"/>
      <inertia ixx="0.000391" ixy="-6.4e-05" ixz="-8.1e-05" iyy="0.000391" iyz="8.1e-05" izz="0.00043"/>
    </inertial>
    <visual>
      <origin rpy="0 0 0" xyz="-0.119533 0.124014 -0.650851"/>
      <geometry>
        <mesh filename="package://rviz_basic/meshes/Limb0Roll1A_2.stl" scale="0.001 0.001 0.001"/>
      </geometry>
      <material name="silver"/>
    </visual>
    <collision>
      <origin rpy="0 0 0" xyz="-0.119533 0.124014 -0.650851"/>
      <geometry>
        <mesh filename="package://rviz_basic/meshes/Limb0Roll1A_2.stl" scale="0.001 0.001 0.001"/>
      </geometry>
    </collision>
  </link>
  <link name="Limb1Roll1A_1">
    <inertial>
      <origin rpy="0 0 0" xyz="0.0068174560772614745 0.006817440350725942 -0.008667904925205638"/>
      <mass value="0.8458457350592995"/>
      <inertia ixx="0.000391" ixy="6.4e-05" ixz="-8.1e-05" iyy="0.000391" iyz="-8.1e-05" izz="0.00043"/>
    </inertial>
    <visual>
      <origin rpy="0 0 0" xyz="-0.119564 -0.11968 -0.650944"/>
      <geometry>
        <mesh filename="package://rviz_basic/meshes/Limb1Roll1A_1.stl" scale="0.001 0.001 0.001"/>
      </geometry>
      <material name="silver"/>
    </visual>
    <collision>
      <origin rpy="0 0 0" xyz="-0.119564 -0.11968 -0.650944"/>
      <geometry>
        <mesh filename="package://rviz_basic/meshes/Limb1Roll1A_1.stl" scale="0.001 0.001 0.001"/>
      </geometry>
    </collision>
  </link>
  <link name="Limb1Connector1_1">
    <inertial>
      <origin rpy="0 0 0" xyz="0.0028824917358001995 0.002882476003268339 -0.003664716518054001"/>
      <mass value="0.41151751450909346"/>
      <inertia ixx="0.000202" ixy="4.2e-05" ixz="-5.4e-05" iyy="0.000202" iyz="-5.4e-05" izz="0.000228"/>
    </inertial>
    <visual>
      <origin rpy="0 0 0" xyz="-0.113779 -0.113895 -0.658298"/>
      <geometry>
        <mesh filename="package://rviz_basic/meshes/Limb1Connector1_1.stl" scale="0.001 0.001 0.001"/>
      </geometry>
      <material name="silver"/>
    </visual>
    <collision>
      <origin rpy="0 0 0" xyz="-0.113779 -0.113895 -0.658298"/>
      <geometry>
        <mesh filename="package://rviz_basic/meshes/Limb1Connector1_1.stl" scale="0.001 0.001 0.001"/>
      </geometry>
    </collision>
  </link>
  <link name="Limb3BodyConnector_1">
    <inertial>
      <origin rpy="0 0 0" xyz="-0.0067195403654506936 -0.0067773886454455395 -0.008504836469146682"/>
      <mass value="1.00227146305622"/>
      <inertia ixx="0.000536" ixy="8.8e-05" ixz="0.000112" iyy="0.000536" iyz="0.000112" izz="0.00059"/>
    </inertial>
    <visual>
      <origin rpy="0 0 0" xyz="0.104123 0.104063 -0.676307"/>
      <geometry>
        <mesh filename="package://rviz_basic/meshes/Limb3BodyConnector_1.stl" scale="0.001 0.001 0.001"/>
      </geometry>
      <material name="silver"/>
    </visual>
    <collision>
      <origin rpy="0 0 0" xyz="0.104123 0.104063 -0.676307"/>
      <geometry>
        <mesh filename="package://rviz_basic/meshes/Limb3BodyConnector_1.stl" scale="0.001 0.001 0.001"/>
      </geometry>
    </collision>
  </link>
  <link name="Body_connector__3__1">
    <inertial>
      <origin rpy="0 0 0" xyz="0.006720085539711471 0.006777019875838897 -0.00850483646812894"/>
      <mass value="1.00227146305622"/>
      <inertia ixx="0.000536" ixy="8.8e-05" ixz="-0.000112" iyy="0.000536" iyz="-0.000112" izz="0.00059"/>
    </inertial>
    <visual>
      <origin rpy="0 0 0" xyz="-0.099583 -0.099642 -0.676307"/>
      <geometry>
        <mesh filename="package://rviz_basic/meshes/Body_connector__3__1.stl" scale="0.001 0.001 0.001"/>
      </geometry>
      <material name="silver"/>
    </visual>
    <collision>
      <origin rpy="0 0 0" xyz="-0.099583 -0.099642 -0.676307"/>
      <geometry>
        <mesh filename="package://rviz_basic/meshes/Body_connector__3__1.stl" scale="0.001 0.001 0.001"/>
      </geometry>
    </collision>
  </link>
  <link name="Limb3Roll1A_1">
    <inertial>
      <origin rpy="0 0 0" xyz="-0.006817910907280164 -0.006817809112227194 -0.00866790492923275"/>
      <mass value="0.8458457350592995"/>
      <inertia ixx="0.000391" ixy="6.4e-05" ixz="8.1e-05" iyy="0.000391" iyz="8.1e-05" izz="0.00043"/>
    </inertial>
    <visual>
      <origin rpy="0 0 0" xyz="0.124103 0.124101 -0.650944"/>
      <geometry>
        <mesh filename="package://rviz_basic/meshes/Limb3Roll1A_1.stl" scale="0.001 0.001 0.001"/>
      </geometry>
      <material name="silver"/>
    </visual>
    <collision>
      <origin rpy="0 0 0" xyz="0.124103 0.124101 -0.650944"/>
      <geometry>
        <mesh filename="package://rviz_basic/meshes/Limb3Roll1A_1.stl" scale="0.001 0.001 0.001"/>
      </geometry>
    </collision>
  </link>
  <link name="Limb3Roll1B_1">
    <inertial>
      <origin rpy="0 0 0" xyz="-0.0013141700819927493 -0.0013150682869401131 -0.0016716503098570534"/>
      <mass value="0.1621742617893587"/>
      <inertia ixx="6.8e-05" ixy="1.5e-05" ixz="1.9e-05" iyy="6.8e-05" iyz="1.9e-05" izz="7.7e-05"/>
    </inertial>
    <visual>
      <origin rpy="0 0 0" xyz="0.137776 0.137773 -0.633562"/>
      <geometry>
        <mesh filename="package://rviz_basic/meshes/Limb3Roll1B_1.stl" scale="0.001 0.001 0.001"/>
      </geometry>
      <material name="silver"/>
    </visual>
    <collision>
      <origin rpy="0 0 0" xyz="0.137776 0.137773 -0.633562"/>
      <geometry>
        <mesh filename="package://rviz_basic/meshes/Limb3Roll1B_1.stl" scale="0.001 0.001 0.001"/>
      </geometry>
    </collision>
  </link>
  <link name="Limb3Pitch1A_1">
    <inertial>
      <origin rpy="0 0 0" xyz="-0.026223396061620913 -0.026226377146498864 -0.03333892243583103"/>
      <mass value="3.3477117479193077"/>
      <inertia ixx="0.003389" ixy="-0.000316" ixz="-0.000498" iyy="0.003392" iyz="-0.000501" izz="0.003225"/>
    </inertial>
    <visual>
      <origin rpy="0 0 0" xyz="0.140405 0.140403 -0.630219"/>
      <geometry>
        <mesh filename="package://rviz_basic/meshes/Limb3Pitch1A_1.stl" scale="0.001 0.001 0.001"/>
      </geometry>
      <material name="silver"/>
    </visual>
    <collision>
      <origin rpy="0 0 0" xyz="0.140405 0.140403 -0.630219"/>
      <geometry>
        <mesh filename="package://rviz_basic/meshes/Limb3Pitch1A_1.stl" scale="0.001 0.001 0.001"/>
      </geometry>
    </collision>
  </link>
  <link name="Limb3Pitch1B_1">
    <inertial>
      <origin rpy="0 0 0" xyz="-0.0682288131087779 -0.06822917142967264 -0.08674078127522311"/>
      <mass value="0.7729993259283914"/>
      <inertia ixx="0.001974" ixy="-0.000551" ixz="-0.000712" iyy="0.001974" iyz="-0.000712" izz="0.001638"/>
    </inertial>
    <visual>
      <origin rpy="0 0 0" xyz="0.17457 0.174572 -0.586784"/>
      <geometry>
        <mesh filename="package://rviz_basic/meshes/Limb3Pitch1B_1.stl" scale="0.001 0.001 0.001"/>
      </geometry>
      <material name="silver"/>
    </visual>
    <collision>
      <origin rpy="0 0 0" xyz="0.17457 0.174572 -0.586784"/>
      <geometry>
        <mesh filename="package://rviz_basic/meshes/Limb3Pitch1B_1.stl" scale="0.001 0.001 0.001"/>
      </geometry>
    </collision>
  </link>
  <link name="Limb3Pitch2A_1">
    <inertial>
      <origin rpy="0 0 0" xyz="-0.02995918481286336 -0.02995953450399086 -0.038087949313386216"/>
      <mass value="0.18660217560053788"/>
      <inertia ixx="0.0001" ixy="-0.0" ixz="3e-06" iyy="0.0001" iyz="3e-06" izz="9.9e-05"/>
    </inertial>
    <visual>
      <origin rpy="0 0 0" xyz="0.271854 0.271856 -0.463105"/>
      <geometry>
        <mesh filename="package://rviz_basic/meshes/Limb3Pitch2A_1.stl" scale="0.001 0.001 0.001"/>
      </geometry>
      <material name="silver"/>
    </visual>
    <collision>
      <origin rpy="0 0 0" xyz="0.271854 0.271856 -0.463105"/>
      <geometry>
        <mesh filename="package://rviz_basic/meshes/Limb3Pitch2A_1.stl" scale="0.001 0.001 0.001"/>
      </geometry>
    </collision>
  </link>
  <link name="Limb3Connector2_1">
    <inertial>
      <origin rpy="0 0 0" xyz="-0.002103580869851629 -0.0021039372810309764 -0.0026740387525512888"/>
      <mass value="0.028818583393616055"/>
      <inertia ixx="1e-05" ixy="2e-06" ixz="3e-06" iyy="1e-05" iyz="3e-06" izz="1.1e-05"/>
    </inertial>
    <visual>
      <origin rpy="0 0 0" xyz="0.316552 0.316554 -0.406279"/>
      <geometry>
        <mesh filename="package://rviz_basic/meshes/Limb3Connector2_1.stl" scale="0.001 0.001 0.001"/>
      </geometry>
      <material name="silver"/>
    </visual>
    <collision>
      <origin rpy="0 0 0" xyz="0.316552 0.316554 -0.406279"/>
      <geometry>
        <mesh filename="package://rviz_basic/meshes/Limb3Connector2_1.stl" scale="0.001 0.001 0.001"/>
      </geometry>
    </collision>
  </link>
  <link name="Limb3Connector3_1">
    <inertial>
      <origin rpy="0 0 0" xyz="-0.002072397909838819 -0.0020727543210186106 -0.002634839906469677"/>
      <mass value="0.028067093486926365"/>
      <inertia ixx="1e-05" ixy="2e-06" ixz="3e-06" iyy="1e-05" iyz="3e-06" izz="1.1e-05"/>
    </inertial>
    <visual>
      <origin rpy="0 0 0" xyz="0.320759 0.320761 -0.400931"/>
      <geometry>
        <mesh filename="package://rviz_basic/meshes/Limb3Connector3_1.stl" scale="0.001 0.001 0.001"/>
      </geometry>
      <material name="silver"/>
    </visual>
    <collision>
      <origin rpy="0 0 0" xyz="0.320759 0.320761 -0.400931"/>
      <geometry>
        <mesh filename="package://rviz_basic/meshes/Limb3Connector3_1.stl" scale="0.001 0.001 0.001"/>
      </geometry>
    </collision>
  </link>
  <link name="Limb3Roll2A_1">
    <inertial>
      <origin rpy="0 0 0" xyz="-0.006681183575417249 -0.006681539986598262 -0.008494527567581345"/>
      <mass value="0.09449902324417689"/>
      <inertia ixx="3.8e-05" ixy="6e-06" ixz="8e-06" iyy="3.8e-05" iyz="8e-06" izz="4.2e-05"/>
    </inertial>
    <visual>
      <origin rpy="0 0 0" xyz="0.324966 0.324968 -0.395583"/>
      <geometry>
        <mesh filename="package://rviz_basic/meshes/Limb3Roll2A_1.stl" scale="0.001 0.001 0.001"/>
      </geometry>
      <material name="silver"/>
    </visual>
    <collision>
      <origin rpy="0 0 0" xyz="0.324966 0.324968 -0.395583"/>
      <geometry>
        <mesh filename="package://rviz_basic/meshes/Limb3Roll2A_1.stl" scale="0.001 0.001 0.001"/>
      </geometry>
    </collision>
  </link>
  <link name="Limb3Roll2B_1">
    <inertial>
      <origin rpy="0 0 0" xyz="-0.0013150659058785985 -0.0013144223170601932 -0.0016712502447977506"/>
      <mass value="0.14254348347132964"/>
      <inertia ixx="5.3e-05" ixy="1.1e-05" ixz="1.4e-05" iyy="5.3e-05" iyz="1.4e-05" izz="6e-05"/>
    </inertial>
    <visual>
      <origin rpy="0 0 0" xyz="0.338112 0.338115 -0.378869"/>
      <geometry>
        <mesh filename="package://rviz_basic/meshes/Limb3Roll2B_1.stl" scale="0.001 0.001 0.001"/>
      </geometry>
      <material name="silver"/>
    </visual>
    <collision>
      <origin rpy="0 0 0" xyz="0.338112 0.338115 -0.378869"/>
      <geometry>
        <mesh filename="package://rviz_basic/meshes/Limb3Roll2B_1.stl" scale="0.001 0.001 0.001"/>
      </geometry>
    </collision>
  </link>
  <link name="Limb3Roll2C_1">
    <inertial>
      <origin rpy="0 0 0" xyz="-0.06879514358919397 0.003539260654662646 -0.040511776258231436"/>
      <mass value="5.5447698039525"/>
      <inertia ixx="0.007579" ixy="0.001164" ixz="-0.00462" iyy="0.015187" iyz="5.5e-05" izz="0.013379"/>
    </inertial>
    <visual>
      <origin rpy="0 0 0" xyz="0.340742 0.340744 -0.375526"/>
      <geometry>
        <mesh filename="package://rviz_basic/meshes/Limb3Roll2C_1.stl" scale="0.001 0.001 0.001"/>
      </geometry>
      <material name="silver"/>
    </visual>
    <collision>
      <origin rpy="0 0 0" xyz="0.340742 0.340744 -0.375526"/>
      <geometry>
        <mesh filename="package://rviz_basic/meshes/Limb3Roll2C_1.stl" scale="0.001 0.001 0.001"/>
      </geometry>
    </collision>
  </link>
  <link name="Limb3Pitch3A_1">
    <inertial>
      <origin rpy="0 0 0" xyz="0.0008923046235595478 -0.000875608458570154 -1.2835033048275157e-05"/>
      <mass value="0.07127174173566476"/>
      <inertia ixx="3.1e-05" ixy="-1e-05" ixz="-0.0" iyy="3.1e-05" iyz="0.0" izz="2.1e-05"/>
    </inertial>
    <visual>
      <origin rpy="0 0 0" xyz="0.44047 0.362698 -0.299219"/>
      <geometry>
        <mesh filename="package://rviz_basic/meshes/Limb3Pitch3A_1.stl" scale="0.001 0.001 0.001"/>
      </geometry>
      <material name="silver"/>
    </visual>
    <collision>
      <origin rpy="0 0 0" xyz="0.44047 0.362698 -0.299219"/>
      <geometry>
        <mesh filename="package://rviz_basic/meshes/Limb3Pitch3A_1.stl" scale="0.001 0.001 0.001"/>
      </geometry>
    </collision>
  </link>
  <link name="Limb3Pitch3B_1">
    <inertial>
      <origin rpy="0 0 0" xyz="0.0008925369018588647 -0.0008755595909240022 -1.3013443638243416e-05"/>
      <mass value="0.07127174173566476"/>
      <inertia ixx="3.1e-05" ixy="-1e-05" ixz="-0.0" iyy="3.1e-05" iyz="0.0" izz="2.1e-05"/>
    </inertial>
    <visual>
      <origin rpy="0 0 0" xyz="0.438686 0.364449 -0.299193"/>
      <geometry>
        <mesh filename="package://rviz_basic/meshes/Limb3Pitch3B_1.stl" scale="0.001 0.001 0.001"/>
      </geometry>
      <material name="silver"/>
    </visual>
    <collision>
      <origin rpy="0 0 0" xyz="0.438686 0.364449 -0.299193"/>
      <geometry>
        <mesh filename="package://rviz_basic/meshes/Limb3Pitch3B_1.stl" scale="0.001 0.001 0.001"/>
      </geometry>
    </collision>
  </link>
  <link name="Limb3Roll3A_1">
    <inertial>
      <origin rpy="0 0 0" xyz="0.029621488782770322 -0.029529732857189905 -0.000733538068181272"/>
      <mass value="2.8490901932138626"/>
      <inertia ixx="0.002326" ixy="0.000133" ixz="-0.000154" iyy="0.00232" iyz="-0.000172" izz="0.002505"/>
    </inertial>
    <visual>
      <origin rpy="0 0 0" xyz="0.436901 0.3662 -0.299167"/>
      <geometry>
        <mesh filename="package://rviz_basic/meshes/Limb3Roll3A_1.stl" scale="0.001 0.001 0.001"/>
      </geometry>
      <material name="silver"/>
    </visual>
    <collision>
      <origin rpy="0 0 0" xyz="0.436901 0.3662 -0.299167"/>
      <geometry>
        <mesh filename="package://rviz_basic/meshes/Limb3Roll3A_1.stl" scale="0.001 0.001 0.001"/>
      </geometry>
    </collision>
  </link>
  <link name="Limb3Roll3B_1">
    <inertial>
      <origin rpy="0 0 0" xyz="-0.002629377762947971 -0.0026297341741378655 -0.0033425127128941523"/>
      <mass value="0.28508696694265934"/>
      <inertia ixx="0.000107" ixy="2.2e-05" ixz="2.8e-05" iyy="0.000107" iyz="2.8e-05" izz="0.000121"/>
    </inertial>
    <visual>
      <origin rpy="0 0 0" xyz="0.42225 0.422252 -0.271903"/>
      <geometry>
        <mesh filename="package://rviz_basic/meshes/Limb3Roll3B_1.stl" scale="0.001 0.001 0.001"/>
      </geometry>
      <material name="silver"/>
    </visual>
    <collision>
      <origin rpy="0 0 0" xyz="0.42225 0.422252 -0.271903"/>
      <geometry>
        <mesh filename="package://rviz_basic/meshes/Limb3Roll3B_1.stl" scale="0.001 0.001 0.001"/>
      </geometry>
    </collision>
  </link>
  <link name="Limb0Connector1__1__1">
    <inertial>
      <origin rpy="0 0 0" xyz="-0.0028827546155695133 0.0028825646539996502 -0.0036642489463752925"/>
      <mass value="0.41151751450909346"/>
      <inertia ixx="0.000202" ixy="-4.2e-05" ixz="5.4e-05" iyy="0.000202" iyz="-5.4e-05" izz="0.000228"/>
    </inertial>
    <visual>
      <origin rpy="0 0 0" xyz="0.118378 -0.113809 -0.658277"/>
      <geometry>
        <mesh filename="package://rviz_basic/meshes/Limb0Connector1__1__1.stl" scale="0.001 0.001 0.001"/>
      </geometry>
      <material name="silver"/>
    </visual>
    <collision>
      <origin rpy="0 0 0" xyz="0.118378 -0.113809 -0.658277"/>
      <geometry>
        <mesh filename="package://rviz_basic/meshes/Limb0Connector1__1__1.stl" scale="0.001 0.001 0.001"/>
      </geometry>
    </collision>
  </link>
  <link name="Limb0Roll1A__1__1">
    <inertial>
      <origin rpy="0 0 0" xyz="-0.006817718959102798 0.0068175289975327125 -0.008667437354983987"/>
      <mass value="0.8458457350592995"/>
      <inertia ixx="0.000391" ixy="-6.4e-05" ixz="8.1e-05" iyy="0.000391" iyz="-8.1e-05" izz="0.00043"/>
    </inertial>
    <visual>
      <origin rpy="0 0 0" xyz="0.124163 -0.119594 -0.650923"/>
      <geometry>
        <mesh filename="package://rviz_basic/meshes/Limb0Roll1A__1__1.stl" scale="0.001 0.001 0.001"/>
      </geometry>
      <material name="silver"/>
    </visual>
    <collision>
      <origin rpy="0 0 0" xyz="0.124163 -0.119594 -0.650923"/>
      <geometry>
        <mesh filename="package://rviz_basic/meshes/Limb0Roll1A__1__1.stl" scale="0.001 0.001 0.001"/>
      </geometry>
    </collision>
  </link>
  <link name="Limb0Roll1B__1__1">
    <inertial>
      <origin rpy="0 0 0" xyz="-0.0013149781338154254 0.0013147881722458676 -0.0016711827356082898"/>
      <mass value="0.1621742617893587"/>
      <inertia ixx="6.8e-05" ixy="-1.5e-05" ixz="1.9e-05" iyy="6.8e-05" iyz="-1.9e-05" izz="7.7e-05"/>
    </inertial>
    <visual>
      <origin rpy="0 0 0" xyz="0.137835 -0.133266 -0.633541"/>
      <geometry>
        <mesh filename="package://rviz_basic/meshes/Limb0Roll1B__1__1.stl" scale="0.001 0.001 0.001"/>
      </geometry>
      <material name="silver"/>
    </visual>
    <collision>
      <origin rpy="0 0 0" xyz="0.137835 -0.133266 -0.633541"/>
      <geometry>
        <mesh filename="package://rviz_basic/meshes/Limb0Roll1B__1__1.stl" scale="0.001 0.001 0.001"/>
      </geometry>
    </collision>
  </link>
  <link name="Limb0Pitch1A__1__1">
    <inertial>
      <origin rpy="0 0 0" xyz="-0.026222083031917087 0.026225975950275843 -0.033340218510740094"/>
      <mass value="3.3477117479193077"/>
      <inertia ixx="0.003392" ixy="0.000316" ixz="-0.000501" iyy="0.003389" iyz="0.000499" izz="0.003225"/>
    </inertial>
    <visual>
      <origin rpy="0 0 0" xyz="0.140465 -0.135895 -0.630198"/>
      <geometry>
        <mesh filename="package://rviz_basic/meshes/Limb0Pitch1A__1__1.stl" scale="0.001 0.001 0.001"/>
      </geometry>
      <material name="silver"/>
    </visual>
    <collision>
      <origin rpy="0 0 0" xyz="0.140465 -0.135895 -0.630198"/>
      <geometry>
        <mesh filename="package://rviz_basic/meshes/Limb0Pitch1A__1__1.stl" scale="0.001 0.001 0.001"/>
      </geometry>
    </collision>
  </link>
  <link name="Limb0Pitch1B__1__1">
    <inertial>
      <origin rpy="0 0 0" xyz="-0.06822878474178282 0.06822905489615136 -0.08674120269560415"/>
      <mass value="0.7729993259283914"/>
      <inertia ixx="0.001974" ixy="0.000551" ixz="-0.000712" iyy="0.001974" iyz="0.000712" izz="0.001638"/>
    </inertial>
    <visual>
      <origin rpy="0 0 0" xyz="0.174628 -0.170063 -0.586761"/>
      <geometry>
        <mesh filename="package://rviz_basic/meshes/Limb0Pitch1B__1__1.stl" scale="0.001 0.001 0.001"/>
      </geometry>
      <material name="silver"/>
    </visual>
    <collision>
      <origin rpy="0 0 0" xyz="0.174628 -0.170063 -0.586761"/>
      <geometry>
        <mesh filename="package://rviz_basic/meshes/Limb0Pitch1B__1__1.stl" scale="0.001 0.001 0.001"/>
      </geometry>
    </collision>
  </link>
  <link name="Limb0Pitch2A__1__1">
    <inertial>
      <origin rpy="0 0 0" xyz="-0.029959154394446574 0.029959429359142975 -0.03808736338923474"/>
      <mass value="0.18660217560053788"/>
      <inertia ixx="0.0001" ixy="0.0" ixz="3e-06" iyy="0.0001" iyz="-3e-06" izz="9.9e-05"/>
    </inertial>
    <visual>
      <origin rpy="0 0 0" xyz="0.271912 -0.267347 -0.463081"/>
      <geometry>
        <mesh filename="package://rviz_basic/meshes/Limb0Pitch2A__1__1.stl" scale="0.001 0.001 0.001"/>
      </geometry>
      <material name="silver"/>
    </visual>
    <collision>
      <origin rpy="0 0 0" xyz="0.271912 -0.267347 -0.463081"/>
      <geometry>
        <mesh filename="package://rviz_basic/meshes/Limb0Pitch2A__1__1.stl" scale="0.001 0.001 0.001"/>
      </geometry>
    </collision>
  </link>
  <link name="Limb0Connector2__1__1">
    <inertial>
      <origin rpy="0 0 0" xyz="-0.002103557171485082 0.00210382541613241 -0.0026744528284016744"/>
      <mass value="0.028818583393616055"/>
      <inertia ixx="1e-05" ixy="-2e-06" ixz="3e-06" iyy="1e-05" iyz="-3e-06" izz="1.1e-05"/>
    </inertial>
    <visual>
      <origin rpy="0 0 0" xyz="0.31661 -0.312045 -0.406256"/>
      <geometry>
        <mesh filename="package://rviz_basic/meshes/Limb0Connector2__1__1.stl" scale="0.001 0.001 0.001"/>
      </geometry>
      <material name="silver"/>
    </visual>
    <collision>
      <origin rpy="0 0 0" xyz="0.31661 -0.312045 -0.406256"/>
      <geometry>
        <mesh filename="package://rviz_basic/meshes/Limb0Connector2__1__1.stl" scale="0.001 0.001 0.001"/>
      </geometry>
    </collision>
  </link>
  <link name="Limb0Connector3__1__1">
    <inertial>
      <origin rpy="0 0 0" xyz="-0.002072374211472272 0.0020726424561186008 -0.0026342539823204225"/>
      <mass value="0.028067093486926365"/>
      <inertia ixx="1e-05" ixy="-2e-06" ixz="3e-06" iyy="1e-05" iyz="-3e-06" izz="1.1e-05"/>
    </inertial>
    <visual>
      <origin rpy="0 0 0" xyz="0.320817 -0.316252 -0.400907"/>
      <geometry>
        <mesh filename="package://rviz_basic/meshes/Limb0Connector3__1__1.stl" scale="0.001 0.001 0.001"/>
      </geometry>
      <material name="silver"/>
    </visual>
    <collision>
      <origin rpy="0 0 0" xyz="0.320817 -0.316252 -0.400907"/>
      <geometry>
        <mesh filename="package://rviz_basic/meshes/Limb0Connector3__1__1.stl" scale="0.001 0.001 0.001"/>
      </geometry>
    </collision>
  </link>
  <link name="Limb0Roll2A__1__1">
    <inertial>
      <origin rpy="0 0 0" xyz="-0.006681159877050313 0.006681428121697641 -0.008493941643432423"/>
      <mass value="0.09449902324417689"/>
      <inertia ixx="3.8e-05" ixy="-6e-06" ixz="8e-06" iyy="3.8e-05" iyz="-8e-06" izz="4.2e-05"/>
    </inertial>
    <visual>
      <origin rpy="0 0 0" xyz="0.325024 -0.320459 -0.395559"/>
      <geometry>
        <mesh filename="package://rviz_basic/meshes/Limb0Roll2A__1__1.stl" scale="0.001 0.001 0.001"/>
      </geometry>
      <material name="silver"/>
    </visual>
    <collision>
      <origin rpy="0 0 0" xyz="0.325024 -0.320459 -0.395559"/>
      <geometry>
        <mesh filename="package://rviz_basic/meshes/Limb0Roll2A__1__1.stl" scale="0.001 0.001 0.001"/>
      </geometry>
    </collision>
  </link>
  <link name="Limb0Roll2B__1__1">
    <inertial>
      <origin rpy="0 0 0" xyz="-0.001315042207511441 0.0013143104521591842 -0.001671664320648858"/>
      <mass value="0.14254348347132964"/>
      <inertia ixx="5.3e-05" ixy="-1.1e-05" ixz="1.4e-05" iyy="5.3e-05" iyz="-1.4e-05" izz="6e-05"/>
    </inertial>
    <visual>
      <origin rpy="0 0 0" xyz="0.33817 -0.333606 -0.378846"/>
      <geometry>
        <mesh filename="package://rviz_basic/meshes/Limb0Roll2B__1__1.stl" scale="0.001 0.001 0.001"/>
      </geometry>
      <material name="silver"/>
    </visual>
    <collision>
      <origin rpy="0 0 0" xyz="0.33817 -0.333606 -0.378846"/>
      <geometry>
        <mesh filename="package://rviz_basic/meshes/Limb0Roll2B__1__1.stl" scale="0.001 0.001 0.001"/>
      </geometry>
    </collision>
  </link>
  <link name="Limb0Roll2C__1__1">
    <inertial>
      <origin rpy="0 0 0" xyz="0.0035396407642167005 0.06879538813547331 -0.04051219033408121"/>
      <mass value="5.5447698039525"/>
      <inertia ixx="0.015187" ixy="-0.001164" ixz="5.5e-05" iyy="0.007579" iyz="0.00462" izz="0.013379"/>
    </inertial>
    <visual>
      <origin rpy="0 0 0" xyz="0.3408 -0.336235 -0.375503"/>
      <geometry>
        <mesh filename="package://rviz_basic/meshes/Limb0Roll2C__1__1.stl" scale="0.001 0.001 0.001"/>
      </geometry>
      <material name="silver"/>
    </visual>
    <collision>
      <origin rpy="0 0 0" xyz="0.3408 -0.336235 -0.375503"/>
      <geometry>
        <mesh filename="package://rviz_basic/meshes/Limb0Roll2C__1__1.stl" scale="0.001 0.001 0.001"/>
      </geometry>
    </collision>
  </link>
  <link name="Limb0Pitch3A__1__1">
    <inertial>
      <origin rpy="0 0 0" xyz="-0.0008752283490133239 -0.0008920600772804876 -1.324910890049269e-05"/>
      <mass value="0.07127174173566476"/>
      <inertia ixx="3.1e-05" ixy="1e-05" ixz="0.0" iyy="3.1e-05" iyz="0.0" izz="2.1e-05"/>
    </inertial>
    <visual>
      <origin rpy="0 0 0" xyz="0.362754 -0.435963 -0.299196"/>
      <geometry>
        <mesh filename="package://rviz_basic/meshes/Limb0Pitch3A__1__1.stl" scale="0.001 0.001 0.001"/>
      </geometry>
      <material name="silver"/>
    </visual>
    <collision>
      <origin rpy="0 0 0" xyz="0.362754 -0.435963 -0.299196"/>
      <geometry>
        <mesh filename="package://rviz_basic/meshes/Limb0Pitch3A__1__1.stl" scale="0.001 0.001 0.001"/>
      </geometry>
    </collision>
  </link>
  <link name="Limb0Pitch3B__1__1">
    <inertial>
      <origin rpy="0 0 0" xyz="0.0008757716509866786 0.0008919399227195757 1.2750891099200246e-05"/>
      <mass value="0.07127174173566476"/>
      <inertia ixx="3.1e-05" ixy="1e-05" ixz="0.0" iyy="3.1e-05" iyz="0.0" izz="2.1e-05"/>
    </inertial>
    <visual>
      <origin rpy="0 0 0" xyz="0.364505 -0.434179 -0.29917"/>
      <geometry>
        <mesh filename="package://rviz_basic/meshes/Limb0Pitch3B__1__1.stl" scale="0.001 0.001 0.001"/>
      </geometry>
      <material name="silver"/>
    </visual>
    <collision>
      <origin rpy="0 0 0" xyz="0.364505 -0.434179 -0.29917"/>
      <geometry>
        <mesh filename="package://rviz_basic/meshes/Limb0Pitch3B__1__1.stl" scale="0.001 0.001 0.001"/>
      </geometry>
    </collision>
  </link>
  <link name="Limb0Roll3A__1__1">
    <inertial>
      <origin rpy="0 0 0" xyz="-0.029529401615279394 -0.02962201195819142 -0.0007337737334465744"/>
      <mass value="2.8490901932138626"/>
      <inertia ixx="0.00232" ixy="-0.000133" ixz="-0.000172" iyy="0.002326" iyz="0.000154" izz="0.002505"/>
    </inertial>
    <visual>
      <origin rpy="0 0 0" xyz="0.364505 -0.434179 -0.29917"/>
      <geometry>
        <mesh filename="package://rviz_basic/meshes/Limb0Roll3A__1__1.stl" scale="0.001 0.001 0.001"/>
      </geometry>
      <material name="silver"/>
    </visual>
    <collision>
      <origin rpy="0 0 0" xyz="0.364505 -0.434179 -0.29917"/>
      <geometry>
        <mesh filename="package://rviz_basic/meshes/Limb0Roll3A__1__1.stl" scale="0.001 0.001 0.001"/>
      </geometry>
    </collision>
  </link>
  <link name="Limb0Roll3B__1__1">
    <inertial>
      <origin rpy="0 0 0" xyz="-0.002629402932225411 0.0026288545875268188 -0.0033427483781611755"/>
      <mass value="0.28508696694265934"/>
      <inertia ixx="0.000107" ixy="-2.2e-05" ixz="2.8e-05" iyy="0.000107" iyz="-2.8e-05" izz="0.000121"/>
    </inertial>
    <visual>
      <origin rpy="0 0 0" xyz="0.420557 -0.419528 -0.271906"/>
      <geometry>
        <mesh filename="package://rviz_basic/meshes/Limb0Roll3B__1__1.stl" scale="0.001 0.001 0.001"/>
      </geometry>
      <material name="silver"/>
    </visual>
    <collision>
      <origin rpy="0 0 0" xyz="0.420557 -0.419528 -0.271906"/>
      <geometry>
        <mesh filename="package://rviz_basic/meshes/Limb0Roll3B__1__1.stl" scale="0.001 0.001 0.001"/>
      </geometry>
    </collision>
  </link>
  <link name="Limb3Wheel_1">
    <inertial>
      <origin rpy="0 0 0" xyz="-0.03313137155284268 -0.03313172796403646 -0.042121191623910065"/>
      <mass value="20.629366559155358"/>
      <inertia ixx="0.146499" ixy="0.022339" ixz="0.028399" iyy="0.146499" iyz="0.028399" izz="0.160265"/>
    </inertial>
    <visual>
      <origin rpy="0 0 0" xyz="0.427509 0.427511 -0.265218"/>
      <geometry>
        <mesh filename="package://rviz_basic/meshes/Limb3Wheel_1.stl" scale="0.001 0.001 0.001"/>
      </geometry>
      <material name="silver"/>
    </visual>
    <collision>
      <origin rpy="0 0 0" xyz="0.427509 0.427511 -0.265218"/>
      <geometry>
        <mesh filename="package://rviz_basic/meshes/Limb3Wheel_1.stl" scale="0.001 0.001 0.001"/>
      </geometry>
    </collision>
  </link>
  <link name="Limb2Wheel_1">
    <inertial>
      <origin rpy="0 0 0" xyz="-0.033131396722130446 0.03313184837742028 -0.042121427289172536"/>
      <mass value="20.629366559155358"/>
      <inertia ixx="0.146499" ixy="-0.022339" ixz="0.028399" iyy="0.146499" iyz="-0.028399" izz="0.160265"/>
    </inertial>
    <visual>
      <origin rpy="0 0 0" xyz="0.425816 -0.424786 -0.265221"/>
      <geometry>
        <mesh filename="package://rviz_basic/meshes/Limb2Wheel_1.stl" scale="0.001 0.001 0.001"/>
      </geometry>
      <material name="silver"/>
    </visual>
    <collision>
      <origin rpy="0 0 0" xyz="0.425816 -0.424786 -0.265221"/>
      <geometry>
        <mesh filename="package://rviz_basic/meshes/Limb2Wheel_1.stl" scale="0.001 0.001 0.001"/>
      </geometry>
    </collision>
  </link>
  <link name="Limb0Wheel_1">
    <inertial>
      <origin rpy="0 0 0" xyz="0.03313181235243107 -0.03313129052002134 -0.042121007885148914"/>
      <mass value="20.629366559155358"/>
      <inertia ixx="0.146499" ixy="-0.022339" ixz="-0.028399" iyy="0.146499" iyz="0.028399" izz="0.160265"/>
    </inertial>
    <visual>
      <origin rpy="0 0 0" xyz="-0.422937 0.427423 -0.265123"/>
      <geometry>
        <mesh filename="package://rviz_basic/meshes/Limb0Wheel_1.stl" scale="0.001 0.001 0.001"/>
      </geometry>
      <material name="silver"/>
    </visual>
    <collision>
      <origin rpy="0 0 0" xyz="-0.422937 0.427423 -0.265123"/>
      <geometry>
        <mesh filename="package://rviz_basic/meshes/Limb0Wheel_1.stl" scale="0.001 0.001 0.001"/>
      </geometry>
    </collision>
  </link>
  <link name="Limb1Wheel_1">
    <inertial>
      <origin rpy="0 0 0" xyz="0.033131543108578854 0.033132069379244455 -0.0421210732205399"/>
      <mass value="20.629366559155358"/>
      <inertia ixx="0.146499" ixy="0.022339" ixz="-0.028399" iyy="0.146499" iyz="-0.028399" izz="0.160265"/>
    </inertial>
    <visual>
      <origin rpy="0 0 0" xyz="-0.422972 -0.423083 -0.265215"/>
      <geometry>
        <mesh filename="package://rviz_basic/meshes/Limb1Wheel_1.stl" scale="0.001 0.001 0.001"/>
      </geometry>
      <material name="silver"/>
    </visual>
    <collision>
      <origin rpy="0 0 0" xyz="-0.422972 -0.423083 -0.265215"/>
      <geometry>
        <mesh filename="package://rviz_basic/meshes/Limb1Wheel_1.stl" scale="0.001 0.001 0.001"/>
      </geometry>
    </collision>
  </link>
  <link name="Connector4_1">
    <inertial>
      <origin rpy="0 0 0" xyz="-0.002901887715433857 -0.00290178592038004 -0.003690068112437328"/>
      <mass value="0.41151751450909346"/>
      <inertia ixx="0.000202" ixy="4.2e-05" ixz="5.4e-05" iyy="0.000202" iyz="5.4e-05" izz="0.000228"/>
    </inertial>
    <visual>
      <origin rpy="0 0 0" xyz="0.118319 0.118317 -0.658298"/>
      <geometry>
        <mesh filename="package://rviz_basic/meshes/Connector4_1.stl" scale="0.001 0.001 0.001"/>
      </geometry>
      <material name="silver"/>
    </visual>
    <collision>
      <origin rpy="0 0 0" xyz="0.118319 0.118317 -0.658298"/>
      <geometry>
        <mesh filename="package://rviz_basic/meshes/Connector4_1.stl" scale="0.001 0.001 0.001"/>
      </geometry>
    </collision>
  </link>
  <joint name="Rigid 12" type="fixed">
    <origin rpy="0 0 0" xyz="-0.104123 0.099642 0.676307"/>
    <parent link="base_link"/>
    <child link="Body_connector_5"/>
  </joint>
  <joint name="Rigid 14" type="fixed">
    <origin rpy="0 0 0" xyz="0.044699 -0.044698 -0.056826"/>
    <parent link="Limb0Pitch2A_2"/>
    <child link="Limb0Connector2_2"/>
  </joint>
  <joint name="Limb0Pitch2" type="continuous">
    <origin rpy="0 0 0" xyz="0.097284 -0.097284 -0.123679"/>
    <parent link="Limb0Pitch1B_2"/>
    <child link="Limb0Pitch2A_2"/>
    <axis xyz="0.527675 0.818143 -0.228478"/>
  </joint>
  <joint name="Limb0Pitch1" type="continuous">
    <origin rpy="0 0 0" xyz="0.034163 -0.034169 -0.043437"/>
    <parent link="Limb0Pitch1A_2"/>
    <child link="Limb0Pitch1B_2"/>
    <axis xyz="0.527675 0.818143 -0.228478"/>
  </joint>
  <joint name="Rigid 17" type="fixed">
    <origin rpy="0 0 0" xyz="0.002629 -0.002629 -0.003343"/>
    <parent link="Limb0Roll1B_2"/>
    <child link="Limb0Pitch1A_2"/>
  </joint>
  <joint name="Limb0Roll1" type="continuous">
    <origin rpy="0 0 0" xyz="0.013673 -0.013672 -0.017382"/>
    <parent link="Limb0Roll1A_2"/>
    <child link="Limb0Roll1B_2"/>
    <axis xyz="0.52586 -0.52586 -0.668537"/>
  </joint>
  <joint name="Rigid 43" type="fixed">
    <origin rpy="0 0 0" xyz="0.004206 -0.004207 -0.005348"/>
    <parent link="Limb0Connector2_2"/>
    <child link="Limb0Connector3_3"/>
  </joint>
  <joint name="Rigid 44" type="fixed">
    <origin rpy="0 0 0" xyz="0.004207 -0.004207 -0.005348"/>
    <parent link="Limb0Connector3_3"/>
    <child link="Limb0Roll2A_3"/>
  </joint>
  <joint name="Limb0Roll2" type="continuous">
    <origin rpy="0 0 0" xyz="0.013147 -0.013146 -0.016714"/>
    <parent link="Limb0Roll2A_3"/>
    <child link="Limb0Roll2B_2"/>
    <axis xyz="-0.52586 0.52586 0.668537"/>
  </joint>
  <joint name="Rigid 46" type="fixed">
    <origin rpy="0 0 0" xyz="0.002629 -0.00263 -0.003342"/>
    <parent link="Limb0Roll2B_2"/>
    <child link="Limb0Roll2C_2"/>
  </joint>
  <joint name="Rigid 47" type="fixed">
    <origin rpy="0 0 0" xyz="0.02541 -0.102493 -0.071414"/>
    <parent link="Limb0Roll2C_2"/>
    <child link="Limb0Pitch3A_2"/>
  </joint>
  <joint name="Limb0Pitch3" type="continuous">
    <origin rpy="0 0 0" xyz="0.001594 0.00191 -0.000248"/>
    <parent link="Limb0Pitch3A_2"/>
    <child link="Limb0Pitch3B_2"/>
    <axis xyz="0.637539 0.763972 -0.09945"/>
  </joint>
  <joint name="Rigid 49" type="fixed">
    <origin rpy="0 0 0" xyz="0.001594 0.00191 -0.000249"/>
    <parent link="Limb0Pitch3B_2"/>
    <child link="Limb0Roll3A_2"/>
  </joint>
  <joint name="Limb0Roll3" type="continuous">
    <origin rpy="0 0 0" xyz="0.052911 0.017165 -0.031713"/>
    <parent link="Limb0Roll3A_2"/>
    <child link="Limb0Roll3B_2"/>
    <axis xyz="0.52586 -0.52586 -0.668537"/>
  </joint>
  <joint name="Revolute 53" type="continuous">
    <origin rpy="0 0 0" xyz="0.013672 0.013672 -0.017382"/>
    <parent link="Limb1Roll1A_1"/>
    <child link="Limb1Roll1B_1"/>
    <axis xyz="0.52586 0.52586 -0.668537"/>
  </joint>
  <joint name="Rigid 54" type="fixed">
    <origin rpy="0 0 0" xyz="0.002629 0.002629 -0.003343"/>
    <parent link="Limb1Roll1B_1"/>
    <child link="Limb1Pitch1A_1"/>
  </joint>
  <joint name="Limb1Pitch1" type="continuous">
    <origin rpy="0 0 0" xyz="0.034168 0.034164 -0.043438"/>
    <parent link="Limb1Pitch1A_1"/>
    <child link="Limb1Pitch1B_1"/>
    <axis xyz="-0.713693 0.70038 -0.010471"/>
  </joint>
  <joint name="Limb1Pitch2" type="continuous">
    <origin rpy="0 0 0" xyz="0.097284 0.097284 -0.123679"/>
    <parent link="Limb1Pitch1B_1"/>
    <child link="Limb1Pitch2A_1"/>
    <axis xyz="0.713693 -0.70038 0.010471"/>
  </joint>
  <joint name="Rigid 57" type="fixed">
    <origin rpy="0 0 0" xyz="0.044698 0.044698 -0.056826"/>
    <parent link="Limb1Pitch2A_1"/>
    <child link="Limb1Connector2_1"/>
  </joint>
  <joint name="Rigid 58" type="fixed">
    <origin rpy="0 0 0" xyz="0.004207 0.004207 -0.005348"/>
    <parent link="Limb1Connector2_1"/>
    <child link="Limb1Connector3_1"/>
  </joint>
  <joint name="Rigid 59" type="fixed">
    <origin rpy="0 0 0" xyz="0.004207 0.004207 -0.005348"/>
    <parent link="Limb1Connector3_1"/>
    <child link="Limb1Roll2A_1"/>
  </joint>
  <joint name="Limb1Roll2" type="continuous">
    <origin rpy="0 0 0" xyz="0.013147 0.013146 -0.016714"/>
    <parent link="Limb1Roll2A_1"/>
    <child link="Limb1Roll2B_1"/>
    <axis xyz="0.52586 0.52586 -0.668537"/>
  </joint>
  <joint name="Rigid 61" type="fixed">
    <origin rpy="0 0 0" xyz="0.002629 0.002629 -0.003342"/>
    <parent link="Limb1Roll2B_1"/>
    <child link="LimbRoll2C__1__1"/>
  </joint>
  <joint name="Rigid 62" type="fixed">
    <origin rpy="0 0 0" xyz="0.099728 0.021954 -0.076308"/>
    <parent link="LimbRoll2C__1__1"/>
    <child link="Limb1Pitch3A_1"/>
  </joint>
  <joint name="Revolute 63" type="continuous">
    <origin rpy="0 0 0" xyz="-0.001784 0.001751 -2.6e-05"/>
    <parent link="Limb1Pitch3A_1"/>
    <child link="Limb1Pitch3B_1"/>
    <axis xyz="-0.713693 0.70038 -0.010471"/>
  </joint>
  <joint name="Rigid 64" type="fixed">
    <origin rpy="0 0 0" xyz="-0.001784 0.001751 -2.6e-05"/>
    <parent link="Limb1Pitch3B_1"/>
    <child link="Limb1Roll3A_1"/>
  </joint>
  <joint name="Revolute 65" type="continuous">
    <origin rpy="0 0 0" xyz="-0.014652 0.056053 -0.027264"/>
    <parent link="Limb1Roll3A_1"/>
    <child link="Limb1Roll3B_1"/>
    <axis xyz="0.52586 0.52586 -0.668537"/>
  </joint>
  <joint name="Rigid 66" type="fixed">
    <origin rpy="0 0 0" xyz="0.014166 -0.014166 -0.018102"/>
    <parent link="Body_connector__2__1"/>
    <child link="Limb0Connector1_1"/>
  </joint>
  <joint name="Rigid 67" type="fixed">
    <origin rpy="0 0 0" xyz="0.099583 -0.104063 0.676307"/>
    <parent link="base_link"/>
    <child link="Body_connector__2__1"/>
  </joint>
  <joint name="Rigid 68" type="fixed">
    <origin rpy="0 0 0" xyz="0.005784 -0.005785 -0.007354"/>
    <parent link="Limb0Connector1_1"/>
    <child link="Limb0Roll1A_2"/>
  </joint>
  <joint name="Rigid 69" type="fixed">
    <origin rpy="0 0 0" xyz="0.005785 0.005785 -0.007354"/>
    <parent link="Limb1Connector1_1"/>
    <child link="Limb1Roll1A_1"/>
  </joint>
  <joint name="Rigid 70" type="fixed">
    <origin rpy="0 0 0" xyz="0.014196 0.014253 -0.018009"/>
    <parent link="Body_connector__3__1"/>
    <child link="Limb1Connector1_1"/>
  </joint>
  <joint name="Rigid 71" type="fixed">
    <origin rpy="0 0 0" xyz="-0.104123 -0.104063 0.676307"/>
    <parent link="base_link"/>
    <child link="Limb3BodyConnector_1"/>
  </joint>
  <joint name="Rigid 72" type="fixed">
    <origin rpy="0 0 0" xyz="0.099583 0.099642 0.676307"/>
    <parent link="base_link"/>
    <child link="Body_connector__3__1"/>
  </joint>
  <joint name="Rigid 74" type="fixed">
    <origin rpy="0 0 0" xyz="-0.005784 -0.005784 -0.007354"/>
    <parent link="Connector4_1"/>
    <child link="Limb3Roll1A_1"/>
  </joint>
  <joint name="Limb3Roll1" type="continuous">
    <origin rpy="0 0 0" xyz="-0.013673 -0.013672 -0.017382"/>
    <parent link="Limb3Roll1A_1"/>
    <child link="Limb3Roll1B_1"/>
    <axis xyz="-0.52586 -0.52586 -0.668537"/>
  </joint>
  <joint name="Rigid 76" type="fixed">
    <origin rpy="0 0 0" xyz="-0.002629 -0.00263 -0.003343"/>
    <parent link="Limb3Roll1B_1"/>
    <child link="Limb3Pitch1A_1"/>
  </joint>
  <joint name="Limb3Pitch1" type="continuous">
    <origin rpy="0 0 0" xyz="-0.034165 -0.034169 -0.043435"/>
    <parent link="Limb3Pitch1A_1"/>
    <child link="Limb3Pitch1B_1"/>
    <axis xyz="-0.713693 0.70038 0.010471"/>
  </joint>
  <joint name="Limb3Pitch2" type="continuous">
    <origin rpy="0 0 0" xyz="-0.097284 -0.097284 -0.123679"/>
    <parent link="Limb3Pitch1B_1"/>
    <child link="Limb3Pitch2A_1"/>
    <axis xyz="-0.713693 0.70038 0.010471"/>
  </joint>
  <joint name="Rigid 79" type="fixed">
    <origin rpy="0 0 0" xyz="-0.044698 -0.044698 -0.056826"/>
    <parent link="Limb3Pitch2A_1"/>
    <child link="Limb3Connector2_1"/>
  </joint>
  <joint name="Rigid 80" type="fixed">
    <origin rpy="0 0 0" xyz="-0.004207 -0.004207 -0.005348"/>
    <parent link="Limb3Connector2_1"/>
    <child link="Limb3Connector3_1"/>
  </joint>
  <joint name="Rigid 81" type="fixed">
    <origin rpy="0 0 0" xyz="-0.004207 -0.004207 -0.005348"/>
    <parent link="Limb3Connector3_1"/>
    <child link="Limb3Roll2A_1"/>
  </joint>
  <joint name="Limb3Roll2" type="continuous">
    <origin rpy="0 0 0" xyz="-0.013146 -0.013147 -0.016714"/>
    <parent link="Limb3Roll2A_1"/>
    <child link="Limb3Roll2B_1"/>
    <axis xyz="-0.52586 -0.52586 -0.668537"/>
  </joint>
  <joint name="Rigid 83" type="fixed">
    <origin rpy="0 0 0" xyz="-0.00263 -0.002629 -0.003343"/>
    <parent link="Limb3Roll2B_1"/>
    <child link="Limb3Roll2C_1"/>
  </joint>
  <joint name="Rigid 84" type="fixed">
    <origin rpy="0 0 0" xyz="-0.099728 -0.021954 -0.076307"/>
    <parent link="Limb3Roll2C_1"/>
    <child link="Limb3Pitch3A_1"/>
  </joint>
  <joint name="Limb3Pitch3" type="continuous">
    <origin rpy="0 0 0" xyz="0.001784 -0.001751 -2.6e-05"/>
    <parent link="Limb3Pitch3A_1"/>
    <child link="Limb3Pitch3B_1"/>
    <axis xyz="0.713693 -0.70038 -0.010471"/>
  </joint>
  <joint name="Rigid 86" type="fixed">
    <origin rpy="0 0 0" xyz="0.001785 -0.001751 -2.6e-05"/>
    <parent link="Limb3Pitch3B_1"/>
    <child link="Limb3Roll3A_1"/>
  </joint>
  <joint name="Limb3Roll3" type="continuous">
    <origin rpy="0 0 0" xyz="0.014651 -0.056052 -0.027264"/>
    <parent link="Limb3Roll3A_1"/>
    <child link="Limb3Roll3B_1"/>
    <axis xyz="-0.52586 -0.52586 -0.668537"/>
  </joint>
  <joint name="Rigid 88" type="fixed">
    <origin rpy="0 0 0" xyz="-0.014255 0.014167 -0.01803"/>
    <parent link="Body_connector_5"/>
    <child link="Limb0Connector1__1__1"/>
  </joint>
  <joint name="Rigid 89" type="fixed">
    <origin rpy="0 0 0" xyz="-0.005785 0.005785 -0.007354"/>
    <parent link="Limb0Connector1__1__1"/>
    <child link="Limb0Roll1A__1__1"/>
  </joint>
  <joint name="Limb2Roll1" type="continuous">
    <origin rpy="0 0 0" xyz="-0.013672 0.013672 -0.017382"/>
    <parent link="Limb0Roll1A__1__1"/>
    <child link="Limb0Roll1B__1__1"/>
    <axis xyz="-0.52586 0.52586 -0.668537"/>
  </joint>
  <joint name="Rigid 91" type="fixed">
    <origin rpy="0 0 0" xyz="-0.00263 0.002629 -0.003343"/>
    <parent link="Limb0Roll1B__1__1"/>
    <child link="Limb0Pitch1A__1__1"/>
  </joint>
  <joint name="Limb2Pitch1" type="continuous">
    <origin rpy="0 0 0" xyz="-0.034163 0.034168 -0.043437"/>
    <parent link="Limb0Pitch1A__1__1"/>
    <child link="Limb0Pitch1B__1__1"/>
    <axis xyz="-0.70038 -0.713693 -0.010471"/>
  </joint>
  <joint name="Limb2Pitch2" type="continuous">
    <origin rpy="0 0 0" xyz="-0.097284 0.097284 -0.12368"/>
    <parent link="Limb0Pitch1B__1__1"/>
    <child link="Limb0Pitch2A__1__1"/>
    <axis xyz="-0.70038 -0.713693 -0.010471"/>
  </joint>
  <joint name="Rigid 94" type="fixed">
    <origin rpy="0 0 0" xyz="-0.044698 0.044698 -0.056825"/>
    <parent link="Limb0Pitch2A__1__1"/>
    <child link="Limb0Connector2__1__1"/>
  </joint>
  <joint name="Rigid 95" type="fixed">
    <origin rpy="0 0 0" xyz="-0.004207 0.004207 -0.005349"/>
    <parent link="Limb0Connector2__1__1"/>
    <child link="Limb0Connector3__1__1"/>
  </joint>
  <joint name="Rigid 96" type="fixed">
    <origin rpy="0 0 0" xyz="-0.004207 0.004207 -0.005348"/>
    <parent link="Limb0Connector3__1__1"/>
    <child link="Limb0Roll2A__1__1"/>
  </joint>
  <joint name="Limb2Roll2" type="continuous">
    <origin rpy="0 0 0" xyz="-0.013146 0.013147 -0.016713"/>
    <parent link="Limb0Roll2A__1__1"/>
    <child link="Limb0Roll2B__1__1"/>
    <axis xyz="-0.52586 0.52586 -0.668537"/>
  </joint>
  <joint name="Rigid 98" type="fixed">
    <origin rpy="0 0 0" xyz="-0.00263 0.002629 -0.003343"/>
    <parent link="Limb0Roll2B__1__1"/>
    <child link="Limb0Roll2C__1__1"/>
  </joint>
  <joint name="Rigid 99" type="fixed">
    <origin rpy="0 0 0" xyz="-0.021954 0.099728 -0.076307"/>
    <parent link="Limb0Roll2C__1__1"/>
    <child link="Limb0Pitch3A__1__1"/>
  </joint>
  <joint name="Limb2Pitch3" type="continuous">
    <origin rpy="0 0 0" xyz="-0.001751 -0.001784 -2.6e-05"/>
    <parent link="Limb0Pitch3A__1__1"/>
    <child link="Limb0Pitch3B__1__1"/>
    <axis xyz="-0.70038 -0.713693 -0.010471"/>
  </joint>
  <joint name="Rigid 101" type="fixed">
    <origin rpy="0 0 0" xyz="0.0 0.0 0.0"/>
    <parent link="Limb0Pitch3B__1__1"/>
    <child link="Limb0Roll3A__1__1"/>
  </joint>
  <joint name="Limb2Roll3" type="continuous">
    <origin rpy="0 0 0" xyz="-0.056052 -0.014651 -0.027264"/>
    <parent link="Limb0Roll3A__1__1"/>
    <child link="Limb0Roll3B__1__1"/>
    <axis xyz="-0.52586 0.52586 -0.668537"/>
  </joint>
  <joint name="Rigid 103" type="fixed">
    <origin rpy="0 0 0" xyz="-0.005259 -0.005259 -0.006685"/>
    <parent link="Limb3Roll3B_1"/>
    <child link="Limb3Wheel_1"/>
  </joint>
  <joint name="Rigid 104" type="fixed">
    <origin rpy="0 0 0" xyz="-0.005259 0.005258 -0.006685"/>
    <parent link="Limb0Roll3B__1__1"/>
    <child link="Limb2Wheel_1"/>
  </joint>
  <joint name="Rigid 105" type="fixed">
    <origin rpy="0 0 0" xyz="0.005258 -0.005259 -0.006685"/>
    <parent link="Limb0Roll3B_2"/>
    <child link="Limb0Wheel_1"/>
  </joint>
  <joint name="Rigid 106" type="fixed">
    <origin rpy="0 0 0" xyz="0.005259 0.005258 -0.006685"/>
    <parent link="Limb1Roll3B_1"/>
    <child link="Limb1Wheel_1"/>
  </joint>
  <joint name="Rigid 107" type="fixed">
    <origin rpy="0 0 0" xyz="-0.014196 -0.014254 -0.018009"/>
    <parent link="Limb3BodyConnector_1"/>
    <child link="Connector4_1"/>
  </joint>
</robot>
