<?xml version="1.0" encoding="utf-8"?>
<!-- This URDF was automatically created by SolidWorks to URDF Exporter! Originally created by Stephen Brawner (brawner@gmail.com) 
     Commit Version: 1.6.0-4-g7f85cfe  Build Version: 1.6.7995.38578
     For more information, please see http://wiki.ros.org/sw_urdf_exporter -->
<robot name="mglimb_7dof" xmlns:xacro="http://www.ros.org/wiki/xacro">

<xacro:property name="ThisPackage" value="urdf_packer" />
<xacro:property name="Filename" value="mglimb_7dof" />
<xacro:property name="UrdfDataPath" value="package://${ThisPackage}/urdf/${Filename}" />
<xacro:property name="MeshPath" value="package://${ThisPackage}/meshes/${Filename}" />

  <material name="Black">
    <color rgba="0.2 0.2 0.2 0.7"/>
  </material>
  <material name="White">
    <color rgba="1.0 1.0 1.0 1.0"/>
  </material>
  <material name="Silver">
    <color rgba="0.653 0.653 0.653 1.0"/>
  </material>

  <link
  name="base_link">
  </link>
  <joint
    name="basefix"
    type="fixed">
    <origin
      xyz="0 0 0"
      rpy="3.1416 0 0" />
    <parent
      link="base_link" />
    <child
      link="eef1_link" />
  </joint>
  <link
    name="eef1_link">
    <inertial>
      <origin
        xyz="1.29013074179555E-07 7.84510574497553E-08 -0.00276488294745968"
        rpy="0 0 0" />
      <mass
        value="0.023752994516635" />
      <inertia
        ixx="7.776725833029E-06"
        ixy="1.92793729442485E-11"
        ixz="1.69361842652945E-11"
        iyy="7.77667085139128E-06"
        iyz="1.27496652782608E-11"
        izz="1.51480461432004E-05" />
    </inertial>
    <visual>
      <origin
        xyz="0 0 0"
        rpy="0 0 0" />
      <geometry>
        <mesh
          filename="${MeshPath}/eef1_link.STL" />
      </geometry>
      <material
        name="Black">
        <color
          rgba="0.792156862745098 0.819607843137255 0.933333333333333 1" />
      </material>
    </visual>
    <collision>
      <origin
        xyz="0 0 0"
        rpy="0 0 0" />
      <geometry>
        <mesh
          filename="${MeshPath}/eef1_link.STL" />
      </geometry>
    </collision>
  </link>
  <link
    name="link1">
    <inertial>
      <origin
        xyz="-0.000851392261437255 0.000502306553466234 -0.13561634672842"
        rpy="0 0 0" />
      <mass
        value="0.782146942513576" />
      <inertia
        ixx="0.00388029619747055"
        ixy="4.22018600087899E-06"
        ixz="0.000269392183701513"
        iyy="0.00361703953129617"
        iyz="2.03354036798432E-05"
        izz="0.00258877392358645" />
    </inertial>
    <visual>
      <origin
        xyz="0 0 0"
        rpy="0 0 0" />
      <geometry>
        <mesh
          filename="${MeshPath}/link1.STL" />
      </geometry>
      <material
        name="White">
        <color
          rgba="0.792156862745098 0.819607843137255 0.933333333333333 1" />
      </material>
    </visual>
    <collision>
      <origin
        xyz="0 0 0"
        rpy="0 0 0" />
      <geometry>
        <mesh
          filename="${MeshPath}/link1.STL" />
      </geometry>
    </collision>
  </link>
  <joint
    name="joint1"
    type="revolute">
    <origin
      xyz="0 0 0"
      rpy="0 0 0" />
    <parent
      link="eef1_link" />
    <child
      link="link1" />
    <axis
      xyz="0 0 1" />
    <limit
      lower="-3.141592"
      upper="3.141592"
      effort="10"
      velocity="10" />
  </joint>
  <link
    name="link2">
    <inertial>
      <origin
        xyz="0.0408105003144926 0.00297674224269077 0.0677917338127515"
        rpy="0 0 0" />
      <mass
        value="1.16776561398528" />
      <inertia
        ixx="0.00406810645044146"
        ixy="0.000102518031396251"
        ixz="-0.000124392967771108"
        iyy="0.00571443256075551"
        iyz="-9.48145811984983E-06"
        izz="0.00585291286623905" />
    </inertial>
    <visual>
      <origin
        xyz="0 0 0"
        rpy="0 0 0" />
      <geometry>
        <mesh
          filename="${MeshPath}/link2.STL" />
      </geometry>
      <material
        name="White">
        <color
          rgba="0.792156862745098 0.819607843137255 0.933333333333333 1" />
      </material>
    </visual>
    <collision>
      <origin
        xyz="0 0 0"
        rpy="0 0 0" />
      <geometry>
        <mesh
          filename="${MeshPath}/link2.STL" />
      </geometry>
    </collision>
  </link>
  <joint
    name="joint2"
    type="revolute">
    <origin
      xyz="-0.0725 0 -0.1971"
      rpy="3.1416 1.5708 0" />
    <parent
      link="link1" />
    <child
      link="link2" />
    <axis
      xyz="0 0 1" />
    <limit
      lower="-3.141592"
      upper="3.141592"
      effort="10"
      velocity="10" />
  </joint>
  <link
    name="link3">
    <inertial>
      <origin
        xyz="-0.00214588509326616 0.00119225730369518 0.162842874508915"
        rpy="0 0 0" />
      <mass
        value="2.91559633558469" />
      <inertia
        ixx="0.0148569440007064"
        ixy="-5.80390603936369E-06"
        ixz="0.000239584257521375"
        iyy="0.0147607356210609"
        iyz="-0.000244855992056839"
        izz="0.00922276007974285" />
    </inertial>
    <visual>
      <origin
        xyz="0 0 0"
        rpy="0 0 0" />
      <geometry>
        <mesh
          filename="${MeshPath}/link3.STL" />
      </geometry>
      <material
        name="White">
        <color
          rgba="0.792156862745098 0.819607843137255 0.933333333333333 1" />
      </material>
    </visual>
    <collision>
      <origin
        xyz="0 0 0"
        rpy="0 0 0" />
      <geometry>
        <mesh
          filename="${MeshPath}/link3.STL" />
      </geometry>
    </collision>
  </link>
  <joint
    name="joint3"
    type="revolute">
    <origin
      xyz="0.1971 0 0.0726"
      rpy="3.1415 -1.5708 0" />
    <parent
      link="link2" />
    <child
      link="link3" />
    <axis
      xyz="0 0 1" />
    <limit
      lower="-3.141592"
      upper="3.141592"
      effort="10"
      velocity="10" />
  </joint>
  <link
    name="link4">
    <inertial>
      <origin
        xyz="-0.16149366533282 -0.000165216661479077 -0.0722429668582283"
        rpy="0 0 0" />
      <mass
        value="2.49177490349903" />
      <inertia
        ixx="0.00765185163933554"
        ixy="3.84544984579443E-05"
        ixz="0.000481031406372384"
        iyy="0.0101234880737109"
        iyz="2.68345266050994E-06"
        izz="0.0103594575433918" />
    </inertial>
    <visual>
      <origin
        xyz="0 0 0"
        rpy="0 0 0" />
      <geometry>
        <mesh
          filename="${MeshPath}/link4.STL" />
      </geometry>
      <material
        name="White">
        <color
          rgba="0.792156862745098 0.819607843137255 0.933333333333333 1" />
      </material>
    </visual>
    <collision>
      <origin
        xyz="0 0 0"
        rpy="0 0 0" />
      <geometry>
        <mesh
          filename="${MeshPath}/link4.STL" />
      </geometry>
    </collision>
  </link>
  <joint
    name="joint4"
    type="revolute">
    <origin
      xyz="-0.0726 0 0.3026"
      rpy="0 1.5708 0" />
    <parent
      link="link3" />
    <child
      link="link4" />
    <axis
      xyz="0 0 1" />
    <limit
      lower="-3.141592"
      upper="3.141592"
      effort="10"
      velocity="10" />
  </joint>
  <link
    name="link5">
    <inertial>
      <origin
        xyz="-0.000851392261433597 0.000502306553460058 -0.13561634672842"
        rpy="0 0 0" />
      <mass
        value="0.782146942513575" />
      <inertia
        ixx="0.00388029619747055"
        ixy="4.22018600087864E-06"
        ixz="0.000269392183701513"
        iyy="0.00361703953129617"
        iyz="2.03354036798419E-05"
        izz="0.00258877392358645" />
    </inertial>
    <visual>
      <origin
        xyz="0 0 0"
        rpy="0 0 0" />
      <geometry>
        <mesh
          filename="${MeshPath}/link5.STL" />
      </geometry>
      <material
        name="White">
        <color
          rgba="0.792156862745098 0.819607843137255 0.933333333333333 1" />
      </material>
    </visual>
    <collision>
      <origin
        xyz="0 0 0"
        rpy="0 0 0" />
      <geometry>
        <mesh
          filename="${MeshPath}/link5.STL" />
      </geometry>
    </collision>
  </link>
  <joint
    name="joint5"
    type="revolute">
    <origin
      xyz="-0.3026 0 -0.0725"
      rpy="0 1.5708 0" />
    <parent
      link="link4" />
    <child
      link="link5" />
    <axis
      xyz="0 0 1" />
    <limit
      lower="-3.141592"
      upper="3.141592"
      effort="10"
      velocity="10" />
  </joint>
  <link
    name="link6">
    <inertial>
      <origin
        xyz="0.0408105002632231 0.00297674223999824 0.0677917336264018"
        rpy="0 0 0" />
      <mass
        value="1.16776561679624" />
      <inertia
        ixx="0.00406810645112587"
        ixy="0.000102518031254211"
        ixz="-0.000124392967409067"
        iyy="0.00571443256199961"
        iyz="-9.48145808718355E-06"
        izz="0.00585291286795255" />
    </inertial>
    <visual>
      <origin
        xyz="0 0 0"
        rpy="0 0 0" />
      <geometry>
        <mesh
          filename="${MeshPath}/link6.STL" />
      </geometry>
      <material
        name="White">
        <color
          rgba="0.792156862745098 0.819607843137255 0.933333333333333 1" />
      </material>
    </visual>
    <collision>
      <origin
        xyz="0 0 0"
        rpy="0 0 0" />
      <geometry>
        <mesh
          filename="${MeshPath}/link6.STL" />
      </geometry>
    </collision>
  </link>
  <joint
    name="joint6"
    type="revolute">
    <origin
      xyz="-0.0725 0 -0.1971"
      rpy="3.1416 1.5708 0" />
    <parent
      link="link5" />
    <child
      link="link6" />
    <axis
      xyz="0 0 1" />
    <limit
      lower="-3.141592"
      upper="3.141592"
      effort="10"
      velocity="10" />
  </joint>
  <link
    name="eef2_link">
    <inertial>
      <origin
        xyz="1.30452130375769E-07 7.93899120121129E-08 -0.00276488244597672"
        rpy="0 0 0" />
      <mass
        value="0.0237529928194326" />
      <inertia
        ixx="7.77672546197223E-06"
        ixy="1.97627851852036E-11"
        ixz="1.71710815737971E-11"
        iyy="7.77667005048947E-06"
        iyz="1.28942882663125E-11"
        izz="1.51480451084006E-05" />
    </inertial>
    <visual>
      <origin
        xyz="0 0 0"
        rpy="0 0 0" />
      <geometry>
        <mesh
          filename="${MeshPath}/eef2_link.STL" />
      </geometry>
      <material
        name="Black">
        <color
          rgba="0.792156862745098 0.819607843137255 0.933333333333333 1" />
      </material>
    </visual>
    <collision>
      <origin
        xyz="0 0 0"
        rpy="0 0 0" />
      <geometry>
        <mesh
          filename="${MeshPath}/eef2_link.STL" />
      </geometry>
    </collision>
  </link>
  <joint
    name="eef2_joint"
    type="revolute">
    <origin
      xyz="0.1971 0 0.0726"
      rpy="0 1.5708 0" />
    <parent
      link="link6" />
    <child
      link="eef2_link" />
    <axis
      xyz="0 0 1" />
    <limit
      lower="-3.141592"
      upper="3.141592"
      effort="10"
      velocity="10" />
  </joint>
  <link
  name="ee">
  </link>
  <joint
    name="eefix"
    type="fixed">
    <origin
      xyz="0 0 0"
      rpy="0 1.57 0" />
    <parent
      link="eef2_link" />
    <child
      link="ee" />
  </joint>
</robot>
