<?xml version="1.0" ?>
<robot name="moonbot_hero_onewheel" xmlns:xacro="http://www.ros.org/wiki/xacro">

<xacro:property name="ThisPackage" value="rviz_basic" />
<xacro:property name="Filename" value="moonbot_hero_onewheel" />
<xacro:property name="UrdfDataPath" value="package://${ThisPackage}/urdf/${Filename}" />
<xacro:property name="MeshPath" value="package://${ThisPackage}/meshes/${Filename}" />
  <!---->
  <!-- <material name="Grey"> -->
  <!--     <color rgba="0.9 0.9 0.98 1" /> -->
  <!-- </material> -->
  <!-- <material name="Black"> -->
  <!--     <color rgba="0.15 0.15 0.15 1" /> -->
  <!-- </material> -->
  <!-- <material name="silver"> -->
  <!--     <color rgba="0.9 0.9 0.98 1" /> -->
  <!-- </material> -->
  <!---->

<xacro:include filename="materials.xacro" />
<xacro:include filename="moonbot_hero_onewheel.trans" />
<xacro:include filename="moonbot_hero_onewheel.gazebo" />

<link name="base_link">
  <inertial>
    <origin xyz="-0.00020130822372109526 -0.00041717746604490196 0.15438663698423066" rpy="0 0 0"/>
    <mass value="12.36"/>
    <inertia ixx="0.2297" iyy="0.2343" izz="0.3465" ixy="0.000731" iyz="1.949e-05" ixz="-0.0001146"/>
  </inertial>
  <visual>
    <origin xyz="0 0 0" rpy="0 0 0"/>
    <geometry>
    <mesh filename="${MeshPath}/base_link.stl" scale="0.001 0.001 0.001"/>
    </geometry>
    <material name="silver"/>
  </visual>
  <collision>
    <origin xyz="0 0 0" rpy="0 0 0"/>
    <geometry>
    <mesh filename="${MeshPath}/base_link.stl" scale="0.001 0.001 0.001"/>
    </geometry>
  </collision>
</link>

<link name="leg3_link5">
  <inertial>
    <origin xyz="-0.021159945005317482 0.0007091330235085846 -0.04028686396790501" rpy="0 0 0"/>
    <mass value="1.93"/>
    <inertia ixx="0.006368" iyy="0.007211" izz="0.005935" ixy="0.000188" iyz="0.000507" ixz="-0.000417"/>
  </inertial>
  <visual>
    <origin xyz="0.852872 0.131589 -0.175691" rpy="0 0 0"/>
    <geometry>
    <mesh filename="${MeshPath}/leg3_link5.stl" scale="0.001 0.001 0.001"/>
    </geometry>
    <material name="silver"/>
  </visual>
  <collision>
    <origin xyz="0.852872 0.131589 -0.175691" rpy="0 0 0"/>
    <geometry>
    <mesh filename="${MeshPath}/leg3_link5.stl" scale="0.001 0.001 0.001"/>
    </geometry>
  </collision>
</link>

<link name="leg3_link6">
  <inertial>
    <origin xyz="-0.007545433439614002 0.05903172498691727 -0.0730631329498605" rpy="0 0 0"/>
    <mass value="2.28"/>
    <inertia ixx="0.018059" iyy="0.017801" izz="0.007751" ixy="2.964e-05" iyz="0.002299" ixz="-0.000296"/>
  </inertial>
  <visual>
    <origin xyz="0.89489 0.071421 -0.11" rpy="0 0 0"/>
    <geometry>
    <mesh filename="${MeshPath}/leg3_link6.stl" scale="0.001 0.001 0.001"/>
    </geometry>
    <material name="silver"/>
  </visual>
  <collision>
    <origin xyz="0.89489 0.071421 -0.11" rpy="0 0 0"/>
    <geometry>
    <mesh filename="${MeshPath}/leg3_link6.stl" scale="0.001 0.001 0.001"/>
    </geometry>
  </collision>
</link>

<link name="leg3_wheel_body">
  <inertial>
    <origin xyz="0.012120027900982211 1.7479052741023483e-05 -0.1932995813581685" rpy="0 0 0"/>
    <mass value="11.54"/>
    <inertia ixx="0.471666" iyy="0.151360" izz="0.388620" ixy="-0.000147" iyz="-3.506e-05" ixz="0.002595"/>
  </inertial>
  <visual>
    <origin xyz="0.904 0.0 0.052" rpy="0 0 0"/>
    <geometry>
    <mesh filename="${MeshPath}/leg3_wheel_body.stl" scale="0.001 0.001 0.001"/>
    </geometry>
    <material name="silver"/>
  </visual>
  <collision>
    <origin xyz="0.904 0.0 0.052" rpy="0 0 0"/>
    <geometry>
    <mesh filename="${MeshPath}/leg3_wheel_body.stl" scale="0.001 0.001 0.001"/>
    </geometry>
  </collision>
</link>

<link name="leg3_wheel_left">
  <inertial>
    <origin xyz="6.05831716671279e-06 -0.079400296699694 3.750658923479255e-05" rpy="0 0 0"/>
    <mass value="5.0"/>
    <inertia ixx="0.147594" iyy="0.254077" izz="0.147636" ixy="-2.387e-06" iyz="-1.538e-05" ixz="6.635e-06"/>
  </inertial>
  <visual>
    <origin xyz="0.9 -0.277 0.265" rpy="0 0 0"/>
    <geometry>
    <mesh filename="${MeshPath}/leg3_wheel_left.stl" scale="0.001 0.001 0.001"/>
    </geometry>
    <material name="black"/>
  </visual>
  <collision>
    <origin xyz="0.9 -0.277 0.265" rpy="0 0 0"/>
    <geometry>
    <mesh filename="${MeshPath}/leg3_wheel_left.stl" scale="0.001 0.001 0.001"/>
    </geometry>
  </collision>
</link>

<link name="leg3_link1">
  <inertial>
    <origin xyz="-0.08893686705016807 0.012060596527737295 0.003237902911888496" rpy="0 0 0"/>
    <mass value="2.28"/>
    <inertia ixx="0.007757" iyy="0.017492" izz="0.017873" ixy="0.002270" iyz="-6.585e-05" ixz="0.000602"/>
  </inertial>
  <visual>
    <origin xyz="0.2545 -0.00185 -0.13385" rpy="0 0 0"/>
    <geometry>
    <mesh filename="${MeshPath}/leg3_link1.stl" scale="0.001 0.001 0.001"/>
    </geometry>
    <material name="black"/>
  </visual>
  <collision>
    <origin xyz="0.2545 -0.00185 -0.13385" rpy="0 0 0"/>
    <geometry>
    <mesh filename="${MeshPath}/leg3_link1.stl" scale="0.001 0.001 0.001"/>
    </geometry>
  </collision>
</link>

<link name="leg3_link4">
  <inertial>
    <origin xyz="-0.0543492893914449 -0.06375843043692539 -0.1379499378657239" rpy="0 0 0"/>
    <mass value="4.41"/>
    <inertia ixx="0.093985" iyy="0.109865" izz="0.032541" ixy="-0.006813" iyz="-0.014181" ixz="-0.039216"/>
  </inertial>
  <visual>
    <origin xyz="0.6818 0.037995 -0.549033" rpy="0 0 0"/>
    <geometry>
    <mesh filename="${MeshPath}/leg3_link4.stl" scale="0.001 0.001 0.001"/>
    </geometry>
    <material name="silver"/>
  </visual>
  <collision>
    <origin xyz="0.6818 0.037995 -0.549033" rpy="0 0 0"/>
    <geometry>
    <mesh filename="${MeshPath}/leg3_link4.stl" scale="0.001 0.001 0.001"/>
    </geometry>
  </collision>
</link>

<link name="leg3_link2">
  <inertial>
    <origin xyz="-0.016598546111078694 0.053516688776755805 0.03842120008435529" rpy="0 0 0"/>
    <mass value="1.93"/>
    <inertia ixx="0.006282" iyy="0.007319" izz="0.005434" ixy="0.000114" iyz="-0.000076" ixz="0.000225"/>
  </inertial>
  <visual>
    <origin xyz="0.4165 -0.071411 -0.152432" rpy="0 0 0"/>
    <geometry>
    <mesh filename="${MeshPath}/leg3_link2.stl" scale="0.001 0.001 0.001"/>
    </geometry>
    <material name="silver"/>
  </visual>
  <collision>
    <origin xyz="0.4165 -0.071411 -0.152432" rpy="0 0 0"/>
    <geometry>
    <mesh filename="${MeshPath}/leg3_link2.stl" scale="0.001 0.001 0.001"/>
    </geometry>
  </collision>
</link>

<link name="leg3_link3">
  <inertial>
    <origin xyz="-0.1493496630860232 -0.06994867670473882 0.20670145689675534" rpy="0 0 0"/>
    <mass value="4.82"/>
    <inertia ixx="0.089469" iyy="0.112891" izz="0.056577" ixy="-0.018812" iyz="0.026072" ixz="0.047337"/>
  </inertial>
  <visual>
    <origin xyz="0.45944 -0.118655 -0.227433" rpy="0 0 0"/>
    <geometry>
    <mesh filename="${MeshPath}/leg3_link3.stl" scale="0.001 0.001 0.001"/>
    </geometry>
    <material name="silver"/>
  </visual>
  <collision>
    <origin xyz="0.45944 -0.118655 -0.227433" rpy="0 0 0"/>
    <geometry>
    <mesh filename="${MeshPath}/leg3_link3.stl" scale="0.001 0.001 0.001"/>
    </geometry>
  </collision>
</link>

<link name="leg3_wheel_right">
  <inertial>
    <origin xyz="-6.058317166268701e-06 0.07940029669969387 3.7506589234403975e-05" rpy="0 0 0"/>
    <mass value="5.0"/>
    <inertia ixx="0.147594" iyy="0.254077" izz="0.147636" ixy="-2.387e-06" iyz="1.538e-05" ixz="-6.635e-06"/>
  </inertial>
  <visual>
    <origin xyz="0.9 0.277 0.265" rpy="0 0 0"/>
    <geometry>
    <mesh filename="${MeshPath}/leg3_wheel_right.stl" scale="0.001 0.001 0.001"/>
    </geometry>
    <material name="black"/>
  </visual>
  <collision>
    <origin xyz="0.9 0.277 0.265" rpy="0 0 0"/>
    <geometry>
    <mesh filename="${MeshPath}/leg3_wheel_right.stl" scale="0.001 0.001 0.001"/>
    </geometry>
  </collision>
</link>

<joint name="leg3_joint5" type="continuous">
  <origin xyz="-0.171072 -0.093594 -0.373342" rpy="0 0 0"/>
  <parent link="leg3_link4"/>
  <child link="leg3_link5"/>
  <axis xyz="-0.456682 -0.05825 -0.887721"/>
</joint>

<joint name="leg3_joint6" type="continuous">
  <origin xyz="-0.042018 0.060168 -0.065691" rpy="0 0 0"/>
  <parent link="leg3_link5"/>
  <child link="leg3_link6"/>
  <axis xyz="-0.126525 0.991963 -0.0"/>
</joint>

<joint name="leg3_steering_joint" type="continuous">
  <origin xyz="-0.00911 0.071421 -0.162" rpy="0 0 0"/>
  <parent link="leg3_link6"/>
  <child link="leg3_wheel_body"/>
  <axis xyz="-0.0 0.0 -1.0"/>
</joint>

<joint name="leg3_wheel_left_joint" type="continuous">
  <origin xyz="0.004 0.277 -0.213" rpy="0 0 0"/>
  <parent link="leg3_wheel_body"/>
  <child link="leg3_wheel_left"/>
  <axis xyz="0.0 1.0 0.0"/>
</joint>

<joint name="leg3_joint1" type="continuous">
  <origin xyz="-0.2545 0.00185 0.13385" rpy="0 0 0"/>
  <parent link="base_link"/>
  <child link="leg3_link1"/>
  <axis xyz="-1.0 -0.0 -0.0"/>
</joint>

<joint name="leg3_joint4" type="continuous">
  <origin xyz="-0.22236 -0.15665 0.3216" rpy="0 0 0"/>
  <parent link="leg3_link3"/>
  <child link="leg3_link4"/>
  <axis xyz="0.25627 -0.96417 -0.068571"/>
</joint>

<joint name="leg3_joint2" type="continuous">
  <origin xyz="-0.162 0.069561 0.018582" rpy="0 0 0"/>
  <parent link="leg3_link1"/>
  <child link="leg3_link2"/>
  <axis xyz="-0.0 0.966122 0.258084"/>
</joint>

<joint name="leg3_joint3" type="continuous">
  <origin xyz="-0.04294 0.047244 0.075001" rpy="0 0 0"/>
  <parent link="leg3_link2"/>
  <child link="leg3_link3"/>
  <axis xyz="-0.580269 -0.21019 0.786834"/>
</joint>

<joint name="leg3_wheel_right_joint" type="continuous">
  <origin xyz="0.004 -0.277 -0.213" rpy="0 0 0"/>
  <parent link="leg3_wheel_body"/>
  <child link="leg3_wheel_right"/>
  <axis xyz="-0.0 -1.0 -0.0"/>
</joint>

</robot>
