<?xml version="1.0" encoding="UTF-8"?>
<robot name="ur16_3f" xmlns:xacro="http://www.ros.org/wiki/xacro">
  <xacro:property name="ThisPackage" value="urdf_packer"></xacro:property>
  <xacro:property name="Filename" value="ur16_3f"></xacro:property>
  <xacro:property name="UrdfDataPath" value="package://${ThisPackage}/urdf/${Filename}"></xacro:property>
  <xacro:property name="MeshPath" value="package://${ThisPackage}/meshes/${Filename}"></xacro:property>
  <link name="world"></link>
  <!-- links -  main serial chain -->
  <link name="base_link"></link>
  <link name="base_link_inertia">
    <visual>
      <origin rpy="0 0 3.141592653589793" xyz="0 0 0"></origin>
      <geometry>
        <mesh filename="${MeshPath}/ur10e/visual/base.dae"></mesh>
      </geometry>
    </visual>
    <collision>
      <origin rpy="0 0 3.141592653589793" xyz="0 0 0"></origin>
      <geometry>
        <mesh filename="${MeshPath}/ur10e/collision/base.stl"></mesh>
      </geometry>
    </collision>
    <inertial>
      <mass value="4.0"></mass>
      <origin rpy="0 0 0" xyz="0 0 0"></origin>
      <inertia ixx="0.0061063308908" ixy="0.0" ixz="0.0" iyy="0.0061063308908" iyz="0.0" izz="0.01125"></inertia>
    </inertial>
  </link>
  <link name="shoulder_link">
    <visual>
      <origin rpy="0 0 3.141592653589793" xyz="0 0 0"></origin>
      <geometry>
        <mesh filename="${MeshPath}/ur10e/visual/shoulder.dae"></mesh>
      </geometry>
    </visual>
    <collision>
      <origin rpy="0 0 3.141592653589793" xyz="0 0 0"></origin>
      <geometry>
        <mesh filename="${MeshPath}/ur10e/collision/shoulder.stl"></mesh>
      </geometry>
    </collision>
    <inertial>
      <mass value="7.369"></mass>
      <origin rpy="1.570796326794897 0 0" xyz="0.0 -0.03 -0.016"></origin>
      <inertia ixx="0.03351" ixy="2e-05" ixz="-1e-05" iyy="0.03374" iyz="0.00374" izz="0.021"></inertia>
    </inertial>
  </link>
  <link name="upper_arm_link">
    <visual>
      <origin rpy="1.5707963267948966 0 -1.5707963267948966" xyz="0 0 0.176"></origin>
      <geometry>
        <mesh filename="${MeshPath}/ur16e/visual/upperarm.dae"></mesh>
      </geometry>
    </visual>
    <collision>
      <origin rpy="1.5707963267948966 0 -1.5707963267948966" xyz="0 0 0.176"></origin>
      <geometry>
        <mesh filename="${MeshPath}/ur16e/collision/upperarm.stl"></mesh>
      </geometry>
    </collision>
    <inertial>
      <mass value="10.45"></mass>
      <origin rpy="0 0 0" xyz="-0.1764 0.0 0.16"></origin>
      <inertia ixx="0.02796" ixy="-0.0001" ixz="-0.0072" iyy="0.47558" iyz="3e-05" izz="0.47635"></inertia>
    </inertial>
  </link>
  <link name="forearm_link">
    <visual>
      <origin rpy="1.5707963267948966 0 -1.5707963267948966" xyz="0 0 0.04"></origin>
      <geometry>
        <mesh filename="${MeshPath}/ur16e/visual/forearm.dae"></mesh>
      </geometry>
    </visual>
    <collision>
      <origin rpy="1.5707963267948966 0 -1.5707963267948966" xyz="0 0 0.04"></origin>
      <geometry>
        <mesh filename="${MeshPath}/ur16e/collision/forearm.stl"></mesh>
      </geometry>
    </collision>
    <inertial>
      <mass value="4.321"></mass>
      <origin rpy="0 0 0" xyz="-0.166 0.0 0.065"></origin>
      <inertia ixx="0.01091" ixy="6e-05" ixz="0.01012" iyy="0.1206" iyz="1e-05" izz="0.11714"></inertia>
    </inertial>
  </link>
  <link name="wrist_1_link">
    <visual>
      <origin rpy="1.5707963267948966 0 0" xyz="0 0 -0.135"></origin>
      <geometry>
        <mesh filename="${MeshPath}/ur10e/visual/wrist1.dae"></mesh>
      </geometry>
    </visual>
    <collision>
      <origin rpy="1.5707963267948966 0 0" xyz="0 0 -0.135"></origin>
      <geometry>
        <mesh filename="${MeshPath}/ur10e/collision/wrist1.stl"></mesh>
      </geometry>
    </collision>
    <inertial>
      <mass value="2.18"></mass>
      <origin rpy="1.570796326794897 0 0" xyz="0.0 -0.011 -0.009"></origin>
      <inertia ixx="0.00609" ixy="-1e-05" ixz="0.0" iyy="0.00245" iyz="0.00083" izz="0.00579"></inertia>
    </inertial>
  </link>
  <link name="wrist_2_link">
    <visual>
      <origin rpy="0 0 0" xyz="0 0 -0.12"></origin>
      <geometry>
        <mesh filename="${MeshPath}/ur10e/visual/wrist2.dae"></mesh>
      </geometry>
    </visual>
    <collision>
      <origin rpy="0 0 0" xyz="0 0 -0.12"></origin>
      <geometry>
        <mesh filename="${MeshPath}/ur10e/collision/wrist2.stl"></mesh>
      </geometry>
    </collision>
    <inertial>
      <mass value="2.033"></mass>
      <origin rpy="-1.570796326794897 0 0" xyz="0.0 0.012 -0.018"></origin>
      <inertia ixx="0.00389" ixy="-1e-05" ixz="0.0" iyy="0.00219" iyz="-0.00045" izz="0.00363"></inertia>
    </inertial>
  </link>
  <link name="wrist_3_link">
    <visual>
      <origin rpy="1.5707963267948966 0 0" xyz="0 0 -0.1168"></origin>
      <geometry>
        <mesh filename="${MeshPath}/ur10e/visual/wrist3.dae"></mesh>
      </geometry>
    </visual>
    <collision>
      <origin rpy="1.5707963267948966 0 0" xyz="0 0 -0.1168"></origin>
      <geometry>
        <mesh filename="${MeshPath}/ur10e/collision/wrist3.stl"></mesh>
      </geometry>
    </collision>
    <inertial>
      <mass value="0.907"></mass>
      <origin rpy="0 0 0" xyz="0.0 0.0 -0.044"></origin>
      <inertia ixx="0.00117" ixy="0.0" ixz="0.0" iyy="0.00118" iyz="0.0" izz="0.00084"></inertia>
    </inertial>
  </link>
  <!-- base_joint fixes base_link to the environment -->
  <joint name="base_joint" type="fixed">
    <origin rpy="0 0 0" xyz="0 0 0"></origin>
    <parent link="world"></parent>
    <child link="base_link"></child>
  </joint>
  <!-- joints - main serial chain -->
  <joint name="base_link-base_link_inertia" type="fixed">
    <parent link="base_link"></parent>
    <child link="base_link_inertia"></child>
    <!-- 'base_link' is REP-103 aligned (so X+ forward), while the internal frames of the robot/controller have X+ pointing backwards. Use the joint between 'base_link' and 'base_link_inertia' (a dummy link/frame) to introduce the necessary rotation over Z (of pi rad). -->
    <origin rpy="0 0 3.141592653589793" xyz="0 0 0"></origin>
  </joint>
  <joint name="shoulder_pan_joint" type="revolute">
    <parent link="base_link_inertia"></parent>
    <child link="shoulder_link"></child>
    <origin rpy="0 0 0" xyz="0 0 0.1807"></origin>
    <axis xyz="0 0 1"></axis>
    <limit effort="330.0" lower="-6.283185307179586" upper="6.283185307179586" velocity="2.0943951023931953"></limit>
    <safety_controller k_position="20" k_velocity="0.0" soft_lower_limit="-6.133185307179586" soft_upper_limit="6.133185307179586"></safety_controller>
    <dynamics damping="0" friction="0"></dynamics>
  </joint>
  <joint name="shoulder_lift_joint" type="revolute">
    <parent link="shoulder_link"></parent>
    <child link="upper_arm_link"></child>
    <origin rpy="1.570796327 0 0" xyz="0 0 0"></origin>
    <axis xyz="0 0 1"></axis>
    <limit effort="330.0" lower="-6.283185307179586" upper="6.283185307179586" velocity="2.0943951023931953"></limit>
    <safety_controller k_position="20" k_velocity="0.0" soft_lower_limit="-6.133185307179586" soft_upper_limit="6.133185307179586"></safety_controller>
    <dynamics damping="0" friction="0"></dynamics>
  </joint>
  <joint name="elbow_joint" type="revolute">
    <parent link="upper_arm_link"></parent>
    <child link="forearm_link"></child>
    <origin rpy="0 0 0" xyz="-0.4784 0 0"></origin>
    <axis xyz="0 0 1"></axis>
    <limit effort="150.0" lower="-3.141592653589793" upper="3.141592653589793" velocity="3.141592653589793"></limit>
    <safety_controller k_position="20" k_velocity="0.0" soft_lower_limit="-2.991592653589793" soft_upper_limit="2.991592653589793"></safety_controller>
    <dynamics damping="0" friction="0"></dynamics>
  </joint>
  <joint name="wrist_1_joint" type="revolute">
    <parent link="forearm_link"></parent>
    <child link="wrist_1_link"></child>
    <origin rpy="0 0 0" xyz="-0.36 0 0.17415"></origin>
    <axis xyz="0 0 1"></axis>
    <limit effort="54.0" lower="-6.283185307179586" upper="6.283185307179586" velocity="3.141592653589793"></limit>
    <safety_controller k_position="20" k_velocity="0.0" soft_lower_limit="-6.133185307179586" soft_upper_limit="6.133185307179586"></safety_controller>
    <dynamics damping="0" friction="0"></dynamics>
  </joint>
  <joint name="wrist_2_joint" type="revolute">
    <parent link="wrist_1_link"></parent>
    <child link="wrist_2_link"></child>
    <origin rpy="1.570796327 0 0" xyz="0 -0.11985 -2.458164590756244e-11"></origin>
    <axis xyz="0 0 1"></axis>
    <limit effort="54.0" lower="-6.283185307179586" upper="6.283185307179586" velocity="3.141592653589793"></limit>
    <safety_controller k_position="20" k_velocity="0.0" soft_lower_limit="-6.133185307179586" soft_upper_limit="6.133185307179586"></safety_controller>
    <dynamics damping="0" friction="0"></dynamics>
  </joint>
  <joint name="wrist_3_joint" type="revolute">
    <parent link="wrist_2_link"></parent>
    <child link="wrist_3_link"></child>
    <origin rpy="1.570796326589793 3.141592653589793 3.141592653589793" xyz="0 0.11655 -2.390480459346185e-11"></origin>
    <axis xyz="0 0 1"></axis>
    <limit effort="54.0" lower="-6.283185307179586" upper="6.283185307179586" velocity="3.141592653589793"></limit>
    <safety_controller k_position="20" k_velocity="0.0" soft_lower_limit="-6.133185307179586" soft_upper_limit="6.133185307179586"></safety_controller>
    <dynamics damping="0" friction="0"></dynamics>
  </joint>


  <!--Start of 3f gripper joint and linkages-->


 <joint
    name="tool_joint"
    type="revolute">
    <origin
      xyz="0 0 0.132"
      rpy="1.57 0 0" />
    <parent link="wrist_3_link" />
    <child link="palm" />
    <axis
      xyz="0 0 1" />
    <limit
      lower="0"
      upper="0"
      effort="0"
      velocity="0" />
  </joint>

<!--Palm link-->

  <link name="palm">
    <visual>
      <geometry>
      <mesh filename="${MeshPath}/robotiq-3f-gripper_articulated/visual/palm_new.stl"/>
      </geometry>
      <material name="green">
        <color rgba="0 1 0 1"/>
      </material>
    </visual>
    <collision>
      <geometry>
      <mesh filename="${MeshPath}/robotiq-3f-gripper_articulated/collision/palm_new.stl"/>
      </geometry>
      <material name="yellow">
        <color rgba="0 1 1 1"/>
      </material>
    </collision>
  </link>
  <inertial>
    <origin rpy="1.57 0 0" xyz="0 0 0.132"/>
    <mass value="1.3"/>
    <inertia ixx="0.078" ixy="-6.419E-07" ixz="0" iyy="1.909E-08" iyz="5.645E-07" izz="0.078"/>
  </inertial>
  <joint name="palm_finger_1_joint" type="revolute">
    <parent link="palm"/>
    <child link="finger_1_link_0"/>
    <axis xyz="0 1 0"/>
    <origin rpy="0 3.1416 -1.57" xyz="-0.0455 0.0214 0.036"/>
    <limit effort="100" lower="-0.16" upper="0.25" velocity="100"/>
  </joint>
  <joint name="palm_finger_2_joint" type="revolute">
    <parent link="palm"/>
    <child link="finger_2_link_0"/>
    <axis xyz="0 1 0"/>
    <origin rpy="0 3.1416 -1.57" xyz="-0.0455 0.0214 -0.036"/>
    <limit effort="100" lower="-0.25" upper="0.16" velocity="100"/>
  </joint>
  <joint name="palm_finger_middle_joint" type="fixed">
    <parent link="palm"/>
    <child link="finger_middle_link_0"/>
    <axis xyz="0 0 1"/>
    <origin rpy="0 0 1.57" xyz="0.0455 0.0214 0"/>
  </joint>


  <link name="finger_1_link_0">
    <visual>
      <origin rpy="0 0 0" xyz="0.020 0 0"/>
      <geometry>
      <mesh filename="${MeshPath}/robotiq-3f-gripper_articulated/visual/link_0.STL"/>
      </geometry>
      <material name="green">
        <color rgba="0 1 0 1"/>
      </material>
    </visual>
    <collision>
      <origin rpy="0 3.1416 -1.57" xyz="-0.0455 0.0414 0.036"/>
      <geometry>
      <mesh filename="${MeshPath}/robotiq-3f-gripper_articulated/collision/link_0.STL"/>
      </geometry>
      <material name="yellow">
        <color rgba="0 1 1 1"/>
      </material>
    </collision>
    <inertial>
      <origin rpy="0 0 0" xyz="0 0 0"/>
      <mass value="0.05"/>
      <inertia ixx="0.01" ixy="-0.00002" ixz="0.00001" iyy="0.0008" iyz="0" izz="0.001"/>
    </inertial>
  </link>
  <link name="finger_1_link_1">
    <visual>
      <origin rpy="0 0 -0.52" xyz="0.050 -.028 0"/>
      <geometry>
      <mesh filename="${MeshPath}/robotiq-3f-gripper_articulated/visual/link_1.STL"/>
      </geometry>
      <material name="green"/>
    </visual>
    <collision>
      <origin rpy="0 0 -0.52" xyz="0.050 -.028 0"/>
      <geometry>
      <mesh filename="${MeshPath}/robotiq-3f-gripper_articulated/collision/link_1.STL"/>
      </geometry>
      <material name="yellow"/>
    </collision>
    <inertial>
      <origin rpy="0 0 0" xyz="0 0 0"/>
      <mass value="0.15"/>
      <inertia ixx="0.001859" ixy="-0.000376" ixz="0.000028" iyy="0.012756" iyz="0" izz="0.0024"/>
    </inertial>
  </link>
  <link name="finger_1_link_2">
    <!--
			NOTE: This link has an offset in the z-direction based on the models that were
			used to generate grap-it poses.  With the offset below the model appears visually
			correct, but it is suspect.
			-->
    <visual>
      <origin rpy="0 0 0" xyz="0.039 0 0.0075"/>
      <geometry>
      <mesh filename="${MeshPath}/robotiq-3f-gripper_articulated/visual/link_2.STL"/>
      </geometry>
      <material name="green"/>
    </visual>
    <collision>
      <origin rpy="0 0 0" xyz="0.039 0 0.0075"/>
      <geometry>
      <mesh filename="${MeshPath}/robotiq-3f-gripper_articulated/collision/link_2.STL"/>
      </geometry>
      <material name="yellow"/>
    </collision>
    <inertial>
      <origin rpy="0 0 0" xyz="0 0 0"/>
      <mass value="0.15"/>
      <inertia ixx="0.001859" ixy="-0.000376" ixz="0.000028" iyy="0.012756" iyz="0" izz="0.0024"/>
    </inertial>
  </link>
  <link name="finger_1_link_3">
    <visual>
      <origin rpy="0 0 0.52" xyz="0 0 0"/>
      <geometry>
      <mesh filename="${MeshPath}/robotiq-3f-gripper_articulated/visual/link_3.STL"/>
      </geometry>
      <material name="green"/>
    </visual>
    <collision>
      <origin rpy="0 0 0.52" xyz="0 0 0"/>
      <geometry>
      <mesh filename="${MeshPath}/robotiq-3f-gripper_articulated/collision/link_3.STL"/>
      </geometry>
      <material name="yellow"/>
    </collision>
    <inertial>
      <origin rpy="0 0 0" xyz="0 0 0"/>
      <mass value="0.05"/>
      <inertia ixx="0.001239" ixy="-0.000251" ixz="0.000019" iyy="0.00085" iyz="0" izz="0.001632"/>
    </inertial>
  </link>
  <joint name="finger_1_joint_1" type="revolute">
    <parent link="finger_1_link_0"/>
    <child link="finger_1_link_1"/>
    <axis xyz="0 0 1"/>
    <origin rpy="0 0 0" xyz="0.020 0 0"/>
    <limit effort="100" lower="0" upper="3.1416" velocity="100"/>
  </joint>
  <joint name="finger_1_joint_2" type="revolute">
    <parent link="finger_1_link_1"/>
    <child link="finger_1_link_2"/>
    <axis xyz="0 0 1"/>
    <origin rpy="0 0 -0.52" xyz="0.050 -.028 0"/>
    <limit effort="100" lower="0" upper="3.1416" velocity="100"/>
  </joint>
  <joint name="finger_1_joint_3" type="revolute">
    <parent link="finger_1_link_2"/>
    <child link="finger_1_link_3"/>
    <axis xyz="0 0 1"/>
    <origin rpy="0 0 0" xyz="0.039 0 0"/>
    <limit effort="100" lower="0" upper="3.1416" velocity="100"/>
  </joint>
  <link name="finger_2_link_0">
    <visual>
      <origin rpy="0 0 0" xyz="0.020 0 0"/>
      <geometry>
      <mesh filename="${MeshPath}/robotiq-3f-gripper_articulated/visual/link_0.STL"/>
      </geometry>
      <material name="green">
        <color rgba="0 1 0 1"/>
      </material>
    </visual>
    <collision>
      <origin rpy="0 3.1416 -1.57" xyz="-0.0455 0.0414 0.036"/>
      <geometry>
      <mesh filename="${MeshPath}/robotiq-3f-gripper_articulated/collision/link_0.STL"/>
      </geometry>
      <material name="yellow">
        <color rgba="0 1 1 1"/>
      </material>
    </collision>
    <inertial>
      <origin rpy="0 0 0" xyz="0 0 0"/>
      <mass value="0.05"/>
      <inertia ixx="0.01" ixy="-0.00002" ixz="0.00001" iyy="0.0008" iyz="0" izz="0.001"/>
    </inertial>
  </link>
  <link name="finger_2_link_1">
    <visual>
      <origin rpy="0 0 -0.52" xyz="0.050 -.028 0"/>
      <geometry>
      <mesh filename="${MeshPath}/robotiq-3f-gripper_articulated/visual/link_1.STL"/>
      </geometry>
      <material name="green"/>
    </visual>
    <collision>
      <origin rpy="0 0 -0.52" xyz="0.050 -.028 0"/>
      <geometry>
      <mesh filename="${MeshPath}/robotiq-3f-gripper_articulated/collision/link_1.STL"/>
      </geometry>
      <material name="yellow"/>
    </collision>
    <inertial>
      <origin rpy="0 0 0" xyz="0 0 0"/>
      <mass value="0.15"/>
      <inertia ixx="0.001859" ixy="-0.000376" ixz="0.000028" iyy="0.012756" iyz="0" izz="0.0024"/>
    </inertial>
  </link>
  <link name="finger_2_link_2">
    <!--
			NOTE: This link has an offset in the z-direction based on the models that were
			used to generate grap-it poses.  With the offset below the model appears visually
			correct, but it is suspect.
			-->
    <visual>
      <origin rpy="0 0 0" xyz="0.039 0 0.0075"/>
      <geometry>
      <mesh filename="${MeshPath}/robotiq-3f-gripper_articulated/visual/link_2.STL"/>
      </geometry>
      <material name="green"/>
    </visual>
    <collision>
      <origin rpy="0 0 0" xyz="0.039 0 0.0075"/>
      <geometry>
      <mesh filename="${MeshPath}/robotiq-3f-gripper_articulated/collision/link_2.STL"/>
      </geometry>
      <material name="yellow"/>
    </collision>
    <inertial>
      <origin rpy="0 0 0" xyz="0 0 0"/>
      <mass value="0.15"/>
      <inertia ixx="0.001859" ixy="-0.000376" ixz="0.000028" iyy="0.012756" iyz="0" izz="0.0024"/>
    </inertial>
  </link>
  <link name="finger_2_link_3">
    <visual>
      <origin rpy="0 0 0.52" xyz="0 0 0"/>
      <geometry>
      <mesh filename="${MeshPath}/robotiq-3f-gripper_articulated/visual/link_3.STL"/>
      </geometry>
      <material name="green"/>
    </visual>
    <collision>
      <origin rpy="0 0 0.52" xyz="0 0 0"/>
      <geometry>
      <mesh filename="${MeshPath}/robotiq-3f-gripper_articulated/collision/link_3.STL"/>
      </geometry>
      <material name="yellow"/>
    </collision>
    <inertial>
      <origin rpy="0 0 0" xyz="0 0 0"/>
      <mass value="0.05"/>
      <inertia ixx="0.001239" ixy="-0.000251" ixz="0.000019" iyy="0.00085" iyz="0" izz="0.001632"/>
    </inertial>
  </link>
  <joint name="finger_2_joint_1" type="revolute">
    <parent link="finger_2_link_0"/>
    <child link="finger_2_link_1"/>
    <axis xyz="0 0 1"/>
    <origin rpy="0 0 0" xyz="0.020 0 0"/>
    <limit effort="100" lower="0" upper="3.1416" velocity="100"/>
  </joint>
  <joint name="finger_2_joint_2" type="revolute">
    <parent link="finger_2_link_1"/>
    <child link="finger_2_link_2"/>
    <axis xyz="0 0 1"/>
    <origin rpy="0 0 -0.52" xyz="0.050 -.028 0"/>
    <limit effort="100" lower="0" upper="3.1416" velocity="100"/>
  </joint>
  <joint name="finger_2_joint_3" type="revolute">
    <parent link="finger_2_link_2"/>
    <child link="finger_2_link_3"/>
    <axis xyz="0 0 1"/>
    <origin rpy="0 0 0" xyz="0.039 0 0"/>
    <limit effort="100" lower="0" upper="3.1416" velocity="100"/>
  </joint>
  <link name="finger_middle_link_0">
    <visual>
      <origin rpy="0 0 0" xyz="0.020 0 0"/>
      <geometry>
      <mesh filename="${MeshPath}/robotiq-3f-gripper_articulated/visual/link_0.STL"/>
      </geometry>
      <material name="green">
        <color rgba="0 1 0 1"/>
      </material>
    </visual>
    <collision>
      <origin rpy="0 3.1416 -1.57" xyz="-0.0455 0.0414 0.036"/>
      <geometry>
      <mesh filename="${MeshPath}/robotiq-3f-gripper_articulated/collision/link_0.STL"/>
      </geometry>
      <material name="yellow">
        <color rgba="0 1 1 1"/>
      </material>
    </collision>
    <inertial>
      <origin rpy="0 0 0" xyz="0 0 0"/>
      <mass value="0.05"/>
      <inertia ixx="0.01" ixy="-0.00002" ixz="0.00001" iyy="0.0008" iyz="0" izz="0.001"/>
    </inertial>
  </link>
  <link name="finger_middle_link_1">
    <visual>
      <origin rpy="0 0 -0.52" xyz="0.050 -.028 0"/>
      <geometry>
      <mesh filename="${MeshPath}/robotiq-3f-gripper_articulated/visual/link_1.STL"/>
      </geometry>
      <material name="green"/>
    </visual>
    <collision>
      <origin rpy="0 0 -0.52" xyz="0.050 -.028 0"/>
      <geometry>
      <mesh filename="${MeshPath}/robotiq-3f-gripper_articulated/collision/link_1.STL"/>
      </geometry>
      <material name="yellow"/>
    </collision>
    <inertial>
      <origin rpy="0 0 0" xyz="0 0 0"/>
      <mass value="0.15"/>
      <inertia ixx="0.001859" ixy="-0.000376" ixz="0.000028" iyy="0.012756" iyz="0" izz="0.0024"/>
    </inertial>
  </link>
  <link name="finger_middle_link_2">
    <!--
			NOTE: This link has an offset in the z-direction based on the models that were
			used to generate grap-it poses.  With the offset below the model appears visually
			correct, but it is suspect.
			-->
    <visual>
      <origin rpy="0 0 0" xyz="0.039 0 0.0075"/>
      <geometry>
      <mesh filename="${MeshPath}/robotiq-3f-gripper_articulated/visual/link_2.STL"/>
      </geometry>
      <material name="green"/>
    </visual>
    <collision>
      <origin rpy="0 0 0" xyz="0.039 0 0.0075"/>
      <geometry>
      <mesh filename="${MeshPath}/robotiq-3f-gripper_articulated/collision/link_2.STL"/>
      </geometry>
      <material name="yellow"/>
    </collision>
    <inertial>
      <origin rpy="0 0 0" xyz="0 0 0"/>
      <mass value="0.15"/>
      <inertia ixx="0.001859" ixy="-0.000376" ixz="0.000028" iyy="0.012756" iyz="0" izz="0.0024"/>
    </inertial>
  </link>
  <link name="finger_middle_link_3">
    <visual>
      <origin rpy="0 0 0.52" xyz="0 0 0"/>
      <geometry>
      <mesh filename="${MeshPath}/robotiq-3f-gripper_articulated/visual/link_3.STL"/>
      </geometry>
      <material name="green"/>
    </visual>
    <collision>
      <origin rpy="0 0 0.52" xyz="0 0 0"/>
      <geometry>
      <mesh filename="${MeshPath}/robotiq-3f-gripper_articulated/collision/link_3.STL"/>
      </geometry>
      <material name="yellow"/>
    </collision>
    <inertial>
      <origin rpy="0 0 0" xyz="0 0 0"/>
      <mass value="0.05"/>
      <inertia ixx="0.001239" ixy="-0.000251" ixz="0.000019" iyy="0.00085" iyz="0" izz="0.001632"/>
    </inertial>
  </link>
  <joint name="finger_middle_joint_1" type="revolute">
    <parent link="finger_middle_link_0"/>
    <child link="finger_middle_link_1"/>
    <axis xyz="0 0 1"/>
    <origin rpy="0 0 0" xyz="0.020 0 0"/>
    <limit effort="100" lower="0" upper="3.1416" velocity="100"/>
  </joint>
  <joint name="finger_middle_joint_2" type="revolute">
    <parent link="finger_middle_link_1"/>
    <child link="finger_middle_link_2"/>
    <axis xyz="0 0 1"/>
    <origin rpy="0 0 -0.52" xyz="0.050 -.028 0"/>
    <limit effort="100" lower="0" upper="3.1416" velocity="100"/>
  </joint>
  <joint name="finger_middle_joint_3" type="revolute">
    <parent link="finger_middle_link_2"/>
    <child link="finger_middle_link_3"/>
    <axis xyz="0 0 1"/>
    <origin rpy="0 0 0" xyz="0.039 0 0"/>
    <limit effort="100" lower="0" upper="3.1416" velocity="100"/>
  </joint>
</robot>
