<?xml version="1.0" ?>
<robot name="moonbot_hero2" xmlns:xacro="http://www.ros.org/wiki/xacro">

<xacro:property name="ThisPackage" value="rviz_basic" />
<xacro:property name="Filename" value="moonbot_hero2" />
<xacro:property name="UrdfDataPath" value="package://${ThisPackage}/urdf/${Filename}" />
<xacro:property name="MeshPath" value="package://${ThisPackage}/meshes/${Filename}" />

  <material name="Grey">
      <color rgba="0.9 0.9 0.98 1" />
  </material>
  <material name="Black">
      <color rgba="0.15 0.15 0.15 1" />
  </material>
  <material name="silver">
      <color rgba="0.9 0.9 0.98 1" />
  </material>

<link name="base_link">
  <inertial>
    <origin xyz="-0.00020130822372109526 -0.0004171774660448793 0.6743866369842314" rpy="0 0 0"/>
    <mass value="25.978941369"/>
    <inertia ixx="0.695743" iyy="0.709859" izz="1.049562" ixy="0.002215" iyz="5.9e-05" ixz="-0.000347"/>
  </inertial>
  <visual>
    <origin xyz="0 0 0" rpy="0 0 0"/>
    <geometry>
    <mesh filename="${MeshPath}/base_link.stl" scale="0.001 0.001 0.001"/>
    </geometry>
    <material name="silver"/>
  </visual>
  <collision>
    <origin xyz="0 0 0" rpy="0 0 0"/>
    <geometry>
    <mesh filename="${MeshPath}/base_link.stl" scale="0.001 0.001 0.001"/>
    </geometry>
  </collision>
</link>

<link name="arm_link1">
  <inertial>
    <origin xyz="-0.0007634208674246793 0.012464319005582487 -0.436063132949862" rpy="0 0 0"/>
    <mass value="2.28"/>
    <inertia ixx="0.025983" iyy="0.025619" izz="0.011186" ixy="1.9e-05" iyz="-0.003347" ixz="0.000212"/>
  </inertial>
  <visual>
    <origin xyz="0.00285 -0.00025 -1.362" rpy="0 0 0"/>
    <geometry>
    <mesh filename="${MeshPath}/arm_link1.stl" scale="0.001 0.001 0.001"/>
    </geometry>
    <material name="silver"/>
  </visual>
  <collision>
    <origin xyz="0.00285 -0.00025 -1.362" rpy="0 0 0"/>
    <geometry>
    <mesh filename="${MeshPath}/arm_link1.stl" scale="0.001 0.001 0.001"/>
    </geometry>
  </collision>
</link>

<link name="arm_link2">
  <inertial>
    <origin xyz="-0.026211875620127584 0.06010163678953524 0.01778915040025797" rpy="0 0 0"/>
    <mass value="1.93"/>
    <inertia ixx="0.004037" iyy="0.004828" izz="0.004205" ixy="0.000281" iyz="-0.000242" ixz="0.000295"/>
  </inertial>
  <visual>
    <origin xyz="0.007341 -0.07211 -0.999" rpy="0 0 0"/>
    <geometry>
    <mesh filename="${MeshPath}/arm_link2.stl" scale="0.001 0.001 0.001"/>
    </geometry>
    <material name="silver"/>
  </visual>
  <collision>
    <origin xyz="0.007341 -0.07211 -0.999" rpy="0 0 0"/>
    <geometry>
    <mesh filename="${MeshPath}/arm_link2.stl" scale="0.001 0.001 0.001"/>
    </geometry>
  </collision>
</link>

<link name="arm_link3">
  <inertial>
    <origin xyz="-0.18171763650050415 -0.015302450234697215 0.14453021333747929" rpy="0 0 0"/>
    <mass value="4.82"/>
    <inertia ixx="0.025271" iyy="0.055622" izz="0.036405" ixy="-0.00326" iyz="0.002588" ixz="0.024166"/>
  </inertial>
  <visual>
    <origin xyz="0.069254 -0.133367 -1.044992" rpy="0 0 0"/>
    <geometry>
    <mesh filename="${MeshPath}/arm_link3.stl" scale="0.001 0.001 0.001"/>
    </geometry>
    <material name="silver"/>
  </visual>
  <collision>
    <origin xyz="0.069254 -0.133367 -1.044992" rpy="0 0 0"/>
    <geometry>
    <mesh filename="${MeshPath}/arm_link3.stl" scale="0.001 0.001 0.001"/>
    </geometry>
  </collision>
</link>

<link name="arm_link4">
  <inertial>
    <origin xyz="0.15254203042141187 -0.049425875211967236 -0.018363332497189466" rpy="0 0 0"/>
    <mass value="4.41"/>
    <inertia ixx="0.008316" iyy="0.070645" izz="0.070131" ixy="0.003222" iyz="-0.000379" ixz="0.007326"/>
  </inertial>
  <visual>
    <origin xyz="0.390617 -0.048174 -1.301738" rpy="0 0 0"/>
    <geometry>
    <mesh filename="${MeshPath}/arm_link4.stl" scale="0.001 0.001 0.001"/>
    </geometry>
    <material name="silver"/>
  </visual>
  <collision>
    <origin xyz="0.390617 -0.048174 -1.301738" rpy="0 0 0"/>
    <geometry>
    <mesh filename="${MeshPath}/arm_link4.stl" scale="0.001 0.001 0.001"/>
    </geometry>
  </collision>
</link>

<link name="leg2_link1">
  <inertial>
    <origin xyz="0.050341123955856076 0.07363140310338845 0.010486221539076301" rpy="0 0 0"/>
    <mass value="2.28"/>
    <inertia ixx="0.020624" iyy="0.016442" izz="0.025723" ixy="-0.007276" iyz="-0.002353" ixz="-0.00155"/>
  </inertial>
  <visual>
    <origin xyz="-0.12795 -0.217916 -0.65335" rpy="0 0 0"/>
    <geometry>
    <mesh filename="${MeshPath}/leg2_link1.stl" scale="0.001 0.001 0.001"/>
    </geometry>
    <material name="silver"/>
  </visual>
  <collision>
    <origin xyz="-0.12795 -0.217916 -0.65335" rpy="0 0 0"/>
    <geometry>
    <mesh filename="${MeshPath}/leg2_link1.stl" scale="0.001 0.001 0.001"/>
    </geometry>
  </collision>
</link>

<link name="leg2_link2">
  <inertial>
    <origin xyz="0.013270336098678698 0.001898752347496091 0.06660418316991723" rpy="0 0 0"/>
    <mass value="1.93"/>
    <inertia ixx="0.004551" iyy="0.004358" izz="0.004161" ixy="-3.2e-05" iyz="-0.000447" ixz="0.000399"/>
  </inertial>
  <visual>
    <origin xyz="-0.242874 -0.338626 -0.713761" rpy="0 0 0"/>
    <geometry>
    <mesh filename="${MeshPath}/leg2_link2.stl" scale="0.001 0.001 0.001"/>
    </geometry>
    <material name="silver"/>
  </visual>
  <collision>
    <origin xyz="-0.242874 -0.338626 -0.713761" rpy="0 0 0"/>
    <geometry>
    <mesh filename="${MeshPath}/leg2_link2.stl" scale="0.001 0.001 0.001"/>
    </geometry>
  </collision>
</link>

<link name="leg2_link3">
  <inertial>
    <origin xyz="-0.15401638383697935 0.17455131996975393 0.12543634174155427" rpy="0 0 0"/>
    <mass value="4.82"/>
    <inertia ixx="0.047563" iyy="0.042844" izz="0.058685" ixy="0.025657" iyz="-0.018496" ixz="0.016793"/>
  </inertial>
  <visual>
    <origin xyz="-0.232746 -0.369216 -0.806835" rpy="0 0 0"/>
    <geometry>
    <mesh filename="${MeshPath}/leg2_link3.stl" scale="0.001 0.001 0.001"/>
    </geometry>
    <material name="silver"/>
  </visual>
  <collision>
    <origin xyz="-0.232746 -0.369216 -0.806835" rpy="0 0 0"/>
    <geometry>
    <mesh filename="${MeshPath}/leg2_link3.stl" scale="0.001 0.001 0.001"/>
    </geometry>
  </collision>
</link>

<link name="leg2_link4">
  <inertial>
    <origin xyz="0.09079220711784809 0.024871990572491454 -0.13109970320351128" rpy="0 0 0"/>
    <mass value="4.41"/>
    <inertia ixx="0.034485" iyy="0.070051" izz="0.044556" ixy="-0.00581" iyz="0.004973" ixz="0.030887"/>
  </inertial>
  <visual>
    <origin xyz="0.037193 -0.651157 -0.965109" rpy="0 0 0"/>
    <geometry>
    <mesh filename="${MeshPath}/leg2_link4.stl" scale="0.001 0.001 0.001"/>
    </geometry>
    <material name="silver"/>
  </visual>
  <collision>
    <origin xyz="0.037193 -0.651157 -0.965109" rpy="0 0 0"/>
    <geometry>
    <mesh filename="${MeshPath}/leg2_link4.stl" scale="0.001 0.001 0.001"/>
    </geometry>
  </collision>
</link>

<link name="leg2_link5">
  <inertial>
    <origin xyz="0.03670202197624206 0.008154373381178082 -0.025647170522605456" rpy="0 0 0"/>
    <mass value="1.93"/>
    <inertia ixx="0.004136" iyy="0.00469" izz="0.004244" ixy="-0.00043" iyz="0.000269" ixz="0.000235"/>
  </inertial>
  <visual>
    <origin xyz="-0.261015 -0.706301 -0.672808" rpy="0 0 0"/>
    <geometry>
    <mesh filename="${MeshPath}/leg2_link5.stl" scale="0.001 0.001 0.001"/>
    </geometry>
    <material name="silver"/>
  </visual>
  <collision>
    <origin xyz="-0.261015 -0.706301 -0.672808" rpy="0 0 0"/>
    <geometry>
    <mesh filename="${MeshPath}/leg2_link5.stl" scale="0.001 0.001 0.001"/>
    </geometry>
  </collision>
</link>

<link name="leg2_link6">
  <inertial>
    <origin xyz="-0.007647021479467497 0.059019447775768175 -0.07306313294986089" rpy="0 0 0"/>
    <mass value="2.28"/>
    <inertia ixx="0.025979" iyy="0.025623" izz="0.011186" ixy="4.3e-05" iyz="0.003326" ixz="-0.000433"/>
  </inertial>
  <visual>
    <origin xyz="-0.313233 -0.778594 -0.631" rpy="0 0 0"/>
    <geometry>
    <mesh filename="${MeshPath}/leg2_link6.stl" scale="0.001 0.001 0.001"/>
    </geometry>
    <material name="silver"/>
  </visual>
  <collision>
    <origin xyz="-0.313233 -0.778594 -0.631" rpy="0 0 0"/>
    <geometry>
    <mesh filename="${MeshPath}/leg2_link6.stl" scale="0.001 0.001 0.001"/>
    </geometry>
  </collision>
</link>

<link name="leg2_wheel_body">
  <inertial>
    <origin xyz="-0.012120027900981878 -1.7479052738744727e-05 -0.19329958135816877" rpy="0 0 0"/>
    <mass value="22.474559913"/>
    <inertia ixx="1.323182" iyy="0.424785" izz="1.091213" ixy="-0.000411" iyz="9.8e-05" ixz="-0.007297"/>
  </inertial>
  <visual>
    <origin xyz="-0.304 -0.85 -0.468" rpy="0 0 0"/>
    <geometry>
    <mesh filename="${MeshPath}/leg2_wheel_body.stl" scale="0.001 0.001 0.001"/>
    </geometry>
    <material name="silver"/>
  </visual>
  <collision>
    <origin xyz="-0.304 -0.85 -0.468" rpy="0 0 0"/>
    <geometry>
    <mesh filename="${MeshPath}/leg2_wheel_body.stl" scale="0.001 0.001 0.001"/>
    </geometry>
  </collision>
</link>

<link name="leg2_wheel_right">
  <inertial>
    <origin xyz="-6.058317168544658e-06 0.07940029669969473 3.75065892350146e-05" rpy="0 0 0"/>
    <mass value="13.05952777"/>
    <inertia ixx="0.555729" iyy="0.956604" izz="0.555876" ixy="-9e-06" iyz="5.8e-05" ixz="-2.5e-05"/>
  </inertial>
  <visual>
    <origin xyz="-0.3 -0.573 -0.255" rpy="0 0 0"/>
    <geometry>
    <mesh filename="${MeshPath}/leg2_wheel_right.stl" scale="0.001 0.001 0.001"/>
    </geometry>
    <material name="silver"/>
  </visual>
  <collision>
    <origin xyz="-0.3 -0.573 -0.255" rpy="0 0 0"/>
    <geometry>
    <mesh filename="${MeshPath}/leg2_wheel_right.stl" scale="0.001 0.001 0.001"/>
    </geometry>
  </collision>
</link>

<link name="leg2_wheel_left">
  <inertial>
    <origin xyz="6.0583171643258105e-06 -0.07940029669969251 3.750658923368233e-05" rpy="0 0 0"/>
    <mass value="13.05952777"/>
    <inertia ixx="0.555729" iyy="0.956604" izz="0.555876" ixy="-9e-06" iyz="-5.8e-05" ixz="2.5e-05"/>
  </inertial>
  <visual>
    <origin xyz="-0.3 -1.127 -0.255" rpy="0 0 0"/>
    <geometry>
    <mesh filename="${MeshPath}/leg2_wheel_left.stl" scale="0.001 0.001 0.001"/>
    </geometry>
    <material name="silver"/>
  </visual>
  <collision>
    <origin xyz="-0.3 -1.127 -0.255" rpy="0 0 0"/>
    <geometry>
    <mesh filename="${MeshPath}/leg2_wheel_left.stl" scale="0.001 0.001 0.001"/>
    </geometry>
  </collision>
</link>

<link name="gripper_left">
  <inertial>
    <origin xyz="0.012751166622106791 0.03776211993028429 0.013137171710661422" rpy="0 0 0"/>
    <mass value="0.64"/>
    <inertia ixx="0.003003" iyy="0.001889" izz="0.003269" ixy="0.000749" iyz="0.000441" ixz="-0.000329"/>
  </inertial>
  <visual>
    <origin xyz="-0.30221 -0.061073 -1.17562" rpy="0 0 0"/>
    <geometry>
    <mesh filename="${MeshPath}/gripper_left.stl" scale="0.001 0.001 0.001"/>
    </geometry>
    <material name="silver"/>
  </visual>
  <collision>
    <origin xyz="-0.30221 -0.061073 -1.17562" rpy="0 0 0"/>
    <geometry>
    <mesh filename="${MeshPath}/gripper_left.stl" scale="0.001 0.001 0.001"/>
    </geometry>
  </collision>
</link>

<link name="gripper_right">
  <inertial>
    <origin xyz="0.012997166627646273 -0.03637527045613584 -0.0160170293378894" rpy="0 0 0"/>
    <mass value="0.635"/>
    <inertia ixx="0.003281" iyy="0.00177" izz="0.003128" ixy="-0.000492" iyz="0.000615" ixz="0.00029"/>
  </inertial>
  <visual>
    <origin xyz="-0.2992 -0.231658 -1.22349" rpy="0 0 0"/>
    <geometry>
    <mesh filename="${MeshPath}/gripper_right.stl" scale="0.001 0.001 0.001"/>
    </geometry>
    <material name="silver"/>
  </visual>
  <collision>
    <origin xyz="-0.2992 -0.231658 -1.22349" rpy="0 0 0"/>
    <geometry>
    <mesh filename="${MeshPath}/gripper_right.stl" scale="0.001 0.001 0.001"/>
    </geometry>
  </collision>
</link>

<link name="arm_link6">
  <inertial>
    <origin xyz="0.06852764878940026 0.06235167253009892 -0.017206817335685853" rpy="0 0 0"/>
    <mass value="2.28"/>
    <inertia ixx="0.011859" iyy="0.025261" izz="0.025668" ixy="-0.003978" iyz="0.000539" ixz="0.002151"/>
  </inertial>
  <visual>
    <origin xyz="-0.093672 -0.06471 -1.234706" rpy="0 0 0"/>
    <geometry>
    <mesh filename="${MeshPath}/arm_link6.stl" scale="0.001 0.001 0.001"/>
    </geometry>
    <material name="silver"/>
  </visual>
  <collision>
    <origin xyz="-0.093672 -0.06471 -1.234706" rpy="0 0 0"/>
    <geometry>
    <mesh filename="${MeshPath}/arm_link6.stl" scale="0.001 0.001 0.001"/>
    </geometry>
  </collision>
</link>

<link name="arm_link5">
  <inertial>
    <origin xyz="0.04480479430685359 0.005589887036902299 -0.005713272193241137" rpy="0 0 0"/>
    <mass value="1.93"/>
    <inertia ixx="0.003919" iyy="0.004738" izz="0.004413" ixy="-0.000461" iyz="1e-06" ixz="0.000127"/>
  </inertial>
  <visual>
    <origin xyz="-0.024577 0.003106 -1.252817" rpy="0 0 0"/>
    <geometry>
    <mesh filename="${MeshPath}/arm_link5.stl" scale="0.001 0.001 0.001"/>
    </geometry>
    <material name="silver"/>
  </visual>
  <collision>
    <origin xyz="-0.024577 0.003106 -1.252817" rpy="0 0 0"/>
    <geometry>
    <mesh filename="${MeshPath}/arm_link5.stl" scale="0.001 0.001 0.001"/>
    </geometry>
  </collision>
</link>

<link name="gripper_palm">
  <inertial>
    <origin xyz="0.029191998422740617 0.0010874210394583583 -0.0033595806330810607" rpy="0 0 0"/>
    <mass value="0.946"/>
    <inertia ixx="0.009624" iyy="0.002505" izz="0.008499" ixy="0.000368" iyz="5.6e-05" ixz="-0.000137"/>
  </inertial>
  <visual>
    <origin xyz="-0.250602 -0.143856 -1.205349" rpy="0 0 0"/>
    <geometry>
    <mesh filename="${MeshPath}/gripper_palm.stl" scale="0.001 0.001 0.001"/>
    </geometry>
    <material name="silver"/>
  </visual>
  <collision>
    <origin xyz="-0.250602 -0.143856 -1.205349" rpy="0 0 0"/>
    <geometry>
    <mesh filename="${MeshPath}/gripper_palm.stl" scale="0.001 0.001 0.001"/>
    </geometry>
  </collision>
</link>

<link name="leg1_link1">
  <inertial>
    <origin xyz="0.03721629760491804 -0.08120898921849837 -0.009263919945124433" rpy="0 0 0"/>
    <mass value="2.28"/>
    <inertia ixx="0.024103" iyy="0.0129" izz="0.025786" ixy="0.005213" iyz="-0.00225" ixz="0.001088"/>
  </inertial>
  <visual>
    <origin xyz="-0.125648 0.221328 -0.65405" rpy="0 0 0"/>
    <geometry>
    <mesh filename="${MeshPath}/leg1_link1.stl" scale="0.001 0.001 0.001"/>
    </geometry>
    <material name="silver"/>
  </visual>
  <collision>
    <origin xyz="-0.125648 0.221328 -0.65405" rpy="0 0 0"/>
    <geometry>
    <mesh filename="${MeshPath}/leg1_link1.stl" scale="0.001 0.001 0.001"/>
    </geometry>
  </collision>
</link>

<link name="leg1_link2">
  <inertial>
    <origin xyz="-0.0510267460100247 -0.03584657947421027 -0.026963850635775666" rpy="0 0 0"/>
    <mass value="1.93"/>
    <inertia ixx="0.004125" iyy="0.004156" izz="0.004788" ixy="-0.000296" iyz="0.000217" ixz="0.000351"/>
  </inertial>
  <visual>
    <origin xyz="-0.164893 0.385732 -0.600577" rpy="0 0 0"/>
    <geometry>
    <mesh filename="${MeshPath}/leg1_link2.stl" scale="0.001 0.001 0.001"/>
    </geometry>
    <material name="silver"/>
  </visual>
  <collision>
    <origin xyz="-0.164893 0.385732 -0.600577" rpy="0 0 0"/>
    <geometry>
    <mesh filename="${MeshPath}/leg1_link2.stl" scale="0.001 0.001 0.001"/>
    </geometry>
  </collision>
</link>

<link name="leg1_link3">
  <inertial>
    <origin xyz="-0.12933638092881636 -0.14062978291091005 0.18280815636771985" rpy="0 0 0"/>
    <mass value="4.82"/>
    <inertia ixx="0.057802" iyy="0.053057" izz="0.038233" ixy="-0.01531" iyz="0.02421" ixz="0.020587"/>
  </inertial>
  <visual>
    <origin xyz="-0.087662 0.446857 -0.60092" rpy="0 0 0"/>
    <geometry>
    <mesh filename="${MeshPath}/leg1_link3.stl" scale="0.001 0.001 0.001"/>
    </geometry>
    <material name="silver"/>
  </visual>
  <collision>
    <origin xyz="-0.087662 0.446857 -0.60092" rpy="0 0 0"/>
    <geometry>
    <mesh filename="${MeshPath}/leg1_link3.stl" scale="0.001 0.001 0.001"/>
    </geometry>
  </collision>
</link>

<link name="leg1_link4">
  <inertial>
    <origin xyz="0.12548337123420072 -0.0759118875774738 -0.06738189799315408" rpy="0 0 0"/>
    <mass value="4.41"/>
    <inertia ixx="0.047032" iyy="0.055292" izz="0.046768" ixy="0.019348" iyz="-0.019468" ixz="0.023911"/>
  </inertial>
  <visual>
    <origin xyz="0.077814 0.668584 -0.91851" rpy="0 0 0"/>
    <geometry>
    <mesh filename="${MeshPath}/leg1_link4.stl" scale="0.001 0.001 0.001"/>
    </geometry>
    <material name="silver"/>
  </visual>
  <collision>
    <origin xyz="0.077814 0.668584 -0.91851" rpy="0 0 0"/>
    <geometry>
    <mesh filename="${MeshPath}/leg1_link4.stl" scale="0.001 0.001 0.001"/>
    </geometry>
  </collision>
</link>

<link name="leg1_link5">
  <inertial>
    <origin xyz="0.026628837215497636 -0.020102352624377207 -0.03095376876756195" rpy="0 0 0"/>
    <mass value="1.93"/>
    <inertia ixx="0.004124" iyy="0.004785" izz="0.00416" ixy="0.000311" iyz="1.5e-05" ixz="0.000404"/>
  </inertial>
  <visual>
    <origin xyz="-0.200925 0.876059 -0.680461" rpy="0 0 0"/>
    <geometry>
    <mesh filename="${MeshPath}/leg1_link5.stl" scale="0.001 0.001 0.001"/>
    </geometry>
    <material name="silver"/>
  </visual>
  <collision>
    <origin xyz="-0.200925 0.876059 -0.680461" rpy="0 0 0"/>
    <geometry>
    <mesh filename="${MeshPath}/leg1_link5.stl" scale="0.001 0.001 0.001"/>
    </geometry>
  </collision>
</link>

<link name="leg1_link6">
  <inertial>
    <origin xyz="0.0404718293184434 0.043632126765362655 -0.07306313294985844" rpy="0 0 0"/>
    <mass value="2.28"/>
    <inertia ixx="0.025811" iyy="0.025791" izz="0.011186" ixy="-0.000183" iyz="0.00246" ixz="0.00228"/>
  </inertial>
  <visual>
    <origin xyz="-0.284815 0.865236 -0.63" rpy="0 0 0"/>
    <geometry>
    <mesh filename="${MeshPath}/leg1_link6.stl" scale="0.001 0.001 0.001"/>
    </geometry>
    <material name="silver"/>
  </visual>
  <collision>
    <origin xyz="-0.284815 0.865236 -0.63" rpy="0 0 0"/>
    <geometry>
    <mesh filename="${MeshPath}/leg1_link6.stl" scale="0.001 0.001 0.001"/>
    </geometry>
  </collision>
</link>

<link name="leg1_wheel_body">
  <inertial>
    <origin xyz="-0.012119860673827865 -6.756303660193641e-05 -0.19329958135816605" rpy="0 0 0"/>
    <mass value="22.474559913"/>
    <inertia ixx="1.32317" iyy="0.424797" izz="1.091213" ixy="0.003281" iyz="6.8e-05" ixz="-0.007298"/>
  </inertial>
  <visual>
    <origin xyz="-0.333793 0.812461 -0.468" rpy="0 0 0"/>
    <geometry>
    <mesh filename="${MeshPath}/leg1_wheel_body.stl" scale="0.001 0.001 0.001"/>
    </geometry>
    <material name="silver"/>
  </visual>
  <collision>
    <origin xyz="-0.333793 0.812461 -0.468" rpy="0 0 0"/>
    <geometry>
    <mesh filename="${MeshPath}/leg1_wheel_body.stl" scale="0.001 0.001 0.001"/>
    </geometry>
  </collision>
</link>

<link name="leg1_wheel_left">
  <inertial>
    <origin xyz="0.00033194674213743447 -0.07939965142951666 3.7506589236790955e-05" rpy="0 0 0"/>
    <mass value="13.05952777"/>
    <inertia ixx="0.555736" iyy="0.956597" izz="0.555876" ixy="-0.001657" iyz="-5.8e-05" ixz="2.5e-05"/>
  </inertial>
  <visual>
    <origin xyz="-0.328655 0.53548 -0.255" rpy="0 0 0"/>
    <geometry>
    <mesh filename="${MeshPath}/leg1_wheel_left.stl" scale="0.001 0.001 0.001"/>
    </geometry>
    <material name="silver"/>
  </visual>
  <collision>
    <origin xyz="-0.328655 0.53548 -0.255" rpy="0 0 0"/>
    <geometry>
    <mesh filename="${MeshPath}/leg1_wheel_left.stl" scale="0.001 0.001 0.001"/>
    </geometry>
  </collision>
</link>

<link name="leg1_wheel_right">
  <inertial>
    <origin xyz="-0.00033289313237505613 0.07939923008749572 3.7506589237013e-05" rpy="0 0 0"/>
    <mass value="13.05952777"/>
    <inertia ixx="0.555736" iyy="0.956597" izz="0.555876" ixy="-0.001657" iyz="5.8e-05" ixz="-2.5e-05"/>
  </inertial>
  <visual>
    <origin xyz="-0.330932 1.089475 -0.255" rpy="0 0 0"/>
    <geometry>
    <mesh filename="${MeshPath}/leg1_wheel_right.stl" scale="0.001 0.001 0.001"/>
    </geometry>
    <material name="silver"/>
  </visual>
  <collision>
    <origin xyz="-0.330932 1.089475 -0.255" rpy="0 0 0"/>
    <geometry>
    <mesh filename="${MeshPath}/leg1_wheel_right.stl" scale="0.001 0.001 0.001"/>
    </geometry>
  </collision>
</link>

<link name="leg3_link5">
  <inertial>
    <origin xyz="-0.021159945005317593 0.0007091330235086957 -0.04028686396790482" rpy="0 0 0"/>
    <mass value="1.93"/>
    <inertia ixx="0.004265" iyy="0.004831" izz="0.003975" ixy="0.000126" iyz="0.000339" ixz="-0.000279"/>
  </inertial>
  <visual>
    <origin xyz="0.852872 0.131589 -0.695691" rpy="0 0 0"/>
    <geometry>
    <mesh filename="${MeshPath}/leg3_link5.stl" scale="0.001 0.001 0.001"/>
    </geometry>
    <material name="silver"/>
  </visual>
  <collision>
    <origin xyz="0.852872 0.131589 -0.695691" rpy="0 0 0"/>
    <geometry>
    <mesh filename="${MeshPath}/leg3_link5.stl" scale="0.001 0.001 0.001"/>
    </geometry>
  </collision>
</link>

<link name="leg3_link6">
  <inertial>
    <origin xyz="-0.007545433439614002 0.05903172498691736 -0.07306313294986044" rpy="0 0 0"/>
    <mass value="2.28"/>
    <inertia ixx="0.025979" iyy="0.025623" izz="0.011186" ixy="4.3e-05" iyz="0.003327" ixz="-0.000427"/>
  </inertial>
  <visual>
    <origin xyz="0.89489 0.071421 -0.63" rpy="0 0 0"/>
    <geometry>
    <mesh filename="${MeshPath}/leg3_link6.stl" scale="0.001 0.001 0.001"/>
    </geometry>
    <material name="silver"/>
  </visual>
  <collision>
    <origin xyz="0.89489 0.071421 -0.63" rpy="0 0 0"/>
    <geometry>
    <mesh filename="${MeshPath}/leg3_link6.stl" scale="0.001 0.001 0.001"/>
    </geometry>
  </collision>
</link>

<link name="leg3_wheel_body">
  <inertial>
    <origin xyz="0.012120027900982211 1.7479052741112008e-05 -0.1932995813581685" rpy="0 0 0"/>
    <mass value="22.474559913"/>
    <inertia ixx="1.323182" iyy="0.424785" izz="1.091213" ixy="-0.000411" iyz="-9.8e-05" ixz="0.007297"/>
  </inertial>
  <visual>
    <origin xyz="0.904 0.0 -0.468" rpy="0 0 0"/>
    <geometry>
    <mesh filename="${MeshPath}/leg3_wheel_body.stl" scale="0.001 0.001 0.001"/>
    </geometry>
    <material name="silver"/>
  </visual>
  <collision>
    <origin xyz="0.904 0.0 -0.468" rpy="0 0 0"/>
    <geometry>
    <mesh filename="${MeshPath}/leg3_wheel_body.stl" scale="0.001 0.001 0.001"/>
    </geometry>
  </collision>
</link>

<link name="leg3_wheel_left">
  <inertial>
    <origin xyz="6.05831716671279e-06 -0.07940029669969395 3.7506589234848065e-05" rpy="0 0 0"/>
    <mass value="13.05952777"/>
    <inertia ixx="0.555729" iyy="0.956604" izz="0.555876" ixy="-9e-06" iyz="-5.8e-05" ixz="2.5e-05"/>
  </inertial>
  <visual>
    <origin xyz="0.9 -0.277 -0.255" rpy="0 0 0"/>
    <geometry>
    <mesh filename="${MeshPath}/leg3_wheel_left.stl" scale="0.001 0.001 0.001"/>
    </geometry>
    <material name="silver"/>
  </visual>
  <collision>
    <origin xyz="0.9 -0.277 -0.255" rpy="0 0 0"/>
    <geometry>
    <mesh filename="${MeshPath}/leg3_wheel_left.stl" scale="0.001 0.001 0.001"/>
    </geometry>
  </collision>
</link>

<link name="leg3_link1">
  <inertial>
    <origin xyz="-0.08893686705016807 0.012060596527737385 0.003237902911888413" rpy="0 0 0"/>
    <mass value="2.28"/>
    <inertia ixx="0.011186" iyy="0.025644" izz="0.025958" ixy="0.003241" iyz="-9.4e-05" ixz="0.000863"/>
  </inertial>
  <visual>
    <origin xyz="0.2545 -0.00185 -0.65385" rpy="0 0 0"/>
    <geometry>
    <mesh filename="${MeshPath}/leg3_link1.stl" scale="0.001 0.001 0.001"/>
    </geometry>
    <material name="silver"/>
  </visual>
  <collision>
    <origin xyz="0.2545 -0.00185 -0.65385" rpy="0 0 0"/>
    <geometry>
    <mesh filename="${MeshPath}/leg3_link1.stl" scale="0.001 0.001 0.001"/>
    </geometry>
  </collision>
</link>

<link name="leg3_link4">
  <inertial>
    <origin xyz="-0.0543492893914449 -0.06375843043692528 -0.13794993786572363" rpy="0 0 0"/>
    <mass value="4.41"/>
    <inertia ixx="0.059274" iyy="0.069296" izz="0.020522" ixy="-0.004182" iyz="-0.008787" ixz="-0.024297"/>
  </inertial>
  <visual>
    <origin xyz="0.6818 0.037995 -1.069033" rpy="0 0 0"/>
    <geometry>
    <mesh filename="${MeshPath}/leg3_link4.stl" scale="0.001 0.001 0.001"/>
    </geometry>
    <material name="silver"/>
  </visual>
  <collision>
    <origin xyz="0.6818 0.037995 -1.069033" rpy="0 0 0"/>
    <geometry>
    <mesh filename="${MeshPath}/leg3_link4.stl" scale="0.001 0.001 0.001"/>
    </geometry>
  </collision>
</link>

<link name="leg3_link2">
  <inertial>
    <origin xyz="-0.016598546111078694 0.05351668877675589 0.038421200084355234" rpy="0 0 0"/>
    <mass value="1.93"/>
    <inertia ixx="0.004234" iyy="0.004911" izz="0.003926" ixy="0.000165" iyz="-0.00011" ixz="0.000324"/>
  </inertial>
  <visual>
    <origin xyz="0.4165 -0.071411 -0.672432" rpy="0 0 0"/>
    <geometry>
    <mesh filename="${MeshPath}/leg3_link2.stl" scale="0.001 0.001 0.001"/>
    </geometry>
    <material name="silver"/>
  </visual>
  <collision>
    <origin xyz="0.4165 -0.071411 -0.672432" rpy="0 0 0"/>
    <geometry>
    <mesh filename="${MeshPath}/leg3_link2.stl" scale="0.001 0.001 0.001"/>
    </geometry>
  </collision>
</link>

<link name="leg3_link3">
  <inertial>
    <origin xyz="-0.1493496630860232 -0.06994867670473875 0.20670145689675534" rpy="0 0 0"/>
    <mass value="4.82"/>
    <inertia ixx="0.051597" iyy="0.06486" izz="0.032635" ixy="-0.010705" iyz="0.01511" ixz="0.027264"/>
  </inertial>
  <visual>
    <origin xyz="0.45944 -0.118655 -0.747433" rpy="0 0 0"/>
    <geometry>
    <mesh filename="${MeshPath}/leg3_link3.stl" scale="0.001 0.001 0.001"/>
    </geometry>
    <material name="silver"/>
  </visual>
  <collision>
    <origin xyz="0.45944 -0.118655 -0.747433" rpy="0 0 0"/>
    <geometry>
    <mesh filename="${MeshPath}/leg3_link3.stl" scale="0.001 0.001 0.001"/>
    </geometry>
  </collision>
</link>

<link name="leg3_wheel_right">
  <inertial>
    <origin xyz="-6.058317166268701e-06 0.07940029669969395 3.7506589234348464e-05" rpy="0 0 0"/>
    <mass value="13.05952777"/>
    <inertia ixx="0.555729" iyy="0.956604" izz="0.555876" ixy="-9e-06" iyz="5.8e-05" ixz="-2.5e-05"/>
  </inertial>
  <visual>
    <origin xyz="0.9 0.277 -0.255" rpy="0 0 0"/>
    <geometry>
    <mesh filename="${MeshPath}/leg3_wheel_right.stl" scale="0.001 0.001 0.001"/>
    </geometry>
    <material name="silver"/>
  </visual>
  <collision>
    <origin xyz="0.9 0.277 -0.255" rpy="0 0 0"/>
    <geometry>
    <mesh filename="${MeshPath}/leg3_wheel_right.stl" scale="0.001 0.001 0.001"/>
    </geometry>
  </collision>
</link>

<link name="arm_realsense">
  <inertial>
    <origin xyz="0.0029278816903696714 0.0002785230319259091 0.012194601527297122" rpy="0 0 0"/>
    <mass value="0.3783774808035141"/>
    <inertia ixx="0.000237" iyy="3.6e-05" izz="0.00024" ixy="1e-05" iyz="2e-06" ixz="0.0"/>
  </inertial>
  <visual>
    <origin xyz="-0.283116 -0.145079 -1.246394" rpy="0 0 0"/>
    <geometry>
    <mesh filename="${MeshPath}/arm_realsense.stl" scale="0.001 0.001 0.001"/>
    </geometry>
    <material name="silver"/>
  </visual>
  <collision>
    <origin xyz="-0.283116 -0.145079 -1.246394" rpy="0 0 0"/>
    <geometry>
    <mesh filename="${MeshPath}/arm_realsense.stl" scale="0.001 0.001 0.001"/>
    </geometry>
  </collision>
</link>

<link name="body_realsense">
  <inertial>
    <origin xyz="-0.011479830691674173 -5.29927122015317e-07 -0.5075482000765336" rpy="0 0 0"/>
    <mass value="0.3783774808035141"/>
    <inertia ixx="0.000238" iyy="3.5e-05" izz="0.00024" ixy="-0.0" iyz="0.0" ixz="0.0"/>
  </inertial>
  <visual>
    <origin xyz="-0.1245 -0.0 -1.232" rpy="0 0 0"/>
    <geometry>
    <mesh filename="${MeshPath}/body_realsense.stl" scale="0.001 0.001 0.001"/>
    </geometry>
    <material name="silver"/>
  </visual>
  <collision>
    <origin xyz="-0.1245 -0.0 -1.232" rpy="0 0 0"/>
    <geometry>
    <mesh filename="${MeshPath}/body_realsense.stl" scale="0.001 0.001 0.001"/>
    </geometry>
  </collision>
</link>

<joint name="arm_joint1" type="continuous">
  <origin xyz="-0.00285 0.00025 1.362" rpy="0 0 0"/>
  <parent link="base_link"/>
  <child link="arm_link1"/>
  <axis xyz="-0.0 0.0 1.0"/>
</joint>

<joint name="arm_joint2" type="continuous">
  <origin xyz="-0.004491 0.07186 -0.363" rpy="0 0 0"/>
  <parent link="arm_link1"/>
  <child link="arm_link2"/>
  <axis xyz="0.062374 -0.998053 -0.0"/>
</joint>

<joint name="arm_joint3" type="continuous">
  <origin xyz="-0.061913 0.061257 0.045992" rpy="0 0 0"/>
  <parent link="arm_link2"/>
  <child link="arm_link3"/>
  <axis xyz="-0.781873 -0.048864 0.62152"/>
</joint>

<joint name="arm_joint4" type="continuous">
  <origin xyz="-0.321363 -0.085193 0.256746" rpy="0 0 0"/>
  <parent link="arm_link3"/>
  <child link="arm_link4"/>
  <axis xyz="-0.047917 0.998685 0.018237"/>
</joint>

<joint name="leg2_joint1" type="continuous">
  <origin xyz="0.12795 0.217916 0.65335" rpy="0 0 0"/>
  <parent link="base_link"/>
  <child link="leg2_link1"/>
  <axis xyz="-0.5 -0.866025 0.0"/>
    <limit
      lower="-1"
      upper="1"
      effort="0"
      velocity="0" />
</joint>

<joint name="leg2_joint2" type="continuous">
  <origin xyz="0.114924 0.12071 0.060411" rpy="0 0 0"/>
  <parent link="leg2_link1"/>
  <child link="leg2_link2"/>
  <axis xyz="-0.471167 0.272028 -0.839049"/>
    <limit
      lower="-1"
      upper="1"
      effort="0"
      velocity="0" />
</joint>

<joint name="leg2_joint3" type="continuous">
  <origin xyz="-0.010128 0.03059 0.093074" rpy="0 0 0"/>
  <parent link="leg2_link2"/>
  <child link="leg2_link3"/>
  <axis xyz="-0.550734 0.652313 0.52075"/>
</joint>

<joint name="leg2_joint4" type="continuous">
  <origin xyz="-0.269939 0.281941 0.158274" rpy="0 0 0"/>
  <parent link="leg2_link3"/>
  <child link="leg2_link4"/>
  <axis xyz="-0.574788 0.156 -0.803295"/>
    <limit
      lower="-1"
      upper="1"
      effort="0"
      velocity="0" />
</joint>

<joint name="leg2_joint5" type="continuous">
  <origin xyz="0.298208 0.055144 -0.292301" rpy="0 0 0"/>
  <parent link="leg2_link4"/>
  <child link="leg2_link5"/>
  <axis xyz="0.818296 0.105811 -0.564974"/>
</joint>

<joint name="leg2_joint6" type="continuous">
  <origin xyz="0.052218 0.072293 -0.041808" rpy="0 0 0"/>
  <parent link="leg2_link5"/>
  <child link="leg2_link6"/>
  <axis xyz="0.128239 -0.991743 0.0"/>
    <limit
      lower="-1"
      upper="1"
      effort="0"
      velocity="0" />
</joint>

<joint name="leg2_steering_joint" type="continuous">
  <origin xyz="-0.009233 0.071406 -0.163" rpy="0 0 0"/>
  <parent link="leg2_link6"/>
  <child link="leg2_wheel_body"/>
  <axis xyz="-0.0 0.0 1.0"/>
</joint>

<joint name="leg2_wheel_right_joint" type="continuous">
  <origin xyz="-0.004 -0.277 -0.213" rpy="0 0 0"/>
  <parent link="leg2_wheel_body"/>
  <child link="leg2_wheel_right"/>
  <axis xyz="0.0 1.0 -0.0"/>
</joint>

<joint name="leg2_wheel_left_joint" type="continuous">
  <origin xyz="-0.004 0.277 -0.213" rpy="0 0 0"/>
  <parent link="leg2_wheel_body"/>
  <child link="leg2_wheel_left"/>
  <axis xyz="-0.0 -1.0 0.0"/>
</joint>

<joint name="finger_left_joint" type="prismatic">
  <origin xyz="0.051608 -0.082783 -0.029729" rpy="0 0 0"/>
  <parent link="gripper_palm"/>
  <child link="gripper_left"/>
  <axis xyz="-0.051245 0.99863 -0.010571"/>
  <limit upper="0.04" lower="0.0" effort="100" velocity="100"/>
</joint>

<joint name="finger_right_joint" type="prismatic">
  <origin xyz="0.048598 0.087802 0.018141" rpy="0 0 0"/>
  <parent link="gripper_palm"/>
  <child link="gripper_right"/>
  <axis xyz="0.051245 -0.99863 0.010571"/>
  <limit upper="0.04" lower="0.0" effort="100" velocity="100"/>
</joint>

<joint name="arm_joint6" type="continuous">
  <origin xyz="0.069095 0.067816 -0.018111" rpy="0 0 0"/>
  <parent link="arm_link5"/>
  <child link="arm_link6"/>
  <axis xyz="-0.066543 0.986741 -0.148032"/>
</joint>

<joint name="arm_joint5" type="continuous">
  <origin xyz="0.415194 -0.05128 -0.048921" rpy="0 0 0"/>
  <parent link="arm_link4"/>
  <child link="arm_link5"/>
  <axis xyz="0.992154 0.049698 -0.114717"/>
</joint>

<joint name="arm_joint7" type="continuous">
  <origin xyz="0.15693 0.079146 -0.029357" rpy="0 0 0"/>
  <parent link="arm_link6"/>
  <child link="gripper_palm"/>
  <axis xyz="0.992154 0.049698 -0.114717"/>
</joint>

<joint name="leg1_joint1" type="continuous">
  <origin xyz="0.125648 -0.221328 0.65405" rpy="0 0 0"/>
  <parent link="base_link"/>
  <child link="leg1_link1"/>
  <axis xyz="0.5 -0.866025 0.0"/>
    <limit
      lower="-1"
      upper="1"
      effort="0"
      velocity="0" />
</joint>

<joint name="leg1_joint2" type="continuous">
  <origin xyz="0.039245 -0.164404 -0.053473" rpy="0 0 0"/>
  <parent link="leg1_link1"/>
  <child link="leg1_link2"/>
  <axis xyz="-0.579931 -0.334823 -0.74268"/>
    <limit
      lower="-1"
      upper="1"
      effort="0"
      velocity="0" />
</joint>

<joint name="leg1_joint3" type="continuous">
  <origin xyz="-0.077231 -0.061125 0.000343" rpy="0 0 0"/>
  <parent link="leg1_link2"/>
  <child link="leg1_link3"/>
  <axis xyz="-0.534266 -0.531908 0.656989"/>
</joint>

<joint name="leg1_joint4" type="continuous">
  <origin xyz="-0.165476 -0.221727 0.31759" rpy="0 0 0"/>
  <parent link="leg1_link3"/>
  <child link="leg1_link4"/>
  <axis xyz="0.781171 -0.013689 0.624168"/>
    <limit
      lower="-1"
      upper="1"
      effort="0"
      velocity="0" />
</joint>

<joint name="leg1_joint5" type="continuous">
  <origin xyz="0.278739 -0.207475 -0.238049" rpy="0 0 0"/>
  <parent link="leg1_link4"/>
  <child link="leg1_link5"/>
  <axis xyz="0.536132 -0.497566 -0.681903"/>
</joint>

<joint name="leg1_joint6" type="continuous">
  <origin xyz="0.08389 0.010823 -0.050461" rpy="0 0 0"/>
  <parent link="leg1_link5"/>
  <child link="leg1_link6"/>
  <axis xyz="0.680252 0.732978 -0.0"/>
    <limit
      lower="-1"
      upper="1"
      effort="0"
      velocity="0" />
</joint>

<joint name="leg1_steering_joint" type="continuous">
  <origin xyz="0.048978 0.052775 -0.162" rpy="0 0 0"/>
  <parent link="leg1_link6"/>
  <child link="leg1_wheel_body"/>
  <axis xyz="0.0 0.0 -1.0"/>
</joint>

<joint name="leg1_wheel_left_joint" type="continuous">
  <origin xyz="-0.005138 0.276981 -0.213" rpy="0 0 0"/>
  <parent link="leg1_wheel_body"/>
  <child link="leg1_wheel_left"/>
  <axis xyz="-0.00411 0.999992 -0.0"/>
</joint>

<joint name="leg1_wheel_right_joint" type="continuous">
  <origin xyz="-0.002861 -0.277014 -0.213" rpy="0 0 0"/>
  <parent link="leg1_wheel_body"/>
  <child link="leg1_wheel_right"/>
  <axis xyz="0.00411 -0.999992 0.0"/>
</joint>

<joint name="leg3_joint5" type="continuous">
  <origin xyz="-0.171072 -0.093594 -0.373342" rpy="0 0 0"/>
  <parent link="leg3_link4"/>
  <child link="leg3_link5"/>
  <axis xyz="-0.456682 -0.05825 -0.887721"/>
</joint>

<joint name="leg3_joint6" type="continuous">
  <origin xyz="-0.042018 0.060168 -0.065691" rpy="0 0 0"/>
  <parent link="leg3_link5"/>
  <child link="leg3_link6"/>
  <axis xyz="-0.126525 0.991963 -0.0"/>
    <limit
      lower="-1"
      upper="1"
      effort="0"
      velocity="0" />
</joint>

<joint name="leg3_steering_joint" type="continuous">
  <origin xyz="-0.00911 0.071421 -0.162" rpy="0 0 0"/>
  <parent link="leg3_link6"/>
  <child link="leg3_wheel_body"/>
  <axis xyz="-0.0 0.0 -1.0"/>
</joint>

<joint name="leg3_wheel_left_joint" type="continuous">
  <origin xyz="0.004 0.277 -0.213" rpy="0 0 0"/>
  <parent link="leg3_wheel_body"/>
  <child link="leg3_wheel_left"/>
  <axis xyz="0.0 1.0 0.0"/>
</joint>

<joint name="leg3_joint1" type="continuous">
  <origin xyz="-0.2545 0.00185 0.65385" rpy="0 0 0"/>
  <parent link="base_link"/>
  <child link="leg3_link1"/>
  <axis xyz="-1.0 -0.0 -0.0"/>
    <limit
      lower="-1"
      upper="1"
      effort="0"
      velocity="0" />
</joint>

<joint name="leg3_joint4" type="continuous">
  <origin xyz="-0.22236 -0.15665 0.3216" rpy="0 0 0"/>
  <parent link="leg3_link3"/>
  <child link="leg3_link4"/>
  <axis xyz="0.25627 -0.96417 -0.068571"/>
    <limit
      lower="-1"
      upper="1"
      effort="0"
      velocity="0" />
</joint>
<!--1246-->
<joint name="leg3_joint2" type="continuous">
  <origin xyz="-0.162 0.069561 0.018582" rpy="0 0 0"/>
  <parent link="leg3_link1"/>
  <child link="leg3_link2"/>
  <axis xyz="-0.0 0.966122 0.258084"/>
    <limit
      lower="-1"
      upper="1"
      effort="0"
      velocity="0" />
</joint>

<joint name="leg3_joint3" type="continuous">
  <origin xyz="-0.04294 0.047244 0.075001" rpy="0 0 0"/>
  <parent link="leg3_link2"/>
  <child link="leg3_link3"/>
  <axis xyz="-0.580269 -0.21019 0.786834"/>
</joint>

<joint name="leg3_wheel_right_joint" type="continuous">
  <origin xyz="0.004 -0.277 -0.213" rpy="0 0 0"/>
  <parent link="leg3_wheel_body"/>
  <child link="leg3_wheel_right"/>
  <axis xyz="-0.0 -1.0 -0.0"/>
</joint>

<joint name="arm_realsense_joint" type="fixed">
  <origin xyz="0.032514 0.001223 0.041045" rpy="0 0 0"/>
  <parent link="gripper_palm"/>
  <child link="arm_realsense"/>
</joint>

<joint name="body_realsense_joint" type="fixed">
  <origin xyz="0.1245 0.0 1.232" rpy="0 0 0"/>
  <parent link="base_link"/>
  <child link="body_realsense"/>
</joint>

</robot>
