<?xml version="1.0" encoding="utf-8"?>
<!-- This URDF was automatically created by SolidWorks to URDF Exporter! Originally created by Stephen Brawner (brawner@gmail.com) 
     Commit Version: 1.6.0-4-g7f85cfe  Build Version: 1.6.7995.38578
     For more information, please see http://wiki.ros.org/sw_urdf_exporter -->
<robot
  name="scar-e">
  <link
    name="base_link">
    <visual>
      <origin
        xyz="0 0 0"
        rpy="0 0 0" />
      <geometry>
        <mesh
          filename="package://rviz_custom/base_link.STL" />
      </geometry>
      <material
        name="">
        <color
          rgba="0.41 0.41 0.41 1" />
      </material>
    </visual>
    <collision>
      <origin
        xyz="0 0 0"
        rpy="0 0 0" />
      <geometry>
        <mesh
          filename="package://rviz_custom/base_link.STL" />
      </geometry>
    </collision>
  </link>
  <link
    name="link1_1">
    <inertial>
      <origin
        xyz="0.089259 5.1834E-09 3.1662E-09"
        rpy="0 0 0" />
      <mass
        value="0.3223" />
      <inertia
        ixx="0.00010343"
        ixy="7.4467E-11"
        ixz="6.013E-11"
        iyy="0.00093847"
        iyz="4.4743E-09"
        izz="0.00095543" />
    </inertial>
    <visual>
      <origin
        xyz="0 0 0"
        rpy="0 0 0" />
      <geometry>
        <mesh
          filename="package://rviz_custom/link1_1.STL" />
      </geometry>
      <material
        name="">
        <color
          rgba="0.91 0.35 0.05 1" />
      </material>
    </visual>
    <collision>
      <origin
        xyz="0 0 0"
        rpy="0 0 0" />
      <geometry>
        <mesh
          filename="package://rviz_custom/link1_1.STL" />
      </geometry>
    </collision>
  </link>
  <joint
    name="joint1_1"
    type="revolute">
    <origin
      xyz="0.185 0 0"
      rpy="1.5707963267949 0 0" />
    <parent
      link="base_link" />
    <child
      link="link1_1" />
    <axis
      xyz="0 1 0" />
    <limit
      lower="-1.0472"
      upper="1.0472"
      effort="0"
      velocity="0" />
  </joint>
  <link
    name="link1_2">
    <inertial>
      <origin
        xyz="0.10174 2.7929E-09 4.423E-09"
        rpy="0 0 0" />
      <mass
        value="0.37139" />
      <inertia
        ixx="0.00011877"
        ixy="5.7476E-11"
        ixz="9.2364E-11"
        iyy="0.0013657"
        iyz="4.008E-10"
        izz="0.0013647" />
    </inertial>
    <visual>
      <origin
        xyz="0 0 0"
        rpy="0 0 0" />
      <geometry>
        <mesh
          filename="package://rviz_custom/link1_2.STL" />
      </geometry>
      <material
        name="">
        <color
          rgba="0.91 0.35 0.05 1" />
      </material>
    </visual>
    <collision>
      <origin
        xyz="0 0 0"
        rpy="0 0 0" />
      <geometry>
        <mesh
          filename="package://rviz_custom/link1_2.STL" />
      </geometry>
    </collision>
  </link>
  <joint
    name="joint1_2"
    type="revolute">
    <origin
      xyz="0.165 0 0"
      rpy="0 0 0" />
    <parent
      link="link1_1" />
    <child
      link="link1_2" />
    <axis
      xyz="0 0 1" />
    <limit
      lower="-1.5708"
      upper="1.5708"
      effort="0"
      velocity="0" />
  </joint>
  <link
    name="link1_3">
    <inertial>
      <origin
        xyz="0.10215 2.5776E-09 4.313E-09"
        rpy="0 0 0" />
      <mass
        value="0.37887" />
      <inertia
        ixx="0.00012589"
        ixy="6.4681E-11"
        ixz="9.4829E-11"
        iyy="0.001345"
        iyz="-2.3662E-09"
        izz="0.0013361" />
    </inertial>
    <visual>
      <origin
        xyz="0 0 0"
        rpy="0 0 0" />
      <geometry>
        <mesh
          filename="package://rviz_custom/link1_3.STL" />
      </geometry>
      <material
        name="">
        <color
          rgba="0.91 0.35 0.05 1" />
      </material>
    </visual>
    <collision>
      <origin
        xyz="0 0 0"
        rpy="0 0 0" />
      <geometry>
        <mesh
          filename="package://rviz_custom/link1_3.STL" />
      </geometry>
    </collision>
  </link>
  <joint
    name="joint1_3"
    type="revolute">
    <origin
      xyz="0.19 0 0"
      rpy="0 0 0" />
    <parent
      link="link1_2" />
    <child
      link="link1_3" />
    <axis
      xyz="0 0 1" />
    <limit
      lower="-2.0944"
      upper="2.0944"
      effort="0"
      velocity="0" />
  </joint>
  <link
    name="gripper1">
    <inertial>
      <origin
        xyz="0.017821 0.031651 0.040044"
        rpy="0 0 0" />
      <mass
        value="0.093845" />
      <inertia
        ixx="1.1829E-05"
        ixy="-1.324E-21"
        ixz="-2.931E-13"
        iyy="1.5154E-05"
        iyz="-4.6596E-23"
        izz="1.1829E-05" />
    </inertial>
    <visual>
      <origin
        xyz="0 0 0"
        rpy="0 0 0" />
      <geometry>
        <mesh
          filename="package://rviz_custom/gripper1.STL" />
      </geometry>
      <material
        name="">
        <color
          rgba="0.63 0.63 0.63 1" />
      </material>
    </visual>
    <collision>
      <origin
        xyz="0 0 0"
        rpy="0 0 0" />
      <geometry>
        <mesh
          filename="package://rviz_custom/gripper1.STL" />
      </geometry>
    </collision>
  </link>
  <joint
    name="joint1_gripper"
    type="fixed">
    <origin
      xyz="0.195035245684479 0.00799220219191371 -0.0430951710535117"
      rpy="0 -0.235341241860591 -1.5707963267949" />
    <parent
      link="link1_3" />
    <child
      link="gripper1" />
    <axis
      xyz="0 0 0" />
    <limit
      lower="0"
      upper="0"
      effort="0"
      velocity="0" />
  </joint>
  <link
    name="link2_1">
    <inertial>
      <origin
        xyz="0.089259 -1.8043E-08 1.4936E-08"
        rpy="0 0 0" />
      <mass
        value="0.3223" />
      <inertia
        ixx="0.00010343"
        ixy="9.7403E-10"
        ixz="-1.1632E-10"
        iyy="0.00093847"
        iyz="4.2307E-09"
        izz="0.00095543" />
    </inertial>
    <visual>
      <origin
        xyz="0 0 0"
        rpy="0 0 0" />
      <geometry>
        <mesh
          filename="package://rviz_custom/link2_1.STL" />
      </geometry>
      <material
        name="">
        <color
          rgba="0.91 0.35 0.05 1" />
      </material>
    </visual>
    <collision>
      <origin
        xyz="0 0 0"
        rpy="0 0 0" />
      <geometry>
        <mesh
          filename="package://rviz_custom/link2_1.STL" />
      </geometry>
    </collision>
  </link>
  <joint
    name="joint2_1"
    type="revolute">
    <origin
      xyz="0.0924999999999984 0.160214699700122 0"
      rpy="1.5707963267949 0 1.0471975511966" />
    <parent
      link="base_link" />
    <child
      link="link2_1" />
    <axis
      xyz="0 1 0" />
    <limit
      lower="-1.0472"
      upper="1.0472"
      effort="0"
      velocity="0" />
  </joint>
  <link
    name="link2_2">
    <inertial>
      <origin
        xyz="0.10174 -1.732E-10 8.2538E-09"
        rpy="0 0 0" />
      <mass
        value="0.37139" />
      <inertia
        ixx="0.00011877"
        ixy="4.9404E-10"
        ixz="-1.4931E-10"
        iyy="0.0013657"
        iyz="3.9652E-10"
        izz="0.0013647" />
    </inertial>
    <visual>
      <origin
        xyz="0 0 0"
        rpy="0 0 0" />
      <geometry>
        <mesh
          filename="package://rviz_custom/link2_2.STL" />
      </geometry>
      <material
        name="">
        <color
          rgba="0.91 0.35 0.05 1" />
      </material>
    </visual>
    <collision>
      <origin
        xyz="0 0 0"
        rpy="0 0 0" />
      <geometry>
        <mesh
          filename="package://rviz_custom/link2_2.STL" />
      </geometry>
    </collision>
  </link>
  <joint
    name="joint2_2"
    type="revolute">
    <origin
      xyz="0.165 0 0"
      rpy="0 0 0" />
    <parent
      link="link2_1" />
    <child
      link="link2_2" />
    <axis
      xyz="0 0 1" />
    <limit
      lower="-1.5708"
      upper="1.5708"
      effort="0"
      velocity="0" />
  </joint>
  <link
    name="link2_3">
    <inertial>
      <origin
        xyz="0.10215 -6.2731E-09 8.4161E-09"
        rpy="0 0 0" />
      <mass
        value="0.37887" />
      <inertia
        ixx="0.00012589"
        ixy="8.4203E-11"
        ixz="6.9199E-11"
        iyy="0.001345"
        iyz="-2.3651E-09"
        izz="0.0013361" />
    </inertial>
    <visual>
      <origin
        xyz="0 0 0"
        rpy="0 0 0" />
      <geometry>
        <mesh
          filename="package://rviz_custom/link2_3.STL" />
      </geometry>
      <material
        name="">
        <color
          rgba="0.91 0.35 0.05 1" />
      </material>
    </visual>
    <collision>
      <origin
        xyz="0 0 0"
        rpy="0 0 0" />
      <geometry>
        <mesh
          filename="package://rviz_custom/link2_3.STL" />
      </geometry>
    </collision>
  </link>
  <joint
    name="joint2_3"
    type="revolute">
    <origin
      xyz="0.19 0 0"
      rpy="0 0 0" />
    <parent
      link="link2_2" />
    <child
      link="link2_3" />
    <axis
      xyz="0 0 1" />
    <limit
      lower="-2.0944"
      upper="2.0944"
      effort="0"
      velocity="0" />
  </joint>
  <link
    name="gripper2">
    <inertial>
      <origin
        xyz="0.017821 0.031651 0.040044"
        rpy="0 0 0" />
      <mass
        value="0.093845" />
      <inertia
        ixx="1.1829E-05"
        ixy="1.7003E-14"
        ixz="-6.4346E-13"
        iyy="1.5154E-05"
        iyz="-5.7661E-14"
        izz="1.1829E-05" />
    </inertial>
    <visual>
      <origin
        xyz="0 0 0"
        rpy="0 0 0" />
      <geometry>
        <mesh
          filename="package://rviz_custom/gripper2.STL" />
      </geometry>
      <material
        name="">
        <color
          rgba="0.63 0.63 0.63 1" />
      </material>
    </visual>
    <collision>
      <origin
        xyz="0 0 0"
        rpy="0 0 0" />
      <geometry>
        <mesh
          filename="package://rviz_custom/gripper2.STL" />
      </geometry>
    </collision>
  </link>
  <joint
    name="joint2_gripper"
    type="fixed">
    <origin
      xyz="0.195035245684479 -0.00978630239374789 0.0427234987971019"
      rpy="-3.14159265358979 0.193535912000455 1.5707963267949" />
    <parent
      link="link2_3" />
    <child
      link="gripper2" />
    <axis
      xyz="0 0 0" />
  </joint>
  <link
    name="link3_1">
    <inertial>
      <origin
        xyz="0.089259 2.8416E-08 -8.6206E-09"
        rpy="0 0 0" />
      <mass
        value="0.3223" />
      <inertia
        ixx="0.00010343"
        ixy="-8.2585E-10"
        ixz="2.3542E-10"
        iyy="0.00093847"
        iyz="4.2301E-09"
        izz="0.00095543" />
    </inertial>
    <visual>
      <origin
        xyz="0 0 0"
        rpy="0 0 0" />
      <geometry>
        <mesh
          filename="package://rviz_custom/link3_1.STL" />
      </geometry>
      <material
        name="">
        <color
          rgba="0.91 0.35 0.05 1" />
      </material>
    </visual>
    <collision>
      <origin
        xyz="0 0 0"
        rpy="0 0 0" />
      <geometry>
        <mesh
          filename="package://rviz_custom/link3_1.STL" />
      </geometry>
    </collision>
  </link>
  <joint
    name="joint3_1"
    type="revolute">
    <origin
      xyz="-0.092500000000002 0.16021469970012 0"
      rpy="1.5707963267949 0 2.0943951023932" />
    <parent
      link="base_link" />
    <child
      link="link3_1" />
    <axis
      xyz="0 1 0" />
    <limit
      lower="-1.0472"
      upper="1.0472"
      effort="0"
      velocity="0" />
  </joint>
  <link
    name="link3_2">
    <inertial>
      <origin
        xyz="0.10174 5.6036E-09 4.8841E-10"
        rpy="0 0 0" />
      <mass
        value="0.37139" />
      <inertia
        ixx="0.00011877"
        ixy="-3.8289E-10"
        ixz="3.3213E-10"
        iyy="0.0013657"
        iyz="3.9779E-10"
        izz="0.0013647" />
    </inertial>
    <visual>
      <origin
        xyz="0 0 0"
        rpy="0 0 0" />
      <geometry>
        <mesh
          filename="package://rviz_custom/link3_2.STL" />
      </geometry>
      <material
        name="">
        <color
          rgba="0.91 0.35 0.05 1" />
      </material>
    </visual>
    <collision>
      <origin
        xyz="0 0 0"
        rpy="0 0 0" />
      <geometry>
        <mesh
          filename="package://rviz_custom/link3_2.STL" />
      </geometry>
    </collision>
  </link>
  <joint
    name="joint3_2"
    type="revolute">
    <origin
      xyz="0.165 0 0"
      rpy="0 0 0" />
    <parent
      link="link3_1" />
    <child
      link="link3_2" />
    <axis
      xyz="0 0 1" />
    <limit
      lower="-1.5708"
      upper="1.5708"
      effort="0"
      velocity="0" />
  </joint>
  <link
    name="link3_3">
    <inertial>
      <origin
        xyz="0.10215 1.1098E-08 1.1831E-10"
        rpy="0 0 0" />
      <mass
        value="0.37887" />
      <inertia
        ixx="0.00012589"
        ixy="3.6133E-11"
        ixz="1.1442E-10"
        iyy="0.001345"
        iyz="-2.3639E-09"
        izz="0.0013361" />
    </inertial>
    <visual>
      <origin
        xyz="0 0 0"
        rpy="0 0 0" />
      <geometry>
        <mesh
          filename="package://rviz_custom/link3_3.STL" />
      </geometry>
      <material
        name="">
        <color
          rgba="0.91 0.35 0.05 1" />
      </material>
    </visual>
    <collision>
      <origin
        xyz="0 0 0"
        rpy="0 0 0" />
      <geometry>
        <mesh
          filename="package://rviz_custom/link3_3.STL" />
      </geometry>
    </collision>
  </link>
  <joint
    name="joint3_3"
    type="revolute">
    <origin
      xyz="0.19 0 0"
      rpy="0 0 0" />
    <parent
      link="link3_2" />
    <child
      link="link3_3" />
    <axis
      xyz="0 0 1" />
    <limit
      lower="-2.0944"
      upper="2.0944"
      effort="0"
      velocity="0" />
  </joint>
  <link
    name="gripper3">
    <inertial>
      <origin
        xyz="0.11291 -1.5785E-10 -2.5782E-10"
        rpy="0 0 0" />
      <mass
        value="0.093845" />
      <inertia
        ixx="1.5154E-05"
        ixy="-3.126E-14"
        ixz="-5.1349E-14"
        iyy="1.1829E-05"
        iyz="5.7841E-14"
        izz="1.1829E-05" />
    </inertial>
    <visual>
      <origin
        xyz="0 0 0"
        rpy="0 0 0" />
      <geometry>
        <mesh
          filename="package://rviz_custom/gripper3.STL" />
      </geometry>
      <material
        name="">
        <color
          rgba="0.63 0.63 0.63 1" />
      </material>
    </visual>
    <collision>
      <origin
        xyz="0 0 0"
        rpy="0 0 0" />
      <geometry>
        <mesh
          filename="package://rviz_custom/gripper3.STL" />
      </geometry>
    </collision>
  </link>
  <joint
    name="joint3_gripper"
    type="fixed">
    <origin
      xyz="0.113778033695662 0 0"
      rpy="0.0665681637758215 0 0" />
    <parent
      link="link3_3" />
    <child
      link="gripper3" />
    <axis
      xyz="0 0 0" />
  </joint>
  <link
    name="link4_1">
    <inertial>
      <origin
        xyz="0.089259 5.1834E-09 3.1662E-09"
        rpy="0 0 0" />
      <mass
        value="0.3223" />
      <inertia
        ixx="0.00010343"
        ixy="7.4467E-11"
        ixz="6.013E-11"
        iyy="0.00093847"
        iyz="4.4743E-09"
        izz="0.00095543" />
    </inertial>
    <visual>
      <origin
        xyz="0 0 0"
        rpy="0 0 0" />
      <geometry>
        <mesh
          filename="package://rviz_custom/link4_1.STL" />
      </geometry>
      <material
        name="">
        <color
          rgba="0.91 0.35 0.05 1" />
      </material>
    </visual>
    <collision>
      <origin
        xyz="0 0 0"
        rpy="0 0 0" />
      <geometry>
        <mesh
          filename="package://rviz_custom/link4_1.STL" />
      </geometry>
    </collision>
  </link>
  <joint
    name="joint4_1"
    type="revolute">
    <origin
      xyz="-0.185 0 0"
      rpy="1.5707963267949 0 -3.14159265358979" />
    <parent
      link="base_link" />
    <child
      link="link4_1" />
    <axis
      xyz="0 1 0" />
    <limit
      lower="-1.0472"
      upper="1.0472"
      effort="0"
      velocity="0" />
  </joint>
  <link
    name="link4_2">
    <inertial>
      <origin
        xyz="0.10174 2.7929E-09 4.423E-09"
        rpy="0 0 0" />
      <mass
        value="0.37139" />
      <inertia
        ixx="0.00011877"
        ixy="5.7476E-11"
        ixz="9.2364E-11"
        iyy="0.0013657"
        iyz="4.008E-10"
        izz="0.0013647" />
    </inertial>
    <visual>
      <origin
        xyz="0 0 0"
        rpy="0 0 0" />
      <geometry>
        <mesh
          filename="package://rviz_custom/link4_2.STL" />
      </geometry>
      <material
        name="">
        <color
          rgba="0.91 0.35 0.05 1" />
      </material>
    </visual>
    <collision>
      <origin
        xyz="0 0 0"
        rpy="0 0 0" />
      <geometry>
        <mesh
          filename="package://rviz_custom/link4_2.STL" />
      </geometry>
    </collision>
  </link>
  <joint
    name="joint4_2"
    type="revolute">
    <origin
      xyz="0.165 0 0"
      rpy="0 0 0" />
    <parent
      link="link4_1" />
    <child
      link="link4_2" />
    <axis
      xyz="0 0 1" />
    <limit
      lower="-1.5708"
      upper="1.5708"
      effort="0"
      velocity="0" />
  </joint>
  <link
    name="link4_3">
    <inertial>
      <origin
        xyz="0.10215 2.5776E-09 4.313E-09"
        rpy="0 0 0" />
      <mass
        value="0.37887" />
      <inertia
        ixx="0.00012589"
        ixy="6.4681E-11"
        ixz="9.4829E-11"
        iyy="0.001345"
        iyz="-2.3662E-09"
        izz="0.0013361" />
    </inertial>
    <visual>
      <origin
        xyz="0 0 0"
        rpy="0 0 0" />
      <geometry>
        <mesh
          filename="package://rviz_custom/link4_3.STL" />
      </geometry>
      <material
        name="">
        <color
          rgba="0.91 0.35 0.05 1" />
      </material>
    </visual>
    <collision>
      <origin
        xyz="0 0 0"
        rpy="0 0 0" />
      <geometry>
        <mesh
          filename="package://rviz_custom/link4_3.STL" />
      </geometry>
    </collision>
  </link>
  <joint
    name="joint4_3"
    type="revolute">
    <origin
      xyz="0.19 0 0"
      rpy="0 0 0" />
    <parent
      link="link4_2" />
    <child
      link="link4_3" />
    <axis
      xyz="0 0 1" />
    <limit
      lower="-2.0944"
      upper="2.0944"
      effort="0"
      velocity="0" />
  </joint>
  <link
    name="gripper4">
    <inertial>
      <origin
        xyz="0.026686 2.0252E-16 8.9822E-17"
        rpy="0 0 0" />
      <mass
        value="0.093845" />
      <inertia
        ixx="1.5154E-05"
        ixy="-2.0059E-21"
        ixz="1.7724E-21"
        iyy="1.1829E-05"
        iyz="5.5517E-14"
        izz="1.1829E-05" />
    </inertial>
    <visual>
      <origin
        xyz="0 0 0"
        rpy="0 0 0" />
      <geometry>
        <mesh
          filename="package://rviz_custom/gripper4.STL" />
      </geometry>
      <material
        name="">
        <color
          rgba="0.63 0.63 0.63 1" />
      </material>
    </visual>
    <collision>
      <origin
        xyz="0 0 0"
        rpy="0 0 0" />
      <geometry>
        <mesh
          filename="package://rviz_custom/gripper4.STL" />
      </geometry>
    </collision>
  </link>
  <joint
    name="joint4_gripper"
    type="fixed">
    <origin
      xyz="0.2 0 0"
      rpy="0.0665681637758229 0 0" />
    <parent
      link="link4_3" />
    <child
      link="gripper4" />
    <axis
      xyz="0 0 0" />
  </joint>
  <link
    name="link5_1">
    <inertial>
      <origin
        xyz="0.089259 -1.8043E-08 1.4936E-08"
        rpy="0 0 0" />
      <mass
        value="0.3223" />
      <inertia
        ixx="0.00010343"
        ixy="9.7403E-10"
        ixz="-1.1632E-10"
        iyy="0.00093847"
        iyz="4.2307E-09"
        izz="0.00095543" />
    </inertial>
    <visual>
      <origin
        xyz="0 0 0"
        rpy="0 0 0" />
      <geometry>
        <mesh
          filename="package://rviz_custom/link5_1.STL" />
      </geometry>
      <material
        name="">
        <color
          rgba="0.91 0.35 0.05 1" />
      </material>
    </visual>
    <collision>
      <origin
        xyz="0 0 0"
        rpy="0 0 0" />
      <geometry>
        <mesh
          filename="package://rviz_custom/link5_1.STL" />
      </geometry>
    </collision>
  </link>
  <joint
    name="joint5_1"
    type="revolute">
    <origin
      xyz="-0.0924999999999996 -0.160214699700121 0"
      rpy="1.5707963267949 0 -2.09439510239319" />
    <parent
      link="base_link" />
    <child
      link="link5_1" />
    <axis
      xyz="0 1 0" />
    <limit
      lower="-1.0472"
      upper="1.0472"
      effort="0"
      velocity="0" />
  </joint>
  <link
    name="link5_2">
    <inertial>
      <origin
        xyz="0.10174 -1.732E-10 8.2538E-09"
        rpy="0 0 0" />
      <mass
        value="0.37139" />
      <inertia
        ixx="0.00011877"
        ixy="4.9404E-10"
        ixz="-1.4931E-10"
        iyy="0.0013657"
        iyz="3.9652E-10"
        izz="0.0013647" />
    </inertial>
    <visual>
      <origin
        xyz="0 0 0"
        rpy="0 0 0" />
      <geometry>
        <mesh
          filename="package://rviz_custom/link5_2.STL" />
      </geometry>
      <material
        name="">
        <color
          rgba="0.91 0.35 0.05 1" />
      </material>
    </visual>
    <collision>
      <origin
        xyz="0 0 0"
        rpy="0 0 0" />
      <geometry>
        <mesh
          filename="package://rviz_custom/link5_2.STL" />
      </geometry>
    </collision>
  </link>
  <joint
    name="joint5_2"
    type="revolute">
    <origin
      xyz="0.165 0 0"
      rpy="0 0 0" />
    <parent
      link="link5_1" />
    <child
      link="link5_2" />
    <axis
      xyz="0 0 1" />
    <limit
      lower="-1.5708"
      upper="1.5708"
      effort="0"
      velocity="0" />
  </joint>
  <link
    name="link5_3">
    <inertial>
      <origin
        xyz="0.10215 -6.2731E-09 8.4161E-09"
        rpy="0 0 0" />
      <mass
        value="0.37887" />
      <inertia
        ixx="0.00012589"
        ixy="8.4203E-11"
        ixz="6.9199E-11"
        iyy="0.001345"
        iyz="-2.3651E-09"
        izz="0.0013361" />
    </inertial>
    <visual>
      <origin
        xyz="0 0 0"
        rpy="0 0 0" />
      <geometry>
        <mesh
          filename="package://rviz_custom/link5_3.STL" />
      </geometry>
      <material
        name="">
        <color
          rgba="0.91 0.35 0.05 1" />
      </material>
    </visual>
    <collision>
      <origin
        xyz="0 0 0"
        rpy="0 0 0" />
      <geometry>
        <mesh
          filename="package://rviz_custom/link5_3.STL" />
      </geometry>
    </collision>
  </link>
  <joint
    name="joint5_3"
    type="revolute">
    <origin
      xyz="0.19 0 0"
      rpy="0 0 0" />
    <parent
      link="link5_2" />
    <child
      link="link5_3" />
    <axis
      xyz="0 0 1" />
    <limit
      lower="-2.0944"
      upper="2.0944"
      effort="0"
      velocity="0" />
  </joint>
  <link
    name="gripper5">
    <inertial>
      <origin
        xyz="0.013518 1.5785E-10 2.5782E-10"
        rpy="0 0 0" />
      <mass
        value="0.093845" />
      <inertia
        ixx="1.5154E-05"
        ixy="3.126E-14"
        ixz="5.1349E-14"
        iyy="1.1829E-05"
        iyz="5.7841E-14"
        izz="1.1829E-05" />
    </inertial>
    <visual>
      <origin
        xyz="0 0 0"
        rpy="0 0 0" />
      <geometry>
        <mesh
          filename="package://rviz_custom/gripper5.STL" />
      </geometry>
      <material
        name="">
        <color
          rgba="0.63 0.63 0.63 1" />
      </material>
    </visual>
    <collision>
      <origin
        xyz="0 0 0"
        rpy="0 0 0" />
      <geometry>
        <mesh
          filename="package://rviz_custom/gripper5.STL" />
      </geometry>
    </collision>
  </link>
  <joint
    name="joint5_gripper"
    type="fixed">
    <origin
      xyz="0.213168151508275 0 0"
      rpy="0.0665681637758215 0 0" />
    <parent
      link="link5_3" />
    <child
      link="gripper5" />
    <axis
      xyz="0 0 0" />
  </joint>
  <link
    name="link6_1">
    <inertial>
      <origin
        xyz="0.089259 2.8416E-08 -8.6206E-09"
        rpy="0 0 0" />
      <mass
        value="0.3223" />
      <inertia
        ixx="0.00010343"
        ixy="-8.2585E-10"
        ixz="2.3542E-10"
        iyy="0.00093847"
        iyz="4.2301E-09"
        izz="0.00095543" />
    </inertial>
    <visual>
      <origin
        xyz="0 0 0"
        rpy="0 0 0" />
      <geometry>
        <mesh
          filename="package://rviz_custom/link6_1.STL" />
      </geometry>
      <material
        name="">
        <color
          rgba="0.91 0.35 0.05 1" />
      </material>
    </visual>
    <collision>
      <origin
        xyz="0 0 0"
        rpy="0 0 0" />
      <geometry>
        <mesh
          filename="package://rviz_custom/link6_1.STL" />
      </geometry>
    </collision>
  </link>
  <joint
    name="joint6_1"
    type="revolute">
    <origin
      xyz="0.0925000000000009 -0.160214699700121 0"
      rpy="1.5707963267949 0 -1.0471975511966" />
    <parent
      link="base_link" />
    <child
      link="link6_1" />
    <axis
      xyz="0 1 0" />
    <limit
      lower="-1.0472"
      upper="1.0472"
      effort="0"
      velocity="0" />
  </joint>
  <link
    name="link6_2">
    <inertial>
      <origin
        xyz="0.10174 5.6036E-09 4.8841E-10"
        rpy="0 0 0" />
      <mass
        value="0.37139" />
      <inertia
        ixx="0.00011877"
        ixy="-3.8289E-10"
        ixz="3.3213E-10"
        iyy="0.0013657"
        iyz="3.9779E-10"
        izz="0.0013647" />
    </inertial>
    <visual>
      <origin
        xyz="0 0 0"
        rpy="0 0 0" />
      <geometry>
        <mesh
          filename="package://rviz_custom/link6_2.STL" />
      </geometry>
      <material
        name="">
        <color
          rgba="0.91 0.35 0.05 1" />
      </material>
    </visual>
    <collision>
      <origin
        xyz="0 0 0"
        rpy="0 0 0" />
      <geometry>
        <mesh
          filename="package://rviz_custom/link6_2.STL" />
      </geometry>
    </collision>
  </link>
  <joint
    name="joint6_2"
    type="revolute">
    <origin
      xyz="0.165 0 0"
      rpy="0 0 0" />
    <parent
      link="link6_1" />
    <child
      link="link6_2" />
    <axis
      xyz="0 0 1" />
    <limit
      lower="-1.5708"
      upper="1.5708"
      effort="0"
      velocity="0" />
  </joint>
  <link
    name="link6_3">
    <inertial>
      <origin
        xyz="0.10215 1.1098E-08 1.1832E-10"
        rpy="0 0 0" />
      <mass
        value="0.37887" />
      <inertia
        ixx="0.00012589"
        ixy="3.6133E-11"
        ixz="1.1442E-10"
        iyy="0.001345"
        iyz="-2.3639E-09"
        izz="0.0013361" />
    </inertial>
    <visual>
      <origin
        xyz="0 0 0"
        rpy="0 0 0" />
      <geometry>
        <mesh
          filename="package://rviz_custom/link6_3.STL" />
      </geometry>
      <material
        name="">
        <color
          rgba="0.91 0.35 0.05 1" />
      </material>
    </visual>
    <collision>
      <origin
        xyz="0 0 0"
        rpy="0 0 0" />
      <geometry>
        <mesh
          filename="package://rviz_custom/link6_3.STL" />
      </geometry>
    </collision>
  </link>
  <joint
    name="joint6_3"
    type="revolute">
    <origin
      xyz="0.19 0 0"
      rpy="0 0 0" />
    <parent
      link="link6_2" />
    <child
      link="link6_3" />
    <axis
      xyz="0 0 1" />
    <limit
      lower="-2.0944"
      upper="2.0944"
      effort="0"
      velocity="0" />
  </joint>
  <link
    name="gripper6">
    <inertial>
      <origin
        xyz="0.11291 -1.5785E-10 -2.5782E-10"
        rpy="0 0 0" />
      <mass
        value="0.093845" />
      <inertia
        ixx="1.5154E-05"
        ixy="-3.126E-14"
        ixz="-5.1349E-14"
        iyy="1.1829E-05"
        iyz="5.7841E-14"
        izz="1.1829E-05" />
    </inertial>
    <visual>
      <origin
        xyz="0 0 0"
        rpy="0 0 0" />
      <geometry>
        <mesh
          filename="package://rviz_custom/gripper6.STL" />
      </geometry>
      <material
        name="">
        <color
          rgba="0.63 0.63 0.63 1" />
      </material>
    </visual>
    <collision>
      <origin
        xyz="0 0 0"
        rpy="0 0 0" />
      <geometry>
        <mesh
          filename="package://rviz_custom/gripper6.STL" />
      </geometry>
    </collision>
  </link>
  <joint
    name="joint6_gripper"
    type="fixed">
    <origin
      xyz="0.11378 0 0"
      rpy="0.066568 0 0" />
    <parent
      link="link6_3" />
    <child
      link="gripper6" />
    <axis
      xyz="0 0 0" />
  </joint>
</robot>
