<?xml version="1.0" ?>
<robot name="moonbot_hero" xmlns:xacro="http://www.ros.org/wiki/xacro">

<xacro:property name="ThisPackage" value="rviz_basic" />
<xacro:property name="Filename" value="moonbot_hero" />
<xacro:property name="UrdfDataPath" value="package://${ThisPackage}/urdf/${Filename}" />
<xacro:property name="MeshPath" value="package://${ThisPackage}/meshes/${Filename}" />

<xacro:include filename="materials.xacro" />
<xacro:include filename="${Filename}.trans" />
<xacro:include filename="${Filename}.gazebo" />

<link name="base_link">
  <inertial>
    <origin xyz="-1.7763568394002505e-17 7.105427357601002e-17 0.22861864817777036" rpy="0 0 0"/>
    <mass value="375.11988568950204"/>
    <inertia ixx="7.759179" iyy="7.759179" izz="7.759179" ixy="0.0" iyz="-0.0" ixz="-0.0"/>
  </inertial>
  <visual>
    <origin xyz="0 0 0" rpy="0 0 0"/>
    <geometry>
    <mesh filename="${MeshPath}/base_link.stl" scale="0.001 0.001 0.001"/>
    </geometry>
    <material name="silver"/>
  </visual>
  <collision>
    <origin xyz="0 0 0" rpy="0 0 0"/>
    <geometry>
    <mesh filename="${MeshPath}/base_link.stl" scale="0.001 0.001 0.001"/>
    </geometry>
  </collision>
</link>

<link name="LegHip_2">
  <inertial>
    <origin xyz="-3.851153477298588e-16 -0.00840515565494468 -0.005942830499220647" rpy="0 0 0"/>
    <mass value="4.86663601500531"/>
    <inertia ixx="0.011585" iyy="0.010312" izz="0.007862" ixy="-0.0" iyz="0.003465" ixz="0.0"/>
  </inertial>
  <visual>
    <origin xyz="0.0 0.161351 -0.113876" rpy="0 0 0"/>
    <geometry>
    <mesh filename="${MeshPath}/LegHip_2.stl" scale="0.001 0.001 0.001"/>
    </geometry>
    <material name="silver"/>
  </visual>
  <collision>
    <origin xyz="0.0 0.161351 -0.113876" rpy="0 0 0"/>
    <geometry>
    <mesh filename="${MeshPath}/LegHip_2.stl" scale="0.001 0.001 0.001"/>
    </geometry>
  </collision>
</link>

<link name="LegRoll1Link_2">
  <inertial>
    <origin xyz="-0.004647167967986943 -0.05712202276619882 -0.04039095750929736" rpy="0 0 0"/>
    <mass value="9.373863502530105"/>
    <inertia ixx="0.021275" iyy="0.015633" izz="0.0185" ixy="-0.000699" iyz="-0.004055" ixz="-0.000494"/>
  </inertial>
  <visual>
    <origin xyz="0.0 0.194011 -0.090782" rpy="0 0 0"/>
    <geometry>
    <mesh filename="${MeshPath}/LegRoll1Link_2.stl" scale="0.001 0.001 0.001"/>
    </geometry>
    <material name="silver"/>
  </visual>
  <collision>
    <origin xyz="0.0 0.194011 -0.090782" rpy="0 0 0"/>
    <geometry>
    <mesh filename="${MeshPath}/LegRoll1Link_2.stl" scale="0.001 0.001 0.001"/>
    </geometry>
  </collision>
</link>

<link name="MH_L-shaped_link_v6_2">
  <inertial>
    <origin xyz="0.019318769269816488 -0.02380094232891644 0.019361296617652027" rpy="0 0 0"/>
    <mass value="1.1768921510936396"/>
    <inertia ixx="0.002042" iyy="0.002105" izz="0.002165" ixy="0.000518" iyz="0.000146" ixz="-0.000421"/>
  </inertial>
  <visual>
    <origin xyz="0.05 0.275661 -0.033047" rpy="0 0 0"/>
    <geometry>
    <mesh filename="${MeshPath}/MH_L-shaped_link_v6_2.stl" scale="0.001 0.001 0.001"/>
    </geometry>
    <material name="silver"/>
  </visual>
  <collision>
    <origin xyz="0.05 0.275661 -0.033047" rpy="0 0 0"/>
    <geometry>
    <mesh filename="${MeshPath}/MH_L-shaped_link_v6_2.stl" scale="0.001 0.001 0.001"/>
    </geometry>
  </collision>
</link>

<link name="LegPitch1Link_2">
  <inertial>
    <origin xyz="-0.007108161123664542 -0.16800225630684673 0.13783507607505957" rpy="0 0 0"/>
    <mass value="25.903618237357847"/>
    <inertia ixx="0.471474" iyy="0.210993" izz="0.292206" ixy="-0.023685" iyz="0.214363" ixz="0.018976"/>
  </inertial>
  <visual>
    <origin xyz="0.0 0.32143 -0.070279" rpy="0 0 0"/>
    <geometry>
    <mesh filename="${MeshPath}/LegPitch1Link_2.stl" scale="0.001 0.001 0.001"/>
    </geometry>
    <material name="silver"/>
  </visual>
  <collision>
    <origin xyz="0.0 0.32143 -0.070279" rpy="0 0 0"/>
    <geometry>
    <mesh filename="${MeshPath}/LegPitch1Link_2.stl" scale="0.001 0.001 0.001"/>
    </geometry>
  </collision>
</link>

<link name="LegPitch2Link_2">
  <inertial>
    <origin xyz="-0.018222504376528902 -0.049037371258055296 -0.21657918431312642" rpy="0 0 0"/>
    <mass value="25.903618237357847"/>
    <inertia ixx="0.458925" iyy="0.450127" izz="0.06562" ixy="-0.017267" iyz="-0.088988" ixz="-0.077354"/>
  </inertial>
  <visual>
    <origin xyz="0.0 0.662759 -0.347937" rpy="0 0 0"/>
    <geometry>
    <mesh filename="${MeshPath}/LegPitch2Link_2.stl" scale="0.001 0.001 0.001"/>
    </geometry>
    <material name="silver"/>
  </visual>
  <collision>
    <origin xyz="0.0 0.662759 -0.347937" rpy="0 0 0"/>
    <geometry>
    <mesh filename="${MeshPath}/LegPitch2Link_2.stl" scale="0.001 0.001 0.001"/>
    </geometry>
  </collision>
</link>

<link name="LegRoll2Link_2">
  <inertial>
    <origin xyz="-0.03256495583712069 0.0026768537637105183 -0.025992679746943262" rpy="0 0 0"/>
    <mass value="1.1768921510936396"/>
    <inertia ixx="0.001913" iyy="0.002334" izz="0.002065" ixy="-5.8e-05" iyz="0.000127" ixz="-0.000637"/>
  </inertial>
  <visual>
    <origin xyz="0.050049 0.758514 0.078591" rpy="0 0 0"/>
    <geometry>
    <mesh filename="${MeshPath}/LegRoll2Link_2.stl" scale="0.001 0.001 0.001"/>
    </geometry>
    <material name="silver"/>
  </visual>
  <collision>
    <origin xyz="0.050049 0.758514 0.078591" rpy="0 0 0"/>
    <geometry>
    <mesh filename="${MeshPath}/LegRoll2Link_2.stl" scale="0.001 0.001 0.001"/>
    </geometry>
  </collision>
</link>

<link name="LegPitch3Link_2">
  <inertial>
    <origin xyz="0.042166236624706435 -0.01213068973596887 -0.0321582951901091" rpy="0 0 0"/>
    <mass value="9.373863502530105"/>
    <inertia ixx="0.021335" iyy="0.021367" izz="0.012706" ixy="1e-06" iyz="2.1e-05" ixz="0.000474"/>
  </inertial>
  <visual>
    <origin xyz="0.104694 0.757166 0.134376" rpy="0 0 0"/>
    <geometry>
    <mesh filename="${MeshPath}/LegPitch3Link_2.stl" scale="0.001 0.001 0.001"/>
    </geometry>
    <material name="silver"/>
  </visual>
  <collision>
    <origin xyz="0.104694 0.757166 0.134376" rpy="0 0 0"/>
    <geometry>
    <mesh filename="${MeshPath}/LegPitch3Link_2.stl" scale="0.001 0.001 0.001"/>
    </geometry>
  </collision>
</link>

<link name="LegAnkle_2">
  <inertial>
    <origin xyz="-0.0011960481771010958 0.0009250467213599567 -0.029667914448414157" rpy="0 0 0"/>
    <mass value="4.8666362605472635"/>
    <inertia ixx="0.00594" iyy="0.011074" izz="0.012746" ixy="0.0017" iyz="-0.000121" ixz="0.000328"/>
  </inertial>
  <visual>
    <origin xyz="0.0609 0.768456 0.236624" rpy="0 0 0"/>
    <geometry>
    <mesh filename="${MeshPath}/LegAnkle_2.stl" scale="0.001 0.001 0.001"/>
    </geometry>
    <material name="silver"/>
  </visual>
  <collision>
    <origin xyz="0.0609 0.768456 0.236624" rpy="0 0 0"/>
    <geometry>
    <mesh filename="${MeshPath}/LegAnkle_2.stl" scale="0.001 0.001 0.001"/>
    </geometry>
  </collision>
</link>

<link name="LegWheelBody_2">
  <inertial>
    <origin xyz="-0.00366349095266022 0.002834398205094235 -0.0908821445281649" rpy="0 0 0"/>
    <mass value="31.73897478389843"/>
    <inertia ixx="0.130871" iyy="0.146043" izz="0.129353" ixy="0.005045" iyz="0.000317" ixz="9.6e-05"/>
  </inertial>
  <visual>
    <origin xyz="0.062511 0.76721 0.276572" rpy="0 0 0"/>
    <geometry>
    <mesh filename="${MeshPath}/LegWheelBody_2.stl" scale="0.001 0.001 0.001"/>
    </geometry>
    <material name="silver"/>
  </visual>
  <collision>
    <origin xyz="0.062511 0.76721 0.276572" rpy="0 0 0"/>
    <geometry>
    <mesh filename="${MeshPath}/LegWheelBody_2.stl" scale="0.001 0.001 0.001"/>
    </geometry>
  </collision>
</link>

<link name="LegWheel1_2">
  <inertial>
    <origin xyz="-0.014851426768839063 -0.04914688150005164 -0.0009338066708897697" rpy="0 0 0"/>
    <mass value="25.69936736300387"/>
    <inertia ixx="0.326142" iyy="0.534104" izz="0.305325" ixy="0.069159" iyz="0.00435" ixz="0.001315"/>
  </inertial>
  <visual>
    <origin xyz="0.08642 0.831372 0.368728" rpy="0 0 0"/>
    <geometry>
    <mesh filename="${MeshPath}/LegWheel1_2.stl" scale="0.001 0.001 0.001"/>
    </geometry>
    <material name="silver"/>
  </visual>
  <collision>
    <origin xyz="0.08642 0.831372 0.368728" rpy="0 0 0"/>
    <geometry>
    <mesh filename="${MeshPath}/LegWheel1_2.stl" scale="0.001 0.001 0.001"/>
    </geometry>
  </collision>
</link>

<link name="LegWheel2_2">
  <inertial>
    <origin xyz="0.014851444863523144 0.04914667791023941 0.0009345176145510448" rpy="0 0 0"/>
    <mass value="25.69936736300387"/>
    <inertia ixx="0.326142" iyy="0.534104" izz="0.305325" ixy="0.069159" iyz="0.00435" ixz="0.001315"/>
  </inertial>
  <visual>
    <origin xyz="0.045929 0.697379 0.366181" rpy="0 0 0"/>
    <geometry>
    <mesh filename="${MeshPath}/LegWheel2_2.stl" scale="0.001 0.001 0.001"/>
    </geometry>
    <material name="silver"/>
  </visual>
  <collision>
    <origin xyz="0.045929 0.697379 0.366181" rpy="0 0 0"/>
    <geometry>
    <mesh filename="${MeshPath}/LegWheel2_2.stl" scale="0.001 0.001 0.001"/>
    </geometry>
  </collision>
</link>

<link name="Arm_Hip_2">
  <inertial>
    <origin xyz="6.175473028994796e-17 2.1687631983624666e-16 0.01029386344233496" rpy="0 0 0"/>
    <mass value="4.8666362605472635"/>
    <inertia ixx="0.005411" iyy="0.011585" izz="0.012763" ixy="-0.0" iyz="0.0" ixz="0.0"/>
  </inertial>
  <visual>
    <origin xyz="0.0 -0.0 -0.457237" rpy="0 0 0"/>
    <geometry>
    <mesh filename="${MeshPath}/Arm_Hip_2.stl" scale="0.001 0.001 0.001"/>
    </geometry>
    <material name="silver"/>
  </visual>
  <collision>
    <origin xyz="0.0 -0.0 -0.457237" rpy="0 0 0"/>
    <geometry>
    <mesh filename="${MeshPath}/Arm_Hip_2.stl" scale="0.001 0.001 0.001"/>
    </geometry>
  </collision>
</link>

<link name="Arm_Roll1Link_2">
  <inertial>
    <origin xyz="-0.004647167967986551 6.7213023029906176e-09 0.0699597584777531" rpy="0 0 0"/>
    <mass value="9.373863502530105"/>
    <inertia ixx="0.021275" iyy="0.021368" izz="0.012766" ixy="-0.0" iyz="0.0" ixz="0.000856"/>
  </inertial>
  <visual>
    <origin xyz="-0.0 -0.0 -0.497237" rpy="0 0 0"/>
    <geometry>
    <mesh filename="${MeshPath}/Arm_Roll1Link_2.stl" scale="0.001 0.001 0.001"/>
    </geometry>
    <material name="silver"/>
  </visual>
  <collision>
    <origin xyz="-0.0 -0.0 -0.497237" rpy="0 0 0"/>
    <geometry>
    <mesh filename="${MeshPath}/Arm_Roll1Link_2.stl" scale="0.001 0.001 0.001"/>
    </geometry>
  </collision>
</link>

<link name="Arm_Pitch1Link_2">
  <inertial>
    <origin xyz="0.01931876926981694 5.773159728050814e-16 0.03168154674555823" rpy="0 0 0"/>
    <mass value="1.1768921510936396"/>
    <inertia ixx="0.002042" iyy="0.002284" izz="0.001986" ixy="-0.0" iyz="-0.0" ixz="-0.000667"/>
  </inertial>
  <visual>
    <origin xyz="0.05 -0.0 -0.597237" rpy="0 0 0"/>
    <geometry>
    <mesh filename="${MeshPath}/Arm_Pitch1Link_2.stl" scale="0.001 0.001 0.001"/>
    </geometry>
    <material name="silver"/>
  </visual>
  <collision>
    <origin xyz="0.05 -0.0 -0.597237" rpy="0 0 0"/>
    <geometry>
    <mesh filename="${MeshPath}/Arm_Pitch1Link_2.stl" scale="0.001 0.001 0.001"/>
    </geometry>
  </collision>
</link>

<link name="Arm_Pitch2Link_2">
  <inertial>
    <origin xyz="-1.165212843627881e-09 0.00716606663725685 0.21730765161396004" rpy="0 0 0"/>
    <mass value="25.903618237357847"/>
    <inertia ixx="0.469711" iyy="0.471503" izz="0.033459" ixy="-0.0" iyz="-0.030595" ixz="0.0"/>
  </inertial>
  <visual>
    <origin xyz="-0.0 -0.0 -0.657237" rpy="0 0 0"/>
    <geometry>
    <mesh filename="${MeshPath}/Arm_Pitch2Link_2.stl" scale="0.001 0.001 0.001"/>
    </geometry>
    <material name="silver"/>
  </visual>
  <collision>
    <origin xyz="-0.0 -0.0 -0.657237" rpy="0 0 0"/>
    <geometry>
    <mesh filename="${MeshPath}/Arm_Pitch2Link_2.stl" scale="0.001 0.001 0.001"/>
    </geometry>
  </collision>
</link>

<link name="Arm_Pitch3Link_2">
  <inertial>
    <origin xyz="0.22269264474158362 -0.00716606663725813 2.975207549216208e-07" rpy="0 0 0"/>
    <mass value="25.903618237357847"/>
    <inertia ixx="0.033459" iyy="0.471503" izz="0.469711" ixy="-0.030595" iyz="-0.0" ixz="0.0"/>
  </inertial>
  <visual>
    <origin xyz="0.0 0.0 -1.097237" rpy="0 0 0"/>
    <geometry>
    <mesh filename="${MeshPath}/Arm_Pitch3Link_2.stl" scale="0.001 0.001 0.001"/>
    </geometry>
    <material name="silver"/>
  </visual>
  <collision>
    <origin xyz="0.0 0.0 -1.097237" rpy="0 0 0"/>
    <geometry>
    <mesh filename="${MeshPath}/Arm_Pitch3Link_2.stl" scale="0.001 0.001 0.001"/>
    </geometry>
  </collision>
</link>

<link name="Arm_Roll2Link_2">
  <inertial>
    <origin xyz="0.028318749609986316 0.03056447938433833 -0.0026737490971615596" rpy="0 0 0"/>
    <mass value="1.1768921510936396"/>
    <inertia ixx="0.001986" iyy="0.002044" izz="0.002282" ixy="-0.000665" iyz="2.1e-05" ixz="5.8e-05"/>
  </inertial>
  <visual>
    <origin xyz="-0.44 0.0 -1.097237" rpy="0 0 0"/>
    <geometry>
    <mesh filename="${MeshPath}/Arm_Roll2Link_2.stl" scale="0.001 0.001 0.001"/>
    </geometry>
    <material name="silver"/>
  </visual>
  <collision>
    <origin xyz="-0.44 0.0 -1.097237" rpy="0 0 0"/>
    <geometry>
    <mesh filename="${MeshPath}/Arm_Roll2Link_2.stl" scale="0.001 0.001 0.001"/>
    </geometry>
  </collision>
</link>

<link name="Arm_Pitch4Link_2">
  <inertial>
    <origin xyz="6.721305068069228e-09 -0.04779872130042869 -0.025973955582060393" rpy="0 0 0"/>
    <mass value="9.373863502530105"/>
    <inertia ixx="0.021368" iyy="0.021061" izz="0.012979" ixy="0.0" iyz="-0.001582" ixz="0.0"/>
  </inertial>
  <visual>
    <origin xyz="-0.5 -0.04981 -1.09288" rpy="0 0 0"/>
    <geometry>
    <mesh filename="${MeshPath}/Arm_Pitch4Link_2.stl" scale="0.001 0.001 0.001"/>
    </geometry>
    <material name="silver"/>
  </visual>
  <collision>
    <origin xyz="-0.5 -0.04981 -1.09288" rpy="0 0 0"/>
    <geometry>
    <mesh filename="${MeshPath}/Arm_Pitch4Link_2.stl" scale="0.001 0.001 0.001"/>
    </geometry>
  </collision>
</link>

<link name="Hand_2">
  <inertial>
    <origin xyz="1.887379141862766e-15 -0.00258866049970035 -0.02959356442099015" rpy="0 0 0"/>
    <mass value="4.8666362605472635"/>
    <inertia ixx="0.005411" iyy="0.011594" izz="0.012754" ixy="-0.0" iyz="0.000102" ixz="0.0"/>
  </inertial>
  <visual>
    <origin xyz="-0.5 0.008716 -0.997618" rpy="0 0 0"/>
    <geometry>
    <mesh filename="${MeshPath}/Hand_2.stl" scale="0.001 0.001 0.001"/>
    </geometry>
    <material name="silver"/>
  </visual>
  <collision>
    <origin xyz="-0.5 0.008716 -0.997618" rpy="0 0 0"/>
    <geometry>
    <mesh filename="${MeshPath}/Hand_2.stl" scale="0.001 0.001 0.001"/>
    </geometry>
  </collision>
</link>

<link name="Leg1Hip_1">
  <inertial>
    <origin xyz="0.008405156672742164 2.3557111607644586e-16 -0.005942831218911773" rpy="0 0 0"/>
    <mass value="4.8666362605472635"/>
    <inertia ixx="0.010312" iyy="0.011585" izz="0.007862" ixy="0.0" iyz="0.0" ixz="-0.003465"/>
  </inertial>
  <visual>
    <origin xyz="-0.161351 -0.0 -0.113876" rpy="0 0 0"/>
    <geometry>
    <mesh filename="${MeshPath}/Leg1Hip_1.stl" scale="0.001 0.001 0.001"/>
    </geometry>
    <material name="silver"/>
  </visual>
  <collision>
    <origin xyz="-0.161351 -0.0 -0.113876" rpy="0 0 0"/>
    <geometry>
    <mesh filename="${MeshPath}/Leg1Hip_1.stl" scale="0.001 0.001 0.001"/>
    </geometry>
  </collision>
</link>

<link name="Leg2_Roll1Link_1">
  <inertial>
    <origin xyz="0.057328137758166586 -0.004633434488142129 -0.040099466895672196" rpy="0 0 0"/>
    <mass value="9.373863502530105"/>
    <inertia ixx="0.015571" iyy="0.021275" izz="0.018562" ixy="0.000701" iyz="-0.000487" ixz="0.004033"/>
  </inertial>
  <visual>
    <origin xyz="-0.194011 -0.0 -0.090782" rpy="0 0 0"/>
    <geometry>
    <mesh filename="${MeshPath}/Leg2_Roll1Link_1.stl" scale="0.001 0.001 0.001"/>
    </geometry>
    <material name="silver"/>
  </visual>
  <collision>
    <origin xyz="-0.194011 -0.0 -0.090782" rpy="0 0 0"/>
    <geometry>
    <mesh filename="${MeshPath}/Leg2_Roll1Link_1.stl" scale="0.001 0.001 0.001"/>
    </geometry>
  </collision>
</link>

<link name="Leg2_Pitch1Link_1">
  <inertial>
    <origin xyz="0.023601879506790713 0.0216076085892345 0.01878736554131096" rpy="0 0 0"/>
    <mass value="1.1768921510936396"/>
    <inertia ixx="0.002151" iyy="0.001943" izz="0.002217" ixy="-0.000518" iyz="-0.000416" ixz="-9.5e-05"/>
  </inertial>
  <visual>
    <origin xyz="-0.277879 0.049852 -0.036183" rpy="0 0 0"/>
    <geometry>
    <mesh filename="${MeshPath}/Leg2_Pitch1Link_1.stl" scale="0.001 0.001 0.001"/>
    </geometry>
    <material name="silver"/>
  </visual>
  <collision>
    <origin xyz="-0.277879 0.049852 -0.036183" rpy="0 0 0"/>
    <geometry>
    <mesh filename="${MeshPath}/Leg2_Pitch1Link_1.stl" scale="0.001 0.001 0.001"/>
    </geometry>
  </collision>
</link>

<link name="Leg2_Roll2Link_1">
  <inertial>
    <origin xyz="0.16705724559157603 0.009164175564016927 0.13885902202101896" rpy="0 0 0"/>
    <mass value="25.903618237357847"/>
    <inertia ixx="0.214399" iyy="0.473375" izz="0.286898" ixy="-0.001706" iyz="-0.002659" ixz="-0.216279"/>
  </inertial>
  <visual>
    <origin xyz="-0.321983 -0.004443 -0.070922" rpy="0 0 0"/>
    <geometry>
    <mesh filename="${MeshPath}/Leg2_Roll2Link_1.stl" scale="0.001 0.001 0.001"/>
    </geometry>
    <material name="silver"/>
  </visual>
  <collision>
    <origin xyz="-0.321983 -0.004443 -0.070922" rpy="0 0 0"/>
    <geometry>
    <mesh filename="${MeshPath}/Leg2_Roll2Link_1.stl" scale="0.001 0.001 0.001"/>
    </geometry>
  </collision>
</link>

<link name="Leg2_Pitch2Link_1">
  <inertial>
    <origin xyz="0.14060641397764528 -0.04742474176932074 -0.1662050624183143" rpy="0 0 0"/>
    <mass value="25.903618237357847"/>
    <inertia ixx="0.30139" iyy="0.430957" izz="0.242325" ixy="0.084903" iyz="-0.099172" ixz="0.195661"/>
  </inertial>
  <visual>
    <origin xyz="-0.661679 -0.037028 -0.348672" rpy="0 0 0"/>
    <geometry>
    <mesh filename="${MeshPath}/Leg2_Pitch2Link_1.stl" scale="0.001 0.001 0.001"/>
    </geometry>
    <material name="silver"/>
  </visual>
  <collision>
    <origin xyz="-0.661679 -0.037028 -0.348672" rpy="0 0 0"/>
    <geometry>
    <mesh filename="${MeshPath}/Leg2_Pitch2Link_1.stl" scale="0.001 0.001 0.001"/>
    </geometry>
  </collision>
</link>

<link name="Leg2_Roll3Link_1">
  <inertial>
    <origin xyz="0.029916901028178233 0.021253000261699496 -0.019914287040912432" rpy="0 0 0"/>
    <mass value="1.1768921510936396"/>
    <inertia ixx="0.001797" iyy="0.002361" izz="0.002153" ixy="-0.000363" iyz="0.000397" ixz="0.000317"/>
  </inertial>
  <visual>
    <origin xyz="-0.938085 0.070365 -0.023608" rpy="0 0 0"/>
    <geometry>
    <mesh filename="${MeshPath}/Leg2_Roll3Link_1.stl" scale="0.001 0.001 0.001"/>
    </geometry>
    <material name="silver"/>
  </visual>
  <collision>
    <origin xyz="-0.938085 0.070365 -0.023608" rpy="0 0 0"/>
    <geometry>
    <mesh filename="${MeshPath}/Leg2_Roll3Link_1.stl" scale="0.001 0.001 0.001"/>
    </geometry>
  </collision>
</link>

<link name="Leg2_Pitch3Link_1">
  <inertial>
    <origin xyz="-0.0172564149400688 -0.04084814057260879 -0.03151130776477959" rpy="0 0 0"/>
    <mass value="9.373863502530105"/>
    <inertia ixx="0.021364" iyy="0.021324" izz="0.012719" ixy="-1.2e-05" iyz="-0.000563" ixz="-0.000147"/>
  </inertial>
  <visual>
    <origin xyz="-0.99554 0.03911 0.019078" rpy="0 0 0"/>
    <geometry>
    <mesh filename="${MeshPath}/Leg2_Pitch3Link_1.stl" scale="0.001 0.001 0.001"/>
    </geometry>
    <material name="silver"/>
  </visual>
  <collision>
    <origin xyz="-0.99554 0.03911 0.019078" rpy="0 0 0"/>
    <geometry>
    <mesh filename="${MeshPath}/Leg2_Pitch3Link_1.stl" scale="0.001 0.001 0.001"/>
    </geometry>
  </collision>
</link>

<link name="Leg2_Ankle_1">
  <inertial>
    <origin xyz="0.0006629432880481678 0.0007761239636264877 -0.029688852846777983" rpy="0 0 0"/>
    <mass value="4.8666362605472635"/>
    <inertia ixx="0.005419" iyy="0.011582" izz="0.012758" ixy="0.000157" iyz="-2.7e-05" ixz="-0.00016"/>
  </inertial>
  <visual>
    <origin xyz="-0.978008 0.082394 0.12066" rpy="0 0 0"/>
    <geometry>
    <mesh filename="${MeshPath}/Leg2_Ankle_1.stl" scale="0.001 0.001 0.001"/>
    </geometry>
    <material name="silver"/>
  </visual>
  <collision>
    <origin xyz="-0.978008 0.082394 0.12066" rpy="0 0 0"/>
    <geometry>
    <mesh filename="${MeshPath}/Leg2_Ankle_1.stl" scale="0.001 0.001 0.001"/>
    </geometry>
  </collision>
</link>

<link name="Leg2_WheelBody_1">
  <inertial>
    <origin xyz="0.0020298730319310287 0.0023784169890303797 -0.09094659865497068" rpy="0 0 0"/>
    <mass value="31.73897478389843"/>
    <inertia ixx="0.129358" iyy="0.147549" izz="0.12936" ixy="0.000452" iyz="0.000486" ixz="1.2e-05"/>
  </inertial>
  <visual>
    <origin xyz="-0.978901 0.081349 0.160636" rpy="0 0 0"/>
    <geometry>
    <mesh filename="${MeshPath}/Leg2_WheelBody_1.stl" scale="0.001 0.001 0.001"/>
    </geometry>
    <material name="silver"/>
  </visual>
  <collision>
    <origin xyz="-0.978901 0.081349 0.160636" rpy="0 0 0"/>
    <geometry>
    <mesh filename="${MeshPath}/Leg2_WheelBody_1.stl" scale="0.001 0.001 0.001"/>
    </geometry>
  </collision>
</link>

<link name="Leg2_Wheel1_1">
  <inertial>
    <origin xyz="0.001275253982526925 0.05131620577462025 0.0013699132924714919" rpy="0 0 0"/>
    <mass value="25.69936736300387"/>
    <inertia ixx="0.305397" iyy="0.554754" izz="0.305421" ixy="0.0062" iyz="0.006663" ixz="0.000166"/>
  </inertial>
  <visual>
    <origin xyz="-0.982669 0.009017 0.249714" rpy="0 0 0"/>
    <geometry>
    <mesh filename="${MeshPath}/Leg2_Wheel1_1.stl" scale="0.001 0.001 0.001"/>
    </geometry>
    <material name="silver"/>
  </visual>
  <collision>
    <origin xyz="-0.982669 0.009017 0.249714" rpy="0 0 0"/>
    <geometry>
    <mesh filename="${MeshPath}/Leg2_Wheel1_1.stl" scale="0.001 0.001 0.001"/>
    </geometry>
  </collision>
</link>

<link name="Leg2_Wheel2_1">
  <inertial>
    <origin xyz="-0.001275507918660046 -0.05131637179655901 -0.001370110602411101" rpy="0 0 0"/>
    <mass value="25.69936736300387"/>
    <inertia ixx="0.305397" iyy="0.554754" izz="0.305421" ixy="0.0062" iyz="0.006663" ixz="0.000166"/>
  </inertial>
  <visual>
    <origin xyz="-0.979193 0.148924 0.253451" rpy="0 0 0"/>
    <geometry>
    <mesh filename="${MeshPath}/Leg2_Wheel2_1.stl" scale="0.001 0.001 0.001"/>
    </geometry>
    <material name="silver"/>
  </visual>
  <collision>
    <origin xyz="-0.979193 0.148924 0.253451" rpy="0 0 0"/>
    <geometry>
    <mesh filename="${MeshPath}/Leg2_Wheel2_1.stl" scale="0.001 0.001 0.001"/>
    </geometry>
  </collision>
</link>

<link name="Leg3_Wheel1_1">
  <inertial>
    <origin xyz="0.051130769013895766 -0.004440662404791462 0.0016795479724283635" rpy="0 0 0"/>
    <mass value="25.69936736300387"/>
    <inertia ixx="0.55295" iyy="0.307111" izz="0.30551" ixy="-0.021514" iyz="-0.000707" ixz="0.008136"/>
  </inertial>
  <visual>
    <origin xyz="-0.077438 -0.990038 0.403464" rpy="0 0 0"/>
    <geometry>
    <mesh filename="${MeshPath}/Leg3_Wheel1_1.stl" scale="0.001 0.001 0.001"/>
    </geometry>
    <material name="silver"/>
  </visual>
  <collision>
    <origin xyz="-0.077438 -0.990038 0.403464" rpy="0 0 0"/>
    <geometry>
    <mesh filename="${MeshPath}/Leg3_Wheel1_1.stl" scale="0.001 0.001 0.001"/>
    </geometry>
  </collision>
</link>

<link name="Leg3_Wheel2_1">
  <inertial>
    <origin xyz="-0.05113055424695584 0.004441085992996419 -0.0016795589604777783" rpy="0 0 0"/>
    <mass value="25.69936736300387"/>
    <inertia ixx="0.55295" iyy="0.307111" izz="0.30551" ixy="-0.021514" iyz="-0.000707" ixz="0.008136"/>
  </inertial>
  <visual>
    <origin xyz="0.061962 -1.002145 0.408042" rpy="0 0 0"/>
    <geometry>
    <mesh filename="${MeshPath}/Leg3_Wheel2_1.stl" scale="0.001 0.001 0.001"/>
    </geometry>
    <material name="silver"/>
  </visual>
  <collision>
    <origin xyz="0.061962 -1.002145 0.408042" rpy="0 0 0"/>
    <geometry>
    <mesh filename="${MeshPath}/Leg3_Wheel2_1.stl" scale="0.001 0.001 0.001"/>
    </geometry>
  </collision>
</link>

<link name="Leg3Hip__1__1">
  <inertial>
    <origin xyz="-3.6838461132238164e-17 0.008405156672742331 -0.00594283121891194" rpy="0 0 0"/>
    <mass value="4.8666362605472635"/>
    <inertia ixx="0.011585" iyy="0.010312" izz="0.007862" ixy="-0.0" iyz="-0.003465" ixz="-0.0"/>
  </inertial>
  <visual>
    <origin xyz="0.0 -0.161351 -0.113876" rpy="0 0 0"/>
    <geometry>
    <mesh filename="${MeshPath}/Leg3Hip__1__1.stl" scale="0.001 0.001 0.001"/>
    </geometry>
    <material name="silver"/>
  </visual>
  <collision>
    <origin xyz="0.0 -0.161351 -0.113876" rpy="0 0 0"/>
    <geometry>
    <mesh filename="${MeshPath}/Leg3Hip__1__1.stl" scale="0.001 0.001 0.001"/>
    </geometry>
  </collision>
</link>

<link name="Leg3_Roll1Link__1__1">
  <inertial>
    <origin xyz="0.004647167967986425 0.05712202276619954 -0.04039095750929763" rpy="0 0 0"/>
    <mass value="9.373863502530105"/>
    <inertia ixx="0.021275" iyy="0.015633" izz="0.0185" ixy="-0.000699" iyz="0.004055" ixz="0.000494"/>
  </inertial>
  <visual>
    <origin xyz="0.0 -0.194011 -0.090782" rpy="0 0 0"/>
    <geometry>
    <mesh filename="${MeshPath}/Leg3_Roll1Link__1__1.stl" scale="0.001 0.001 0.001"/>
    </geometry>
    <material name="silver"/>
  </visual>
  <collision>
    <origin xyz="0.0 -0.194011 -0.090782" rpy="0 0 0"/>
    <geometry>
    <mesh filename="${MeshPath}/Leg3_Roll1Link__1__1.stl" scale="0.001 0.001 0.001"/>
    </geometry>
  </collision>
</link>

<link name="Leg3_Pitch1Link__1__1">
  <inertial>
    <origin xyz="-0.020318749609983686 0.027269896487498613 0.014060405056806793" rpy="0 0 0"/>
    <mass value="1.1768921510936396"/>
    <inertia ixx="0.001986" iyy="0.002093" izz="0.002233" ixy="0.000593" iyz="-9.9e-05" ixz="0.000306"/>
  </inertial>
  <visual>
    <origin xyz="-0.05 -0.275661 -0.033047" rpy="0 0 0"/>
    <geometry>
    <mesh filename="${MeshPath}/Leg3_Pitch1Link__1__1.stl" scale="0.001 0.001 0.001"/>
    </geometry>
    <material name="silver"/>
  </visual>
  <collision>
    <origin xyz="-0.05 -0.275661 -0.033047" rpy="0 0 0"/>
    <geometry>
    <mesh filename="${MeshPath}/Leg3_Pitch1Link__1__1.stl" scale="0.001 0.001 0.001"/>
    </geometry>
  </collision>
</link>

<link name="Leg3_Roll2Link_1">
  <inertial>
    <origin xyz="0.00716606663725681 0.19314581254048974 0.09958516399856117" rpy="0 0 0"/>
    <mass value="25.903618237357847"/>
    <inertia ixx="0.471503" iyy="0.125077" izz="0.378093" ixy="-0.027193" iyz="-0.177692" ixz="-0.014021"/>
  </inertial>
  <visual>
    <origin xyz="0.002 -0.327212 -0.059627" rpy="0 0 0"/>
    <geometry>
    <mesh filename="${MeshPath}/Leg3_Roll2Link_1.stl" scale="0.001 0.001 0.001"/>
    </geometry>
    <material name="silver"/>
  </visual>
  <collision>
    <origin xyz="0.002 -0.327212 -0.059627" rpy="0 0 0"/>
    <geometry>
    <mesh filename="${MeshPath}/Leg3_Roll2Link_1.stl" scale="0.001 0.001 0.001"/>
    </geometry>
  </collision>
</link>

<link name="Leg3_Pitch1Link__2__1">
  <inertial>
    <origin xyz="-0.0071660666372587445 0.10205327034869083 -0.19793167678327578" rpy="0 0 0"/>
    <mass value="25.903618237357847"/>
    <inertia ixx="0.471503" iyy="0.378093" izz="0.125077" ixy="-0.014021" iyz="0.177692" ixz="0.027193"/>
  </inertial>
  <visual>
    <origin xyz="0.002 -0.71829 -0.261265" rpy="0 0 0"/>
    <geometry>
    <mesh filename="${MeshPath}/Leg3_Pitch1Link__2__1.stl" scale="0.001 0.001 0.001"/>
    </geometry>
    <material name="silver"/>
  </visual>
  <collision>
    <origin xyz="0.002 -0.71829 -0.261265" rpy="0 0 0"/>
    <geometry>
    <mesh filename="${MeshPath}/Leg3_Pitch1Link__2__1.stl" scale="0.001 0.001 0.001"/>
    </geometry>
  </collision>
</link>

<link name="Leg3_Roll3Link_1">
  <inertial>
    <origin xyz="-0.031063227748902432 0.006984250655333923 -0.027135310504735083" rpy="0 0 0"/>
    <mass value="1.1768921510936396"/>
    <inertia ixx="0.001997" iyy="0.002331" izz="0.001983" ixy="0.000249" iyz="1.8e-05" ixz="-0.000608"/>
  </inertial>
  <visual>
    <origin xyz="0.002 -0.919929 0.129812" rpy="0 0 0"/>
    <geometry>
    <mesh filename="${MeshPath}/Leg3_Roll3Link_1.stl" scale="0.001 0.001 0.001"/>
    </geometry>
    <material name="silver"/>
  </visual>
  <collision>
    <origin xyz="0.002 -0.919929 0.129812" rpy="0 0 0"/>
    <geometry>
    <mesh filename="${MeshPath}/Leg3_Roll3Link_1.stl" scale="0.001 0.001 0.001"/>
    </geometry>
  </collision>
</link>

<link name="Leg3_Pitch2_Link_1">
  <inertial>
    <origin xyz="0.04594586795408963 0.014227756571079997 -0.024224598691337224" rpy="0 0 0"/>
    <mass value="9.373863502530105"/>
    <inertia ixx="0.021171" iyy="0.020895" izz="0.013343" ixy="-0.000301" iyz="0.001948" ixz="0.001233"/>
  </inertial>
  <visual>
    <origin xyz="0.052986 -0.937424 0.186047" rpy="0 0 0"/>
    <geometry>
    <mesh filename="${MeshPath}/Leg3_Pitch2_Link_1.stl" scale="0.001 0.001 0.001"/>
    </geometry>
    <material name="silver"/>
  </visual>
  <collision>
    <origin xyz="0.052986 -0.937424 0.186047" rpy="0 0 0"/>
    <geometry>
    <mesh filename="${MeshPath}/Leg3_Pitch2_Link_1.stl" scale="0.001 0.001 0.001"/>
    </geometry>
  </collision>
</link>

<link name="Leg3_Ankle_1">
  <inertial>
    <origin xyz="0.0015110410800645015 0.0064488389379586675 -0.02895873153642703" rpy="0 0 0"/>
    <mass value="4.8666362605472635"/>
    <inertia ixx="0.011552" iyy="0.005804" izz="0.012404" ixy="-0.00045" iyz="-0.001573" ixz="-0.000164"/>
  </inertial>
  <visual>
    <origin xyz="-0.001074 -0.967652 0.278051" rpy="0 0 0"/>
    <geometry>
    <mesh filename="${MeshPath}/Leg3_Ankle_1.stl" scale="0.001 0.001 0.001"/>
    </geometry>
    <material name="silver"/>
  </visual>
  <collision>
    <origin xyz="-0.001074 -0.967652 0.278051" rpy="0 0 0"/>
    <geometry>
    <mesh filename="${MeshPath}/Leg3_Ankle_1.stl" scale="0.001 0.001 0.001"/>
    </geometry>
  </collision>
</link>

<link name="Leg3_WheelBody_1">
  <inertial>
    <origin xyz="0.004629107383469366 0.019755711794100184 -0.08870900549402344" rpy="0 0 0"/>
    <mass value="31.73897478389843"/>
    <inertia ixx="0.147417" iyy="0.129483" izz="0.129366" ixy="-0.001569" iyz="-5.2e-05" ixz="0.000594"/>
  </inertial>
  <visual>
    <origin xyz="-0.003109 -0.976336 0.317044" rpy="0 0 0"/>
    <geometry>
    <mesh filename="${MeshPath}/Leg3_WheelBody_1.stl" scale="0.001 0.001 0.001"/>
    </geometry>
    <material name="silver"/>
  </visual>
  <collision>
    <origin xyz="-0.003109 -0.976336 0.317044" rpy="0 0 0"/>
    <geometry>
    <mesh filename="${MeshPath}/Leg3_WheelBody_1.stl" scale="0.001 0.001 0.001"/>
    </geometry>
  </collision>
</link>

<link name="Leg4_Hip_2">
  <inertial>
    <origin xyz="-0.008405156672741665 1.9617480655863313e-17 -0.00594283121891169" rpy="0 0 0"/>
    <mass value="4.8666362605472635"/>
    <inertia ixx="0.010312" iyy="0.011585" izz="0.007862" ixy="0.0" iyz="-0.0" ixz="0.003465"/>
  </inertial>
  <visual>
    <origin xyz="0.161351 -0.0 -0.113876" rpy="0 0 0"/>
    <geometry>
    <mesh filename="${MeshPath}/Leg4_Hip_2.stl" scale="0.001 0.001 0.001"/>
    </geometry>
    <material name="silver"/>
  </visual>
  <collision>
    <origin xyz="0.161351 -0.0 -0.113876" rpy="0 0 0"/>
    <geometry>
    <mesh filename="${MeshPath}/Leg4_Hip_2.stl" scale="0.001 0.001 0.001"/>
    </geometry>
  </collision>
</link>

<link name="Leg4_Roll1Link_2">
  <inertial>
    <origin xyz="-0.057122022766198655 0.00464716796798661 -0.04039095750929729" rpy="0 0 0"/>
    <mass value="9.373863502530105"/>
    <inertia ixx="0.015633" iyy="0.021275" izz="0.0185" ixy="0.000699" iyz="0.000494" ixz="-0.004055"/>
  </inertial>
  <visual>
    <origin xyz="0.194011 0.0 -0.090782" rpy="0 0 0"/>
    <geometry>
    <mesh filename="${MeshPath}/Leg4_Roll1Link_2.stl" scale="0.001 0.001 0.001"/>
    </geometry>
    <material name="silver"/>
  </visual>
  <collision>
    <origin xyz="0.194011 0.0 -0.090782" rpy="0 0 0"/>
    <geometry>
    <mesh filename="${MeshPath}/Leg4_Roll1Link_2.stl" scale="0.001 0.001 0.001"/>
    </geometry>
  </collision>
</link>

<link name="Leg4_Pitch1Link_2">
  <inertial>
    <origin xyz="-0.027509586732636537 -0.019318769269816797 0.015713974924805786" rpy="0 0 0"/>
    <mass value="1.1768921510936396"/>
    <inertia ixx="0.002059" iyy="0.002042" izz="0.002211" ixy="-0.00058" iyz="0.000331" ixz="0.000129"/>
  </inertial>
  <visual>
    <origin xyz="0.275661 -0.05 -0.033047" rpy="0 0 0"/>
    <geometry>
    <mesh filename="${MeshPath}/Leg4_Pitch1Link_2.stl" scale="0.001 0.001 0.001"/>
    </geometry>
    <material name="silver"/>
  </visual>
  <collision>
    <origin xyz="0.275661 -0.05 -0.033047" rpy="0 0 0"/>
    <geometry>
    <mesh filename="${MeshPath}/Leg4_Pitch1Link_2.stl" scale="0.001 0.001 0.001"/>
    </geometry>
  </collision>
</link>

<link name="Leg4_Roll2Link_2">
  <inertial>
    <origin xyz="-0.1886934850878263 0.007166066637257675 0.10778413811123652" rpy="0 0 0"/>
    <mass value="25.903618237357847"/>
    <inertia ixx="0.140783" iyy="0.471503" izz="0.362387" ixy="0.026566" iyz="-0.015175" ixz="0.187888"/>
  </inertial>
  <visual>
    <origin xyz="0.32776 -0.0 -0.062807" rpy="0 0 0"/>
    <geometry>
    <mesh filename="${MeshPath}/Leg4_Roll2Link_2.stl" scale="0.001 0.001 0.001"/>
    </geometry>
    <material name="silver"/>
  </visual>
  <collision>
    <origin xyz="0.32776 -0.0 -0.062807" rpy="0 0 0"/>
    <geometry>
    <mesh filename="${MeshPath}/Leg4_Roll2Link_2.stl" scale="0.001 0.001 0.001"/>
    </geometry>
  </collision>
</link>

<link name="Leg4_Pitch2Link_2">
  <inertial>
    <origin xyz="-0.11045492471027696 -0.0071660666372565 -0.19336889504461097" rpy="0 0 0"/>
    <mass value="25.903618237357847"/>
    <inertia ixx="0.362387" iyy="0.471503" izz="0.140783" ixy="0.015175" iyz="0.026566" ixz="-0.187888"/>
  </inertial>
  <visual>
    <origin xyz="0.709823 -0.0 -0.281046" rpy="0 0 0"/>
    <geometry>
    <mesh filename="${MeshPath}/Leg4_Pitch2Link_2.stl" scale="0.001 0.001 0.001"/>
    </geometry>
    <material name="silver"/>
  </visual>
  <collision>
    <origin xyz="0.709823 -0.0 -0.281046" rpy="0 0 0"/>
    <geometry>
    <mesh filename="${MeshPath}/Leg4_Pitch2Link_2.stl" scale="0.001 0.001 0.001"/>
    </geometry>
  </collision>
</link>

<link name="Leg4_Roll3Link_2">
  <inertial>
    <origin xyz="-0.01404608992027001 0.030681230730184507 -0.02458979224391325" rpy="0 0 0"/>
    <mass value="1.1768921510936396"/>
    <inertia ixx="0.002211" iyy="0.002042" izz="0.002059" ixy="0.000331" iyz="0.00058" ixz="-0.000129"/>
  </inertial>
  <visual>
    <origin xyz="0.928062 -0.0 0.101016" rpy="0 0 0"/>
    <geometry>
    <mesh filename="${MeshPath}/Leg4_Roll3Link_2.stl" scale="0.001 0.001 0.001"/>
    </geometry>
    <material name="silver"/>
  </visual>
  <collision>
    <origin xyz="0.928062 -0.0 0.101016" rpy="0 0 0"/>
    <geometry>
    <mesh filename="${MeshPath}/Leg4_Roll3Link_2.stl" scale="0.001 0.001 0.001"/>
    </geometry>
  </collision>
</link>

<link name="Leg4_Pitch3Link_2">
  <inertial>
    <origin xyz="-0.014899994618079448 -0.04535283203201122 -0.026085269441935233" rpy="0 0 0"/>
    <mass value="9.373863502530105"/>
    <inertia ixx="0.019252" iyy="0.021275" izz="0.014882" ixy="-0.000425" iyz="-0.000743" ixz="-0.003705"/>
  </inertial>
  <visual>
    <origin xyz="0.957822 -0.05 0.153115" rpy="0 0 0"/>
    <geometry>
    <mesh filename="${MeshPath}/Leg4_Pitch3Link_2.stl" scale="0.001 0.001 0.001"/>
    </geometry>
    <material name="silver"/>
  </visual>
  <collision>
    <origin xyz="0.957822 -0.05 0.153115" rpy="0 0 0"/>
    <geometry>
    <mesh filename="${MeshPath}/Leg4_Pitch3Link_2.stl" scale="0.001 0.001 0.001"/>
    </geometry>
  </collision>
</link>

<link name="Leg4_Ankle_2">
  <inertial>
    <origin xyz="-0.014734128653511647 -3.6429025640361847e-07 -0.025794496275879986" rpy="0 0 0"/>
    <mass value="4.8666362605472635"/>
    <inertia ixx="0.00722" iyy="0.011585" izz="0.010954" ixy="-0.0" iyz="0.0" ixz="0.003166"/>
  </inertial>
  <visual>
    <origin xyz="1.007422 -2e-06 0.239948" rpy="0 0 0"/>
    <geometry>
    <mesh filename="${MeshPath}/Leg4_Ankle_2.stl" scale="0.001 0.001 0.001"/>
    </geometry>
    <material name="silver"/>
  </visual>
  <collision>
    <origin xyz="1.007422 -2e-06 0.239948" rpy="0 0 0"/>
    <geometry>
    <mesh filename="${MeshPath}/Leg4_Ankle_2.stl" scale="0.001 0.001 0.001"/>
    </geometry>
  </collision>
</link>

<link name="Leg4_WheelBody_2">
  <inertial>
    <origin xyz="-0.04513557964675363 -3.642902557612329e-07 -0.07901707219497817" rpy="0 0 0"/>
    <mass value="31.73897478389843"/>
    <inertia ixx="0.129347" iyy="0.147573" izz="0.129347" ixy="0.0" iyz="0.0" ixz="0.0"/>
  </inertial>
  <visual>
    <origin xyz="1.027262 -2e-06 0.274681" rpy="0 0 0"/>
    <geometry>
    <mesh filename="${MeshPath}/Leg4_WheelBody_2.stl" scale="0.001 0.001 0.001"/>
    </geometry>
    <material name="silver"/>
  </visual>
  <collision>
    <origin xyz="1.027262 -2e-06 0.274681" rpy="0 0 0"/>
    <geometry>
    <mesh filename="${MeshPath}/Leg4_WheelBody_2.stl" scale="0.001 0.001 0.001"/>
    </geometry>
  </collision>
</link>

<link name="Leg4_Wheel1_2">
  <inertial>
    <origin xyz="4.203532466551252e-07 0.05135007904015869 -7.219497949462195e-08" rpy="0 0 0"/>
    <mass value="25.69936736300387"/>
    <inertia ixx="0.305243" iyy="0.555086" izz="0.305243" ixy="-0.0" iyz="0.0" ixz="0.0"/>
  </inertial>
  <visual>
    <origin xyz="1.072398 -0.070002 0.353698" rpy="0 0 0"/>
    <geometry>
    <mesh filename="${MeshPath}/Leg4_Wheel1_2.stl" scale="0.001 0.001 0.001"/>
    </geometry>
    <material name="silver"/>
  </visual>
  <collision>
    <origin xyz="1.072398 -0.070002 0.353698" rpy="0 0 0"/>
    <geometry>
    <mesh filename="${MeshPath}/Leg4_Wheel1_2.stl" scale="0.001 0.001 0.001"/>
    </geometry>
  </collision>
</link>

<link name="Leg4_Wheel2_2">
  <inertial>
    <origin xyz="4.203532470992144e-07 -0.05135080762066993 -7.21949772741759e-08" rpy="0 0 0"/>
    <mass value="25.69936736300387"/>
    <inertia ixx="0.305243" iyy="0.555086" izz="0.305243" ixy="0.0" iyz="-0.0" ixz="0.0"/>
  </inertial>
  <visual>
    <origin xyz="1.072398 0.069998 0.353698" rpy="0 0 0"/>
    <geometry>
    <mesh filename="${MeshPath}/Leg4_Wheel2_2.stl" scale="0.001 0.001 0.001"/>
    </geometry>
    <material name="silver"/>
  </visual>
  <collision>
    <origin xyz="1.072398 0.069998 0.353698" rpy="0 0 0"/>
    <geometry>
    <mesh filename="${MeshPath}/Leg4_Wheel2_2.stl" scale="0.001 0.001 0.001"/>
    </geometry>
  </collision>
</link>

<joint name="Rigid 33" type="fixed">
  <origin xyz="0.0 -0.161351 0.113876" rpy="0 0 0"/>
  <parent link="base_link"/>
  <child link="LegHip_2"/>
</joint>

<joint name="Revolute 34" type="continuous">
<!-- <origin xyz="0.0 -0.03266 -0.023094" rpy="${0 * 3.14 / 180} ${0 * 3.14 / 180} ${0 * 3.14 / 180}"/> -->
  <origin xyz="0.0 -0.03266 -0.023094" rpy="0.0 -0.0 -0.0"/>
  <parent link="LegHip_2"/>
  <child link="LegRoll1Link_2"/>
  <!-- <axis xyz="0.0 0.0 1.0"/> -->
  <axis xyz="0.0 -0.816497 -0.57735"/>
</joint>
<!-- [ik_heavy_node-4] │   0 │ link0  │     0 │ BASE   │ SE3(0, -0.1614, 0.1139) ⊕ SE3(0, -0.03266, -0.02309; 17.35°, -43.4°, -41.96°) ⊕ Rz(q0) │ -->

<joint name="Revolute 35" type="continuous">
  <origin xyz="-0.05 -0.08165 -0.057735" rpy="0 0 0"/>
  <parent link="LegRoll1Link_2"/>
  <child link="MH_L-shaped_link_v6_2"/>
  <axis xyz="-1.0 -0.0 -0.0"/>
</joint>

<joint name="Revolute 36" type="continuous">
  <origin xyz="0.05 -0.045769 0.037232" rpy="0 0 0"/>
  <parent link="MH_L-shaped_link_v6_2"/>
  <child link="LegPitch1Link_2"/>
  <axis xyz="0.0 -0.775748 0.631042"/>
</joint>

<joint name="Revolute 37" type="continuous">
  <origin xyz="0.0 -0.341329 0.277658" rpy="0 0 0"/>
  <parent link="LegPitch1Link_2"/>
  <child link="LegPitch2Link_2"/>
  <axis xyz="0.991919 -0.08006 -0.098419"/>
</joint>

<joint name="Revolute 38" type="continuous">
  <origin xyz="-0.050049 -0.095755 -0.426528" rpy="0 0 0"/>
  <parent link="LegPitch2Link_2"/>
  <child link="LegRoll2Link_2"/>
  <axis xyz="-0.113747 -0.217624 -0.969382"/>
</joint>

<joint name="Revolute 39" type="continuous">
  <origin xyz="-0.054645 0.001348 -0.055785" rpy="0 0 0"/>
  <parent link="LegRoll2Link_2"/>
  <child link="LegPitch3Link_2"/>
  <axis xyz="0.956416 -0.288112 -0.047545"/>
</joint>

<joint name="Revolute 40" type="continuous">
  <origin xyz="0.043794 -0.01129 -0.102248" rpy="0 0 0"/>
  <parent link="LegPitch3Link_2"/>
  <child link="LegAnkle_2"/>
  <axis xyz="-0.040264 0.031151 -0.998703"/>
</joint>

<joint name="Rigid 41" type="fixed">
  <origin xyz="-0.001611 0.001246 -0.039948" rpy="0 0 0"/>
  <parent link="LegAnkle_2"/>
  <child link="LegWheelBody_2"/>
</joint>

<joint name="Revolute 42" type="continuous">
  <origin xyz="-0.023909 -0.064162 -0.092156" rpy="0 0 0"/>
  <parent link="LegWheelBody_2"/>
  <child link="LegWheel1_2"/>
  <axis xyz="-0.28922 -0.95709 -0.018192"/>
</joint>

<joint name="Revolute 43" type="continuous">
  <origin xyz="0.016582 0.069831 -0.089609" rpy="0 0 0"/>
  <parent link="LegWheelBody_2"/>
  <child link="LegWheel2_2"/>
  <axis xyz="0.28922 0.95709 0.018192"/>
</joint>

<joint name="Rigid 77" type="fixed">
  <origin xyz="0.0 0.0 0.457237" rpy="0 0 0"/>
  <parent link="base_link"/>
  <child link="Arm_Hip_2"/>
</joint>

<joint name="Revolute 78" type="continuous">
  <origin xyz="0.0 0.0 0.04" rpy="0 0 0"/>
  <parent link="Arm_Hip_2"/>
  <child link="Arm_Roll1Link_2"/>
  <axis xyz="-0.0 0.0 1.0"/>
</joint>

<joint name="Revolute 79" type="continuous">
  <origin xyz="-0.05 0.0 0.1" rpy="0 0 0"/>
  <parent link="Arm_Roll1Link_2"/>
  <child link="Arm_Pitch1Link_2"/>
  <axis xyz="-1.0 0.0 -0.0"/>
</joint>

<joint name="Revolute 80" type="continuous">
  <origin xyz="0.05 0.0 0.06" rpy="0 0 0"/>
  <parent link="Arm_Pitch1Link_2"/>
  <child link="Arm_Pitch2Link_2"/>
  <axis xyz="-0.0 -0.0 1.0"/>
</joint>

<joint name="Revolute 81" type="continuous">
  <origin xyz="-0.0 -0.0 0.44" rpy="0 0 0"/>
  <parent link="Arm_Pitch2Link_2"/>
  <child link="Arm_Pitch3Link_2"/>
  <axis xyz="0.0 -1.0 0.0"/>
</joint>

<joint name="Revolute 82" type="continuous">
  <origin xyz="0.44 0.0 0.0" rpy="0 0 0"/>
  <parent link="Arm_Pitch3Link_2"/>
  <child link="Arm_Roll2Link_2"/>
  <axis xyz="1.0 0.0 -0.0"/>
</joint>

<joint name="Revolute 83" type="continuous">
  <origin xyz="0.06 0.04981 -0.004357" rpy="0 0 0"/>
  <parent link="Arm_Roll2Link_2"/>
  <child link="Arm_Pitch4Link_2"/>
  <axis xyz="0.0 -0.996195 0.087156"/>
</joint>

<joint name="Revolute 84" type="continuous">
  <origin xyz="0.0 -0.058526 -0.095262" rpy="0 0 0"/>
  <parent link="Arm_Pitch4Link_2"/>
  <child link="Hand_2"/>
  <axis xyz="-0.0 -0.087156 -0.996195"/>
</joint>

<joint name="Rigid 96" type="fixed">
  <origin xyz="0.161351 0.0 0.113876" rpy="0 0 0"/>
  <parent link="base_link"/>
  <child link="Leg1Hip_1"/>
</joint>

<joint name="Revolute 97" type="continuous">
  <origin xyz="0.03266 0.0 -0.023094" rpy="0 0 0"/>
  <parent link="Leg1Hip_1"/>
  <child link="Leg2_Roll1Link_1"/>
  <axis xyz="0.816497 0.0 -0.57735"/>
</joint>

<joint name="Revolute 98" type="continuous">
  <origin xyz="0.083868 -0.049852 -0.054599" rpy="0 0 0"/>
  <parent link="Leg2_Roll1Link_1"/>
  <child link="Leg2_Pitch1Link_1"/>
  <axis xyz="0.044353 -0.997045 0.062724"/>
</joint>

<joint name="Revolute 99" type="continuous">
  <origin xyz="0.044104 0.054295 0.034739" rpy="0 0 0"/>
  <parent link="Leg2_Pitch1Link_1"/>
  <child link="Leg2_Roll2Link_1"/>
  <axis xyz="0.772036 0.074056 0.63125"/>
</joint>

<joint name="Revolute 100" type="continuous">
  <origin xyz="0.339696 0.032585 0.27775" rpy="0 0 0"/>
  <parent link="Leg2_Roll2Link_1"/>
  <child link="Leg2_Pitch2Link_1"/>
  <axis xyz="0.099361 0.966914 -0.234955"/>
</joint>

<joint name="Revolute 101" type="continuous">
  <origin xyz="0.276406 -0.107393 -0.325064" rpy="0 0 0"/>
  <parent link="Leg2_Pitch2Link_1"/>
  <child link="Leg2_Roll3Link_1"/>
  <axis xyz="0.628195 -0.244074 -0.738782"/>
</joint>

<joint name="Revolute 102" type="continuous">
  <origin xyz="0.057455 0.031255 -0.042686" rpy="0 0 0"/>
  <parent link="Leg2_Roll3Link_1"/>
  <child link="Leg2_Pitch3Link_1"/>
  <axis xyz="-0.395272 -0.917977 -0.032829"/>
</joint>

<joint name="Revolute 103" type="continuous">
  <origin xyz="-0.017532 -0.043284 -0.101582" rpy="0 0 0"/>
  <parent link="Leg2_Pitch3Link_1"/>
  <child link="Leg2_Ankle_1"/>
  <axis xyz="0.022311 0.026135 -0.999409"/>
</joint>

<joint name="Rigid 104" type="fixed">
  <origin xyz="0.000893 0.001045 -0.039976" rpy="0 0 0"/>
  <parent link="Leg2_Ankle_1"/>
  <child link="Leg2_WheelBody_1"/>
</joint>

<joint name="Revolute 105" type="continuous">
  <origin xyz="0.003768 0.072332 -0.089078" rpy="0 0 0"/>
  <parent link="Leg2_WheelBody_1"/>
  <child link="Leg2_Wheel1_1"/>
  <axis xyz="0.024832 0.999335 0.026687"/>
</joint>

<joint name="Revolute 106" type="continuous">
  <origin xyz="0.000292 -0.067575 -0.092815" rpy="0 0 0"/>
  <parent link="Leg2_WheelBody_1"/>
  <child link="Leg2_Wheel2_1"/>
  <axis xyz="-0.024832 -0.999335 -0.026687"/>
</joint>

<joint name="Revolute 116" type="continuous">
  <origin xyz="0.074329 0.013702 -0.08642" rpy="0 0 0"/>
  <parent link="Leg3_WheelBody_1"/>
  <child link="Leg3_Wheel1_1"/>
  <axis xyz="0.995717 -0.08648 0.032703"/>
</joint>

<joint name="Revolute 117" type="continuous">
  <origin xyz="-0.065071 0.025809 -0.090998" rpy="0 0 0"/>
  <parent link="Leg3_WheelBody_1"/>
  <child link="Leg3_Wheel2_1"/>
  <axis xyz="-0.995717 0.08648 -0.032703"/>
</joint>

<joint name="Rigid 118" type="fixed">
  <origin xyz="0.0 0.161351 0.113876" rpy="0 0 0"/>
  <parent link="base_link"/>
  <child link="Leg3Hip__1__1"/>
</joint>

<joint name="Revolute 119" type="continuous">
  <origin xyz="0.0 0.03266 -0.023094" rpy="0 0 0"/>
  <parent link="Leg3Hip__1__1"/>
  <child link="Leg3_Roll1Link__1__1"/>
  <axis xyz="-0.0 0.816497 -0.57735"/>
</joint>

<joint name="Revolute 120" type="continuous">
  <origin xyz="0.05 0.08165 -0.057735" rpy="0 0 0"/>
  <parent link="Leg3_Roll1Link__1__1"/>
  <child link="Leg3_Pitch1Link__1__1"/>
  <axis xyz="1.0 0.0 -0.0"/>
</joint>

<joint name="Revolute 121" type="continuous">
  <origin xyz="-0.052 0.051551 0.02658" rpy="0 0 0"/>
  <parent link="Leg3_Pitch1Link__1__1"/>
  <child link="Leg3_Roll2Link_1"/>
  <axis xyz="-0.0 0.888813 0.45827"/>
</joint>

<joint name="Revolute 122" type="continuous">
  <origin xyz="0.0 0.391078 0.201638" rpy="0 0 0"/>
  <parent link="Leg3_Roll2Link_1"/>
  <child link="Leg3_Pitch1Link__2__1"/>
  <axis xyz="-1.0 -0.0 0.0"/>
</joint>

<joint name="Revolute 123" type="continuous">
  <origin xyz="0.0 0.201639 -0.391077" rpy="0 0 0"/>
  <parent link="Leg3_Pitch1Link__2__1"/>
  <child link="Leg3_Roll3Link_1"/>
  <axis xyz="-0.0 0.45827 -0.888813"/>
</joint>

<joint name="Revolute 124" type="continuous">
  <origin xyz="-0.050986 0.017495 -0.056235" rpy="0 0 0"/>
  <parent link="Leg3_Roll3Link_1"/>
  <child link="Leg3_Pitch2_Link_1"/>
  <axis xyz="0.980492 0.174702 0.090076"/>
</joint>

<joint name="Revolute 125" type="continuous">
  <origin xyz="0.05406 0.030228 -0.092004" rpy="0 0 0"/>
  <parent link="Leg3_Pitch2_Link_1"/>
  <child link="Leg3_Ankle_1"/>
  <axis xyz="0.050873 0.2171 -0.974823"/>
</joint>

<joint name="Rigid 126" type="fixed">
  <origin xyz="0.002035 0.008684 -0.038993" rpy="0 0 0"/>
  <parent link="Leg3_Ankle_1"/>
  <child link="Leg3_WheelBody_1"/>
</joint>

<joint name="Rigid 127" type="fixed">
  <origin xyz="-0.161351 0.0 0.113876" rpy="0 0 0"/>
  <parent link="base_link"/>
  <child link="Leg4_Hip_2"/>
</joint>

<joint name="Revolute 128" type="continuous">
  <origin xyz="-0.03266 -0.0 -0.023094" rpy="0 0 0"/>
  <parent link="Leg4_Hip_2"/>
  <child link="Leg4_Roll1Link_2"/>
  <axis xyz="-0.816497 -0.0 -0.57735"/>
</joint>

<joint name="Revolute 129" type="continuous">
  <origin xyz="-0.08165 0.05 -0.057735" rpy="0 0 0"/>
  <parent link="Leg4_Roll1Link_2"/>
  <child link="Leg4_Pitch1Link_2"/>
  <axis xyz="0.0 1.0 0.0"/>
</joint>

<joint name="Revolute 130" type="continuous">
  <origin xyz="-0.052099 -0.05 0.02976" rpy="0 0 0"/>
  <parent link="Leg4_Pitch1Link_2"/>
  <child link="Leg4_Roll2Link_2"/>
  <axis xyz="-0.868323 0.0 0.495998"/>
</joint>

<joint name="Revolute 131" type="continuous">
  <origin xyz="-0.382063 0.0 0.218239" rpy="0 0 0"/>
  <parent link="Leg4_Roll2Link_2"/>
  <child link="Leg4_Pitch2Link_2"/>
  <axis xyz="-0.0 -1.0 -0.0"/>
</joint>

<joint name="Revolute 132" type="continuous">
  <origin xyz="-0.218239 0.0 -0.382062" rpy="0 0 0"/>
  <parent link="Leg4_Pitch2Link_2"/>
  <child link="Leg4_Roll3Link_2"/>
  <axis xyz="-0.495998 0.0 -0.868323"/>
</joint>

<joint name="Revolute 133" type="continuous">
  <origin xyz="-0.02976 0.05 -0.052099" rpy="0 0 0"/>
  <parent link="Leg4_Roll3Link_2"/>
  <child link="Leg4_Pitch3Link_2"/>
  <axis xyz="-0.0 -1.0 -0.0"/>
</joint>

<joint name="Revolute 134" type="continuous">
  <origin xyz="-0.0496 -0.049998 -0.086833" rpy="0 0 0"/>
  <parent link="Leg4_Pitch3Link_2"/>
  <child link="Leg4_Ankle_2"/>
  <axis xyz="-0.495998 0.0 -0.868323"/>
</joint>

<joint name="Rigid 135" type="fixed">
  <origin xyz="-0.01984 0.0 -0.034733" rpy="0 0 0"/>
  <parent link="Leg4_Ankle_2"/>
  <child link="Leg4_WheelBody_2"/>
</joint>

<joint name="Revolute 136" type="continuous">
  <origin xyz="-0.045136 0.07 -0.079017" rpy="0 0 0"/>
  <parent link="Leg4_WheelBody_2"/>
  <child link="Leg4_Wheel1_2"/>
  <axis xyz="0.0 1.0 0.0"/>
</joint>

<joint name="Revolute 137" type="continuous">
  <origin xyz="-0.045136 -0.07 -0.079017" rpy="0 0 0"/>
  <parent link="Leg4_WheelBody_2"/>
  <child link="Leg4_Wheel2_2"/>
  <axis xyz="-0.0 -1.0 -0.0"/>
</joint>

</robot>
