<?xml version="1.0" encoding="UTF-8"?>
<robot name="mg_limb_4dof" xmlns:xacro="http://www.ros.org/wiki/xacro">

  <xacro:property name="ThisPackage" value="urdf_packer"></xacro:property>
  <xacro:property name="Filename" value="mg_limb_4dof"></xacro:property>
  <xacro:property name="UrdfDataPath" value="package://${ThisPackage}/urdf/${Filename}"></xacro:property>
  <xacro:property name="MeshPath" value="package://${ThisPackage}/meshes/${Filename}"></xacro:property>

  <link name="base_link">
    <inertial>
      <origin rpy="0 0 0" xyz="-6.32702240353629E-08 -7.45234971540242E-08 0.00277450409037011"></origin>
      <mass value="0.0239385159475204"></mass>
      <inertia ixx="7.90024876786918E-06" ixy="-2.25571527007123E-11" ixz="1.07174398977376E-11" iyy="7.90024552384554E-06" iyz="1.2249303307814E-11" izz="1.53938321724266E-05"></inertia>
    </inertial>
    <visual>
      <origin rpy="0 0 0" xyz="0 0 0"></origin>
      <geometry>
        <mesh filename="${MeshPath}/eef1_link.STL"></mesh>
      </geometry>
      <material name="">
        <color rgba="0.792156862745098 0.819607843137255 0.933333333333333 1"></color>
      </material>
    </visual>
    <collision>
      <origin rpy="0 0 0" xyz="0 0 0"></origin>
      <geometry>
        <mesh filename="${MeshPath}/eef1_link.STL"></mesh>
      </geometry>
    </collision>
  </link>
  <link name="link1">
    <inertial>
      <origin rpy="0 0 0" xyz="0.0285672301339123 -0.000366343505554881 0.164586028597064"></origin>
      <mass value="1.14707763162049"></mass>
      <inertia ixx="0.00466122883321823" ixy="-4.86701441683876E-06" ixz="-0.00026511894805086" iyy="0.00406432511720851" iyz="1.0731532031594E-05" izz="0.00310046817291436"></inertia>
    </inertial>
    <visual>
      <origin rpy="0 0 0" xyz="0 0 0"></origin>
      <geometry>
      <mesh filename="${MeshPath}/link1.STL"></mesh>
      </geometry>
      <material name="">
        <color rgba="0.792156862745098 0.819607843137255 0.933333333333333 1"></color>
      </material>
    </visual>
    <collision>
      <origin rpy="0 0 0" xyz="0 0 0"></origin>
      <geometry>
        <mesh filename="${MeshPath}/link1.STL"></mesh>
      </geometry>
    </collision>
  </link>
  <joint name="joint1" type="revolute">
    <origin rpy="0 0 0" xyz="0 0 0"></origin>
    <parent link="base_link"></parent>
    <child link="link1"></child>
    <axis xyz="0 0 -1"></axis>
    <limit effort="10.0" lower="-3.14159265358979" upper="3.14159265358979" velocity="10.0"></limit>
  </joint>
  <link name="link2">
    <inertial>
      <origin rpy="0 0 0" xyz="-0.0334732916129275 0.00204666366161849 -0.0892977524194901"></origin>
      <mass value="1.44966543806477"></mass>
      <inertia ixx="0.00449231081823489" ixy="-0.000103296473438572" ixz="-0.00012484349658756" iyy="0.00614737212859449" iyz="7.97206026823848E-06" izz="0.00652980679345959"></inertia>
    </inertial>
    <visual>
      <origin rpy="0 0 0" xyz="0 0 0"></origin>
      <geometry>
        <mesh filename="${MeshPath}/link2.STL"></mesh>
      </geometry>
      <material name="">
        <color rgba="0.792156862745098 0.819607843137255 0.933333333333333 1"></color>
      </material>
    </visual>
    <collision>
      <origin rpy="0 0 0" xyz="0 0 0"></origin>
      <geometry>
        <mesh filename="${MeshPath}/link2.STL"></mesh>
      </geometry>
    </collision>
  </link>
  <joint name="joint2" type="revolute">
    <origin rpy="0 1.5707963267949 0" xyz="-0.0825000000000035 0 0.207099999999996"></origin>
    <parent link="link1"></parent>
    <child link="link2"></child>
    <axis xyz="0 0 -1"></axis>
    <limit effort="10.0" lower="-3.14159265358979" upper="3.14159265358979" velocity="10.0"></limit>
  </joint>
  <link name="link3">
    <inertial>
      <origin rpy="0 0 0" xyz="0.00769647295275289 0.00191505338790561 0.172198455769819"></origin>
      <mass value="3.10370671744126"></mass>
      <inertia ixx="0.0149380739622292" ixy="-2.96038534846583E-05" ixz="0.000314341638704582" iyy="0.0146542323118176" iyz="-0.000473825175379418" izz="0.00929241067367723"></inertia>
    </inertial>
    <visual>
      <origin rpy="0 0 0" xyz="0 0 0"></origin>
      <geometry>
        <mesh filename="${MeshPath}/link3.STL"></mesh>
      </geometry>
      <material name="">
        <color rgba="0.792156862745098 0.819607843137255 0.933333333333333 1"></color>
      </material>
    </visual>
    <collision>
      <origin rpy="0 0 0" xyz="0 0 0"></origin>
      <geometry>
        <mesh filename="${MeshPath}/link3.STL"></mesh>
      </geometry>
    </collision>
  </link>
  <joint name="joint3" type="revolute">
    <origin rpy="3.14159265358979 1.5707963267949 0" xyz="-0.207100000000004 0 -0.0725999999999924"></origin>
    <parent link="link2"></parent>
    <child link="link3"></child>
    <axis xyz="0 0 1"></axis>
    <limit effort="10.0" lower="-3.14159265358979" upper="3.14159265358979" velocity="10.0"></limit>
  </joint>
  <link name="link4">
    <inertial>
      <origin rpy="0 0 0" xyz="-0.0699071069442022 -0.000127322361395695 0.101848050831432"></origin>
      <mass value="1.69580215708747"></mass>
      <inertia ixx="0.004771676335146" ixy="-6.64219834590732E-06" ixz="-0.00049024765824555" iyy="0.00769631542114103" iyz="-4.4614000358848E-06" izz="0.00817084465324831"></inertia>
    </inertial>
    <visual>
      <origin rpy="0 0 0" xyz="0 0 0"></origin>
      <geometry>
        <mesh filename="${MeshPath}/link4.STL"></mesh>
      </geometry>
      <material name="">
        <color rgba="0.792156862745098 0.819607843137255 0.933333333333333 1"></color>
      </material>
    </visual>
    <collision>
      <origin rpy="0 0 0" xyz="0 0 0"></origin>
      <geometry>
        <mesh filename="${MeshPath}/link4.STL"></mesh>
      </geometry>
    </collision>
  </link>
  <joint name="joint4" type="revolute">
    <origin rpy="3.14159265358979 1.5707963267949 0" xyz="-0.0726000000000013 0 0.302600000000001"></origin>
    <parent link="link3"></parent>
    <child link="link4"></child>
    <axis xyz="0 0 -1"></axis>
    <limit effort="10.0" lower="-3.14159265358979" upper="3.14159265358979" velocity="10.0"></limit>
  </joint>
  <link name="EndEff">
    <inertial>
      <origin rpy="0 0 0" xyz="9.38389896196718E-19 2.80895307050019E-19 0.0520505903469446"></origin>
      <mass value="1.12222465090096"></mass>
      <inertia ixx="0.00289504434830875" ixy="3.39975378002115E-19" ixz="1.7079151286922E-21" iyy="0.00289504434830875" iyz="-8.64164153229198E-20" izz="0.00327149822638556"></inertia>
    </inertial>
    <visual>
      <origin rpy="0 0 0" xyz="0 0 0"></origin>
      <geometry>
        <mesh filename="${MeshPath}/eef2_link.STL"></mesh>
      </geometry>
      <material name="">
        <color rgba="1 1 1 1"></color>
      </material>
    </visual>
    <collision>
      <origin rpy="0 0 0" xyz="0 0 0"></origin>
      <geometry>
        <mesh filename="${MeshPath}/eef2_link.STL"></mesh>
      </geometry>
    </collision>
  </link>
  <joint name="EEfixed" type="fixed">
    <origin rpy="0 1.5707963267949 0" xyz="-0.299099999999999 0 0.0824999999999915"></origin>
    <parent link="link4"></parent>
    <child link="EndEff"></child>
    <axis xyz="0 0 0"></axis>
    <limit effort="10" lower="-3.141592" upper="3.141592" velocity="10"></limit>
  </joint>
</robot>
